<mujocoinclude model="full_body">
  <body>
    <camera name="third_person" mode="trackcom" pos="1.5 0 0" target="SMPL_0" quat="0.5 0.5 0.5 0.5" fovy="90"/>

    <!--  盆骨  -->
    <body name="pelvis"  pos="0 0 0.95" quat="0.707035 0.707179 0 0">
      <inertial pos="-0.0707 0 0" mass="11.777" diaginertia="0.1028 0.0871 0.0579"/>
      <joint name="pelvis_tx" pos="0 0 0" axis="1 0 0" type="slide" range="-5 5" damping="0"/>
      <joint name="pelvis_ty" pos="0 0 0" axis="0 1 0" type="slide" range="-1 2" damping="0" user="0.93"/>
      <joint name="pelvis_tz" pos="0 0 0" axis="0 0 1" type="slide" range="-3 3" damping="0"/>
      <joint name="pelvis_tilt" pos="0 0 0" axis="0 0 1" range="-1.571 1.571" damping="0"/>
      <joint name="pelvis_list" pos="0 0 0" axis="1 0 0" range="-1.571 1.571" damping="0"/>
      <joint name="pelvis_rotation" pos="0 0 0" axis="0 1 0" range="-1.571 1.571" damping="0"/>
      <geom name="pelvis_geom_1" type="mesh" rgba="1 1 1 1" mesh="pelvis_geom_1_r_pelvis"/>
      <geom name="pelvis_geom_2" type="mesh" rgba="1 1 1 1" mesh="pelvis_geom_2_l_pelvis"/>
      <geom name="pelvis_geom_3" type="mesh" rgba="1 1 1 1" mesh="pelvis_geom_3_sacrum"/>
      <geom name="Gmax1_at_pelvis_r_cylinder" size="0.04 0.075" pos="-0.077 -0.099 0.061" quat="0.931256 -0.288071 0.213142 -0.0659324" type="cylinder" group="4" rgba="0.19 0.83 0.78 0.2"/>
      <geom name="Gmax2_at_pelvis_r_cylinder" size="0.04 0.05" pos="-0.08 -0.083 0.068" quat="0.912872 -0.359331 0.180301 -0.0709714" type="cylinder" group="4" rgba="0.19 0.83 0.78 0.2"/>
      <geom name="Gmax3_at_pelvis_r_cylinder" size="0.04 0.05" pos="-0.083 -0.088 0.068" quat="0.99875 -0.0499792 0 0" type="cylinder" group="4" rgba="0.19 0.83 0.78 0.2"/>
      <geom name="Gmax1_at_pelvis_l_cylinder" size="0.04 0.075" pos="-0.077 -0.099 -0.061" quat="0.931256 0.288071 -0.213142 -0.0659324" type="cylinder" group="4" rgba="0.19 0.83 0.78 0.2"/>
      <geom name="Gmax2_at_pelvis_l_cylinder" size="0.04 0.05" pos="-0.08 -0.083 -0.068" quat="0.912872 0.359331 -0.180301 -0.0709714" type="cylinder" group="4" rgba="0.19 0.83 0.78 0.2"/>
      <geom name="Gmax3_at_pelvis_l_cylinder" size="0.04 0.05" pos="-0.083 -0.088 -0.068" quat="0.99875 0.0499792 0 0" type="cylinder" group="4" rgba="0.19 0.83 0.78 0.2"/>
      <geom name="PS_at_brim_r_cylinder" size="0.05 0.05" pos="-0.074 -0.06 0.0656" quat="0.981103 -0.13006 -0.127199 0.0658971" type="cylinder" group="4" rgba="0.19 0.83 0.78 0.2"/>
      <geom name="PS_at_brim_l_cylinder" size="0.05 0.05" pos="-0.074 -0.06 -0.0656" quat="0.981103 0.13006 0.127199 0.0658971" type="cylinder" group="4" rgba="0.19 0.83 0.78 0.2"/>
      <geom name="IL_at_brim_r_cylinder" size="0.0549 0.05" pos="-0.071 -0.065 0.0756" quat="0.874257 -0.193832 -0.0376181 0.443495" type="cylinder" group="4" rgba="0.19 0.83 0.78 0.2"/>
      <geom name="IL_at_brim_l_cylinder" size="0.0549 0.05" pos="-0.071 -0.065 -0.0756" quat="0.874257 0.193832 0.0376181 0.443495" type="cylinder" group="4" rgba="0.19 0.83 0.78 0.2"/>
      <site name="Gmax1_at_pelvis_r_sidesite" pos="-0.1139 -0.08893 0.07572" size="0.0005"/>
      <site name="Gmax1_at_pelvis_l_sidesite" pos="-0.1139 -0.08893 -0.07572" size="0.0005"/>
      <site name="PS_at_brim_r_sidesite" pos="-0.06909 -0.1088 0.07947" size="0.0005"/>
      <site name="PS_at_brim_l_sidesite" pos="-0.06909 -0.1088 -0.07947" size="0.0005"/>
      <site name="IL_at_brim_r_sidesite" pos="-0.02847 -0.09471 0.09641" size="0.0005"/>
      <site name="IL_at_brim_l_sidesite" pos="-0.02847 -0.09471 -0.09641" size="0.0005"/>
      <site name="addbrev_r_addbrev_r-P1" pos="-0.0191 -0.094 0.0154"/>
      <site name="addlong_r_addlong_r-P1" pos="-0.00758 -0.0889 0.01888"/>
      <site name="addmagDist_r_addmagDist_r-P1" pos="-0.07404 -0.12767 0.03982"/>
      <site name="addmagIsch_r_addmagIsch_r-P1" pos="-0.08962 -0.12976 0.04171"/>
      <site name="addmagMid_r_addmagMid_r-P1" pos="-0.05266 -0.12075 0.02854"/>
      <site name="addmagProx_r_addmagProx_r-P1" pos="-0.03098 -0.10755 0.01365"/>
      <site name="bflh140_r_bflh140_r-P1" pos="-0.104 -0.1191 0.0586"/>
      <site name="ercspn_r_ercspn_r-P1" pos="-0.15 0.0439 0.0436"/>
      <site name="extobl_r_extobl_r-P1" pos="-0.04 -0.055 0.05"/>
      <site name="gem_r_gem_r-P1" pos="-0.10357 -0.0764 0.06707"/>
      <site name="glmax1_r_glmax1_r-P1" pos="-0.1231 0.0345 0.0563"/>
      <site name="glmax1_r_glmax1_r-P2" pos="-0.1257 -0.0242 0.0779"/>
      <site name="Gmax1_at_pelvis_r_cylinder_glmax1_r_2_sidesite" pos="-0.102812 -0.084971 0.111667" size="0.0005"/>
      <site name="glmax2_r_glmax2_r-P1" pos="-0.1317 0.0087 0.0462"/>
      <site name="glmax2_r_glmax2_r-P2" pos="-0.1344 -0.0609 0.0813"/>
      <site name="Gmax2_at_pelvis_r_cylinder_glmax2_r_2_sidesite" pos="-0.115443 -0.07535 0.102803" size="0.0005"/>
      <site name="glmax3_r_glmax3_r-P1" pos="-0.13 -0.0525 0.009"/>
      <site name="glmax3_r_glmax3_r-P2" pos="-0.1273 -0.1263 0.0435"/>
      <site name="Gmax3_at_pelvis_r_cylinder_glmax3_r_1_sidesite" pos="0.317 0.312 0.468" size="0.0005"/>
      <site name="glmed1_r_glmed1_r-P1" pos="-0.0445 0.0245 0.1172"/>
      <site name="glmed2_r_glmed2_r-P1" pos="-0.085 0.0316 0.0675"/>
      <site name="glmed3_r_glmed3_r-P1" pos="-0.1152 -0.0073 0.0526"/>
      <site name="glmin1_r_glmin1_r-P1" pos="-0.0464 -0.0149 0.1042"/>
      <site name="glmin2_r_glmin2_r-P1" pos="-0.0616 -0.0142 0.0971"/>
      <site name="glmin3_r_glmin3_r-P1" pos="-0.0789 -0.0155 0.0798"/>
      <site name="grac_r_grac_r-P1" pos="-0.04736 -0.12932 0.02456"/>
      <site name="iliacus_r_iliacus_r-P1" pos="-0.0605 0.0309 0.0843"/>
      <site name="iliacus_r_iliacus_r-P2" pos="-0.0135 -0.0557 0.0756"/>
      <site name="IL_at_brim_r_cylinder_iliacus_r_2_sidesite" pos="0.00262162 -0.0899044 0.050451" size="0.0005"/>
      <site name="intobl_r_intobl_r-P1" pos="-0.05 0.07 0.1157"/>
      <site name="obtext_r_obtext_r-P1" pos="-0.054 -0.111 0.026"/>
      <site name="obtint_r_obtint_r-P1" pos="-0.062 -0.114 0.029"/>
      <site name="obtint_r_obtint_r-P2" pos="-0.111 -0.083 0.047"/>
      <site name="pect_r_pect_r-P1" pos="-0.0232 -0.08325 0.04529"/>
      <site name="piri_r_piri_r-P1" pos="-0.10181 -0.00653 0.01351"/>
      <site name="piri_r_piri_r-P2" pos="-0.10202 -0.03066 0.06092"/>
      <site name="psoas_r_psoas_r-P1" pos="-0.0606 0.062 0.039"/>
      <site name="psoas_r_psoas_r-P2" pos="-0.0205 -0.0654 0.0656"/>
      <site name="PS_at_brim_r_cylinder_psoas_r_2_sidesite" pos="-0.0240219 -0.0528315 0.109085" size="0.0005"/>
      <site name="quadfem_r_quadfem_r-P1" pos="-0.11192 -0.11473 0.05166"/>
      <site name="recfem_r_recfem_r-P1" pos="-0.024 -0.0388 0.0933"/>
      <site name="rectab_r_rectab_r-P1" pos="-0.025 -0.07 0.03"/>
      <site name="sart_r_sart_r-P1" pos="-0.0195 -0.0156 0.1056"/>
      <site name="semimem_r_semimem_r-P1" pos="-0.0987 -0.114 0.0614"/>
      <site name="semiten_r_semiten_r-P1" pos="-0.1038 -0.1253 0.0515"/>
      <site name="tfl_r_tfl_r-P1" pos="-0.0311 0.0214 0.1241"/>
      <site name="addbrev_l_addbrev_l-P1" pos="-0.0191 -0.094 -0.0154"/>
      <site name="addlong_l_addlong_l-P1" pos="-0.00758 -0.0889 -0.01888"/>
      <site name="addmagDist_l_addmagDist_l-P1" pos="-0.07404 -0.12767 -0.03982"/>
      <site name="addmagIsch_l_addmagIsch_l-P1" pos="-0.08962 -0.12976 -0.04171"/>
      <site name="addmagMid_l_addmagMid_l-P1" pos="-0.05266 -0.12075 -0.02854"/>
      <site name="addmagProx_l_addmagProx_l-P1" pos="-0.03098 -0.10755 -0.01365"/>
      <site name="bflh140_l_bflh140_l-P1" pos="-0.104 -0.1191 -0.0586"/>
      <site name="ercspn_l_ercspn_l-P1" pos="-0.15 0.0439 -0.0436"/>
      <site name="extobl_l_extobl_l-P1" pos="-0.04 -0.055 -0.05"/>
      <site name="gem_l_gem_l-P1" pos="-0.10357 -0.0764 -0.06707"/>
      <site name="glmax1_l_glmax1_l-P1" pos="-0.1231 0.0345 -0.0563"/>
      <site name="glmax1_l_glmax1_l-P2" pos="-0.1257 -0.0242 -0.0779"/>
      <site name="Gmax1_at_pelvis_l_cylinder_glmax1_l_2_sidesite" pos="-0.0886985 -0.0609517 -0.135862" size="0.0005"/>
      <site name="glmax2_l_glmax2_l-P1" pos="-0.1317 0.0087 -0.0462"/>
      <site name="glmax2_l_glmax2_l-P2" pos="-0.1344 -0.0609 -0.0813"/>
      <site name="Gmax2_at_pelvis_l_cylinder_glmax2_l_2_sidesite" pos="-0.11412 -0.0478044 -0.0898373" size="0.0005"/>
      <site name="glmax3_l_glmax3_l-P1" pos="-0.13 -0.0525 -0.009"/>
      <site name="glmax3_l_glmax3_l-P2" pos="-0.1273 -0.1263 -0.0435"/>
      <site name="Gmax3_at_pelvis_l_cylinder_glmax3_l_1_sidesite" pos="0.317 0.312 0.332" size="0.0005"/>
      <site name="glmed1_l_glmed1_l-P1" pos="-0.0445 0.0245 -0.1172"/>
      <site name="glmed2_l_glmed2_l-P1" pos="-0.085 0.0316 -0.0675"/>
      <site name="glmed3_l_glmed3_l-P1" pos="-0.1152 -0.0073 -0.0526"/>
      <site name="glmin1_l_glmin1_l-P1" pos="-0.0464 -0.0149 -0.1042"/>
      <site name="glmin2_l_glmin2_l-P1" pos="-0.0616 -0.0142 -0.0971"/>
      <site name="glmin3_l_glmin3_l-P1" pos="-0.0789 -0.0155 -0.0798"/>
      <site name="grac_l_grac_l-P1" pos="-0.04736 -0.12932 -0.02456"/>
      <site name="iliacus_l_iliacus_l-P1" pos="-0.0605 0.0309 -0.0843"/>
      <site name="iliacus_l_iliacus_l-P2" pos="-0.0135 -0.0557 -0.0756"/>
      <site name="IL_at_brim_l_cylinder_iliacus_l_2_sidesite" pos="-0.0524543 -0.00513011 -0.0545739" size="0.0005"/>
      <site name="intobl_l_intobl_l-P1" pos="-0.05 0.07 -0.1157"/>
      <site name="obtext_l_obtext_l-P1" pos="-0.054 -0.111 -0.026"/>
      <site name="obtint_l_obtint_l-P1" pos="-0.062 -0.114 -0.029"/>
      <site name="obtint_l_obtint_l-P2" pos="-0.111 -0.083 -0.047"/>
      <site name="pect_l_pect_l-P1" pos="-0.0232 -0.08325 -0.04529"/>
      <site name="piri_l_piri_l-P1" pos="-0.10181 -0.00653 -0.01351"/>
      <site name="piri_l_piri_l-P2" pos="-0.10202 -0.03066 -0.06092"/>
      <site name="psoas_l_psoas_l-P1" pos="-0.0606 0.062 -0.039"/>
      <site name="psoas_l_psoas_l-P2" pos="-0.0205 -0.0654 -0.0656"/>
      <site name="PS_at_brim_l_cylinder_psoas_l_2_sidesite" pos="-0.0227972 -0.0409222 -0.0984629" size="0.0005"/>
      <site name="quadfem_l_quadfem_l-P1" pos="-0.11192 -0.11473 -0.05166"/>
      <site name="recfem_l_recfem_l-P1" pos="-0.024 -0.0388 -0.0933"/>
      <site name="rectab_l_rectab_l-P1" pos="-0.025 -0.07 -0.03"/>
      <site name="sart_l_sart_l-P1" pos="-0.0195 -0.0156 -0.1056"/>
      <site name="semimem_l_semimem_l-P1" pos="-0.0987 -0.114 -0.0614"/>
      <site name="semiten_l_semiten_l-P1" pos="-0.1038 -0.1253 -0.0515"/>
      <site name="tfl_l_tfl_l-P1" pos="-0.0311 0.0214 -0.1241"/>
      <!--  右侧大腿股骨    -->
      <body name="femur_r" pos="-0.05628 -0.07849 0.07726">
        <!-- 髋关节动捕记录点    -->
        <body name="SMPL_1" pos="0 0 0">
          <site name="SMPL_1" pos="0 0 0" rgba="0 1 0 1" type="sphere" size="0.01"/>
        </body>

        <inertial pos="0 -0.17 0" quat="0.5 0.5 -0.5 0.5" mass="9.3014" diaginertia="0.1412 0.1339 0.0351"/>
        <joint name="hip_flexion_r" pos="0 0 0" axis="0 0 1" range="-0.5236 2.094" user="2.33205e-09"/>
        <joint name="hip_adduction_r" pos="0 0 0" axis="1 0 0" range="-0.8727 0.5236" user="-1.19929e-09"/>
        <joint name="hip_rotation_r" pos="0 0 0" axis="0 1 0" range="-0.6981 0.6981"/>
        <geom name="femur_r_geom_1" type="mesh" rgba="1 1 1 1" mesh="femur_r_geom_1_r_femur"/>
        <geom name="GasLat_at_condyles_r_cylinder" size="0.026 0.05" pos="0.005 -0.41 0" type="cylinder" group="4" rgba="0.19 0.83 0.78 0.2"/>
        <geom name="GasMed_at_condyles_r_cylinder" size="0.025 0.05" pos="0.005 -0.41 0" type="cylinder" group="4" rgba="0.19 0.83 0.78 0.2"/>
        <geom name="KnExt_at_fem_r_cylinder" size="0.025 0.05" pos="0.003588 -0.4027 0.002091" quat="0.999192 -0.0311549 0.0253649 -0.000790882" type="cylinder" group="4" rgba="0.19 0.83 0.78 0.2"/>
        <geom name="KnExtVL_at_fem_r_cylinder" size="0.025 0.05" pos="0.001888 -0.4027 0.002091" quat="0.999192 -0.0311549 0.0253649 -0.000790882" type="cylinder" group="4" rgba="0.19 0.83 0.78 0.2"/>
        <geom name="AB_at_femshaft_r_cylinder" size="0.0165 0.035" pos="0.01464 -0.1126 0.02337" quat="0.671205 0.735393 0.0628058 0.068812" type="cylinder" group="4" rgba="0.19 0.83 0.78 0.2"/>
        <geom name="AL_at_femshaft_r_cylinder" size="0.0201 0.05" pos="0.03073 -0.2319 0.01511" quat="0.629109 0.77432 0.0430035 0.0529295" type="cylinder" group="4" rgba="0.19 0.83 0.78 0.2"/>
        <geom name="AMprox_at_femshaft_r_cylinder" size="0.0211 0.035" pos="0.005183 -0.07289 0.0254" quat="0.689738 0.718041 0.0645399 0.0671882" type="cylinder" group="4" rgba="0.19 0.83 0.78 0.2"/>
        <geom name="AMmid_at_femshaft_r_cylinder" size="0.0214 0.06" pos="0.02301 -0.1607 0.02058" quat="0.691136 0.719496 0.0472781 0.0492181" type="cylinder" group="4" rgba="0.19 0.83 0.78 0.2"/>
        <geom name="AMdist_at_femshaft_r_cylinder" size="0.0218 0.1" pos="0.03161 -0.2607 0.009365" quat="0.652613 0.751942 0.0610661 0.0703605" type="cylinder" group="4" rgba="0.19 0.83 0.78 0.2"/>
        <geom name="AMisch_at_condyles_r_cylinder" size="0.04 0.12" pos="-0.02265 -0.3768 -0.003154" quat="0.638315 0.734726 -0.150602 -0.173349" type="cylinder" group="4" rgba="0.19 0.83 0.78 0.2"/>
        <geom name="PECT_at_femshaft_r_cylinder" size="0.015 0.025" pos="0.006086 -0.0845 0.03044" quat="0.610631 0.779849 0.0848995 0.108427" type="cylinder" group="4" rgba="0.19 0.83 0.78 0.2"/>
        <geom name="OBTEXT_at_femneck_r_cylinder" size="0.0136 0.024" pos="-0.005764 -0.01725 0.02336" quat="0.939344 0.325795 -0.101275 -0.0351255" type="cylinder" group="4" rgba="0.19 0.83 0.78 0.2"/>
        <site name="addbrev_r_addbrev_r-P2" pos="-0.002 -0.118 0.0249"/>
        <site name="AB_at_femshaft_r_cylinder_addbrev_r_1_sidesite" pos="0.0167109 -0.144235 0.00104369" size="0.0005"/>
        <site name="addlong_r_addlong_r-P2" pos="0.01126 -0.23937 0.01583"/>
        <site name="AL_at_femshaft_r_cylinder_addlong_r_1_sidesite" pos="0.01126 -0.2394 0.01583" size="0.0005"/>
        <site name="addmagDist_r_addmagDist_r-P2" pos="0.01125 -0.2625 0.0193"/>
        <site name="AMdist_at_femshaft_r_cylinder_addmagDist_r_1_sidesite" pos="0.00968235 -0.285318 0.00586558" size="0.0005"/>
        <site name="addmagIsch_r_addmagIsch_r-P2" pos="0.00481 -0.38797 -0.03273"/>
        <site name="AMisch_at_condyles_r_cylinder_addmagIsch_r_1_sidesite" pos="0.00481 -0.388 -0.03273" size="0.0005"/>
        <site name="addmagMid_r_addmagMid_r-P2" pos="0.00242 -0.1624 0.02922"/>
        <site name="AMmid_at_femshaft_r_cylinder_addmagMid_r_1_sidesite" pos="0.00242 -0.1624 0.02922" size="0.0005"/>
        <site name="addmagProx_r_addmagProx_r-P2" pos="-0.01527 -0.07886 0.03202"/>
        <site name="AMprox_at_femshaft_r_cylinder_addmagProx_r_1_sidesite" pos="-0.00447309 -0.0718189 0.00193965" size="0.0005"/>
        <site name="bfsh140_r_bfsh140_r-P1" pos="0.005 -0.2111 0.0234"/>
        <site name="gaslat140_r_gaslat140_r-P1" pos="0.002 -0.381 0.02059"/>
        <site name="GasLat_at_condyles_r_cylinder_gaslat140_r_1_sidesite" pos="-0.0185499 -0.389534 0.0360656" size="0.0005"/>
        <site name="gasmed_r_gasmed_r-P1" pos="0.006 -0.384 -0.022"/>
        <site name="GasMed_at_condyles_r_cylinder_gasmed_r_1_sidesite" pos="-0.0108691 -0.384541 -0.00961897" size="0.0005"/>
        <site name="gem_r_gem_r-P2" pos="-0.0142 -0.0033 0.0443"/>
        <site name="glmax1_r_glmax1_r-P3" pos="-0.0444 -0.0326 0.0302"/>
        <site name="glmax1_r_glmax1_r-P4" pos="-0.0277 -0.0566 0.047"/>
        <site name="glmax2_r_glmax2_r-P3" pos="-0.045 -0.0584 0.0252"/>
        <site name="glmax2_r_glmax2_r-P4" pos="-0.0156 -0.1016 0.0419"/>
        <site name="glmax3_r_glmax3_r-P3" pos="-0.0281 -0.1125 0.0094"/>
        <site name="glmax3_r_glmax3_r-P4" pos="-0.006 -0.1419 0.0411"/>
        <site name="glmed1_r_glmed1_r-P2" pos="-0.0218 -0.0117 0.0555"/>
        <site name="glmed2_r_glmed2_r-P2" pos="-0.0258 -0.0058 0.0527"/>
        <site name="glmed3_r_glmed3_r-P2" pos="-0.0309 -0.0047 0.0518"/>
        <site name="glmin1_r_glmin1_r-P2" pos="-0.0072 -0.0104 0.056"/>
        <site name="glmin2_r_glmin2_r-P2" pos="-0.0096 -0.0104 0.056"/>
        <site name="glmin3_r_glmin3_r-P2" pos="-0.0135 -0.0083 0.055"/>
        <site name="iliacus_r_iliacus_r-P3" pos="-0.0023 -0.0565 0.0139"/>
        <site name="iliacus_r_iliacus_r-P4" pos="-0.0122 -0.0637 0.0196"/>
        <site name="obtext_r_obtext_r-P2" pos="-0.025 -0.011 0.039"/>
        <site name="OBTEXT_at_femneck_r_cylinder_obtext_r_1_sidesite" pos="-0.0210016 -0.0162408 0.039308" size="0.0005"/>
        <site name="obtint_r_obtint_r-P3" pos="-0.0162 -0.0013 0.0443"/>
        <site name="pect_r_pect_r-P2" pos="-0.00797 -0.08518 0.02403"/>
        <site name="PECT_at_femshaft_r_cylinder_pect_r_1_sidesite" pos="-0.00797 -0.08518 0.02403" size="0.0005"/>
        <site name="piri_r_piri_r-P3" pos="-0.0148 -0.0036 0.0437"/>
        <site name="psoas_r_psoas_r-P3" pos="-0.0132 -0.0467 0.0046"/>
        <site name="psoas_r_psoas_r-P4" pos="-0.0235 -0.0524 0.0088"/>
        <site name="quadfem_r_quadfem_r-P2" pos="-0.03575 -0.03552 0.03612"/>
        <site name="KnExt_at_fem_r_cylinder_recfem_r_3_sidesite" pos="0.253588 -0.1527 0.252091" size="0.0005"/>
        <site name="sart_r_sart_r-P2" pos="-0.003 -0.3568 -0.0421"/>
        <site name="tfl_r_tfl_r-P2" pos="0.0294 -0.0995 0.0597"/>
        <site name="tfl_r_tfl_r-P3" pos="0.0107 -0.405 0.0324"/>
        <site name="vasint_r_vasint_r-P1" pos="0.029 -0.1924 0.031"/>
        <site name="vasint_r_vasint_r-P2" pos="0.0335 -0.2084 0.0285"/>
        <site name="KnExt_at_fem_r_cylinder_vasint_r_3_sidesite" pos="0.253588 -0.1527 0.252091" size="0.0005"/>
        <site name="vaslat140_r_vaslat140_r-P1" pos="0.0048 -0.1854 0.0349"/>
        <site name="vaslat140_r_vaslat140_r-P2" pos="0.0269 -0.2591 0.0409"/>
        <site name="KnExtVL_at_fem_r_cylinder_vaslat140_r_3_sidesite" pos="0.251888 -0.1527 0.252091" size="0.0005"/>
        <site name="vasmed_r_vasmed_r-P1" pos="0.014 -0.2099 0.0188"/>
        <site name="vasmed_r_vasmed_r-P2" pos="0.0356 -0.2769 0.0009"/>
        <site name="KnExt_at_fem_r_cylinder_vasmed_r_4_sidesite" pos="-0.007846 -0.4075 -0.02075" size="0.0005"/>
        <site name="KnExt_at_fem_r_cylinder_vasmed_r_3_sidesite" pos="-0.007846 -0.4075 -0.02075" size="0.0005"/>

        <!--   （胫骨）人体小腿内侧的长骨     -->
        <body name="tibia_r" pos="0.00359 -0.4061 -0.0002653">
          <!-- 髋关节动捕记录点    -->
          <body name="SMPL_4" pos="0 0 0">
            <site name="SMPL_4" pos="0 0 0" rgba="0 1 0 1" type="sphere" size="0.01"/>
          </body>
          <inertial pos="0 -0.1867 0" quat="0.5 0.5 -0.5 0.5" mass="3.7075" diaginertia="0.0511 0.0504 0.0051"/>
          <joint name="walker_knee_r_translation1" pos="0 0 0" axis="-4.56599e-07 -0.0707098 -0.997497" type="slide" range="0 0.00176" user="-7.73364e-07"/>
          <joint name="walker_knee_r_translation2" pos="0 0 0" axis="-0.124295 0.989762 -0.0701573" type="slide" range="-0.006539 0.000301" user="-2.49715e-05"/>
          <joint name="walker_knee_r_translation3" pos="0 0 0" axis="0.992243 0.124005 -0.00878938" type="slide" range="-0.001898 0.003676" user="-1.43135e-05"/>
          <joint name="knee_angle_r" pos="0 0 0" axis="-4.56599e-07 -0.0707098 -0.997497" range="-0.1745 2.443" user="4.87767e-05"/>
          <joint name="walker_knee_r_rotation2" pos="0 0 0" axis="0.992243 0.124005 -0.00878938" range="-0.001678 0.03354" user="3.84342e-06"/>
          <joint name="walker_knee_r_rotation3" pos="0 0 0" axis="-0.124295 0.989762 -0.0701573" range="0 0.2628" user="1.80334e-05"/>
          <geom name="tibia_r_geom_1" type="mesh" rgba="1 1 1 1" mesh="tibia_r_geom_1_r_tibia"/>
          <geom name="tibia_r_geom_2" type="mesh" rgba="1 1 1 1" mesh="tibia_r_geom_2_r_fibula"/>
          <geom name="GasLat_at_shank_r_cylinder" size="0.055 0.05" pos="-0.0074 -0.074 -0.0033" quat="-0.0297182 0.737325 0.65545 -0.160791" type="cylinder" group="4" rgba="0.19 0.83 0.78 0.2"/>
          <geom name="GasMed_at_shank_r_cylinder" size="0.059 0.05" pos="-0.0074 -0.074 -0.0033" quat="0.0738196 0.735435 0.67182 -0.0484208" type="cylinder" group="4" rgba="0.19 0.83 0.78 0.2"/>
          <geom name="GR_at_condyles_r_cylinder" size="0.036 0.05" pos="-0.003 -0.02 0" quat="0.980067 0 -0.198669 0" type="cylinder" group="4" rgba="0.19 0.83 0.78 0.2"/>
          <geom name="SM_at_condyles_r_cylinder" size="0.0345 0.05" pos="-0.001 -0.02 0" quat="0.99875 0 -0.0499792 0" type="cylinder" group="4" rgba="0.19 0.83 0.78 0.2"/>
          <geom name="ST_at_condyles_r_cylinder" size="0.0425 0.05" pos="-0.002 -0.0205 0" quat="0.995004 0 -0.0998334 0" type="cylinder" group="4" rgba="0.19 0.83 0.78 0.2"/>
          <geom name="BF140_at_gastroc_r_cylinder" size="0.029 0.075" pos="-0.039 -0.06 0" type="cylinder" group="4" rgba="0.19 0.83 0.78 0.2"/>
          <site name="GasLat_at_shank_r_sidesite" pos="-0.06099 -0.06623 0.01096" size="0.0005"/>
          <site name="GasMed_at_shank_r_sidesite" pos="-0.06712 -0.06882 -0.005909" size="0.0005"/>
          <site name="BF140_at_gastroc_r_sidesite" pos="-0.039 -0.03 0" size="0.0005"/>
          <site name="bflh140_r_bflh140_r-P2" pos="-0.03436 -0.03648 0.03618"/>
          <site name="bflh140_r_bflh140_r-P3" pos="-0.02704 -0.05008 0.03476"/>
          <site name="bfsh140_r_bfsh140_r-P2" pos="-0.02866 -0.03284 0.03204"/>
          <site name="BF140_at_gastroc_r_cylinder_bfsh140_r_1_sidesite" pos="-0.0458494 -0.0258807 -0.0218782" size="0.0005"/>
          <site name="edl_r_edl_r-P1" pos="-0.016 -0.1157 0.0205"/>
          <site name="edl_r_edl_r-P2" pos="0.0164 -0.376 0.0112"/>
          <site name="ehl_r_ehl_r-P1" pos="-0.014 -0.155 0.0189"/>
          <site name="ehl_r_ehl_r-P2" pos="0.0071 -0.2909 0.0164"/>
          <site name="ehl_r_ehl_r-P3" pos="0.02 -0.3693 -0.0028"/>
          <site name="fdl_r_fdl_r-P1" pos="-0.0023 -0.1832 -0.0018"/>
          <site name="fdl_r_fdl_r-P2" pos="-0.0176 -0.3645 -0.0124"/>
          <site name="fhl_r_fhl_r-P1" pos="-0.031 -0.2163 0.02"/>
          <site name="fhl_r_fhl_r-P2" pos="-0.0242 -0.3671 -0.0076"/>
          <site name="grac_r_grac_r-P2" pos="-0.01842 -0.04755 -0.02961"/>
          <site name="grac_r_grac_r-P3" pos="0.00178 -0.06962 -0.01573"/>
          <site name="GR_at_condyles_r_cylinder_grac_r_1_sidesite" pos="-0.0294079 -0.0412182 -0.0341712" size="0.0005"/>
          <site name="perbrev_r_perbrev_r-P1" pos="-0.0243 -0.2532 0.0251"/>
          <site name="perbrev_r_perbrev_r-P2" pos="-0.0339 -0.3893 0.0249"/>
          <site name="perbrev_r_perbrev_r-P3" pos="-0.0285 -0.4004 0.0255"/>
          <site name="perlong_r_perlong_r-P1" pos="-0.02 -0.1373 0.0282"/>
          <site name="perlong_r_perlong_r-P2" pos="-0.0317 -0.39 0.0237"/>
          <site name="perlong_r_perlong_r-P3" pos="-0.0272 -0.4014 0.024"/>
          <site name="recfem_r_recfem_r-P5" pos="0.0326 -0.06312 -0.00047"/>
          <site name="sart_r_sart_r-P3" pos="-0.0251 -0.0401 -0.0365"/>
          <site name="sart_r_sart_r-P4" pos="-0.0159 -0.0599 -0.0264"/>
          <site name="sart_r_sart_r-P5" pos="0.0136 -0.081 -0.0026"/>
          <site name="semimem_r_semimem_r-P2" pos="-0.027 -0.041 -0.0196"/>
          <site name="SM_at_condyles_r_cylinder_semimem_r_1_sidesite" pos="-0.0408605 -0.0256896 -0.0134805" size="0.0005"/>
          <site name="semiten_r_semiten_r-P2" pos="-0.0312 -0.0508 -0.0229"/>
          <site name="semiten_r_semiten_r-P3" pos="0.0019 -0.0773 -0.0117"/>
          <site name="ST_at_condyles_r_cylinder_semiten_r_1_sidesite" pos="-0.0387975 -0.0558564 -0.00347776" size="0.0005"/>
          <site name="soleus_r_soleus_r-P1" pos="-0.0076 -0.0916 0.0098"/>
          <site name="tfl_r_tfl_r-P4" pos="0.0108 -0.041 0.0346"/>
          <site name="tibant_r_tibant_r-P1" pos="0.0154 -0.1312 0.0162"/>
          <site name="tibant_r_tibant_r-P2" pos="0.0251 -0.1906 0.0128"/>
          <site name="tibant_r_tibant_r-P3" pos="0.0233 -0.3659 -0.0132"/>
          <site name="tibpost_r_tibpost_r-P1" pos="-0.0041 -0.1304 0.0103"/>
          <site name="tibpost_r_tibpost_r-P2" pos="-0.0164 -0.3655 -0.0175"/>
          <site name="vasint_r_vasint_r-P5" pos="0.03257 -0.0632 0.00043"/>
          <site name="vaslat140_r_vaslat140_r-P5" pos="0.03254 -0.06338 0.00511"/>
          <site name="vasmed_r_vasmed_r-P5" pos="0.0319 -0.06357 -0.00678"/>
          <!-- 距骨 是位于胫骨、腓骨与跟骨之间的短骨，属于足部最高位的骨骼 -->
          <body name="talus_r" pos="-0.01 -0.4 0">
            <!-- 踝关节动捕记录点    -->
            <body name="SMPL_7" pos="0 0 0">
              <site name="SMPL_7" pos="0 0 0" rgba="0 1 0 1" type="sphere" size="0.01"/>
            </body>
            <inertial pos="0 0 0" mass="0.1" diaginertia="0.001 0.001 0.001"/>
            <joint name="ankle_angle_r" pos="0 0 0" axis="-0.105003 -0.174005 0.979131" range="-0.6981 0.5236" user="-1.18287e-09"/>
            <geom name="talus_r_geom_1" type="mesh" rgba="1 1 1 1" mesh="talus_r_geom_1_r_talus"/>
            <!--跟骨Calcaneus -->
            <body name="calcn_r" pos="-0.04877 -0.04195 0.00792">
              <inertial pos="0.1 0.03 0" quat="0 0.707107 0 0.707107" mass="1.25" diaginertia="0.0041 0.0039 0.0014"/>
              <joint name="subtalar_angle_r" pos="0 0 0" axis="0.787215 0.604711 -0.120902" range="-0.6109 0.6109"/>
              <geom name="calcn_r_geom_1" type="mesh" rgba="1 1 1 1" mesh="calcn_r_geom_1_r_foot"/>
              <site name="edl_r_edl_r-P3" pos="0.0919 0.036 0.0008"/>
              <site name="edl_r_edl_r-P4" pos="0.1616 0.0055 0.013"/>
              <site name="ehl_r_ehl_r-P4" pos="0.097 0.0389 -0.0211"/>
              <site name="ehl_r_ehl_r-P5" pos="0.1293 0.0309 -0.0257"/>
              <site name="ehl_r_ehl_r-P6" pos="0.1734 0.0139 -0.028"/>
              <site name="fdl_r_fdl_r-P3" pos="0.0436 0.0315 -0.028"/>
              <site name="fdl_r_fdl_r-P4" pos="0.0708 0.0176 -0.0263"/>
              <site name="fdl_r_fdl_r-P5" pos="0.1658 -0.0081 0.0116"/>
              <site name="fhl_r_fhl_r-P3" pos="0.0374 0.0276 -0.0241"/>
              <site name="fhl_r_fhl_r-P4" pos="0.1038 0.0068 -0.0256"/>
              <site name="fhl_r_fhl_r-P5" pos="0.1726 -0.0053 -0.0269"/>
              <site name="gaslat140_r_gaslat140_r-P2" pos="0.0044 0.031 -0.0053"/>
              <site name="gasmed_r_gasmed_r-P2" pos="0.0044 0.031 -0.0053"/>
              <site name="perbrev_r_perbrev_r-P4" pos="0.0471 0.027 0.0233"/>
              <site name="perbrev_r_perbrev_r-P5" pos="0.0677 0.0219 0.0343"/>
              <site name="perlong_r_perlong_r-P4" pos="0.0438 0.023 0.0221"/>
              <site name="perlong_r_perlong_r-P5" pos="0.0681 0.0106 0.0284"/>
              <site name="perlong_r_perlong_r-P6" pos="0.0852 0.0069 0.0118"/>
              <site name="perlong_r_perlong_r-P7" pos="0.1203 0.0085 -0.0184"/>
              <site name="soleus_r_soleus_r-P2" pos="0.0044 0.031 -0.0053"/>
              <site name="tibant_r_tibant_r-P4" pos="0.1166 0.0178 -0.0305"/>
              <site name="tibpost_r_tibpost_r-P3" pos="0.0417 0.0334 -0.0286"/>
              <site name="tibpost_r_tibpost_r-P4" pos="0.0772 0.0159 -0.0281"/>
              <body name="toes_r" pos="0.1788 -0.002 0.00108">

                <body name="SMPL_10" pos="0 0 0">
                  <site name="SMPL_10" pos="0 0 0" rgba="0 1 0 1" type="sphere" size="0.01"/>
                </body>
                <inertial pos="0.0346 0.006 -0.0175" quat="0 0.707107 0 0.707107" mass="0.2166" diaginertia="0.001 0.001 0.001"/>
                <joint name="mtp_angle_r" pos="0 0 0" axis="0.581002 2.16001e-06 -0.813902" range="-0.5236 0.5236"/>
                <geom name="toes_r_geom_1" type="mesh" rgba="1 1 1 1" mesh="toes_r_geom_1_r_bofoot"/>
                <site name="edl_r_edl_r-P5" pos="0.0003 0.0047 0.0153"/>
                <site name="edl_r_edl_r-P6" pos="0.0443 -0.0004 0.025"/>
                <site name="ehl_r_ehl_r-P7" pos="0.0298 0.0041 -0.0245"/>
                <site name="ehl_r_ehl_r-P8" pos="0.0563 0.0034 -0.0186"/>
                <site name="fdl_r_fdl_r-P6" pos="-0.0019 -0.0078 0.0147"/>
                <site name="fdl_r_fdl_r-P7" pos="0.0285 -0.0071 0.0215"/>
                <site name="fdl_r_fdl_r-P8" pos="0.0441 -0.006 0.0242"/>
                <site name="fhl_r_fhl_r-P6" pos="0.0155 -0.0064 -0.0265"/>
                <site name="fhl_r_fhl_r-P7" pos="0.0562 -0.0102 -0.0181"/>
              </body>
            </body>
          </body>
        </body>
        <!-- 髌骨（即膝盖骨）       -->
        <body name="patella_r" pos="-0.00809 -0.408 -0.00275">
          <inertial pos="0.0018 0.0264 0" quat="0.5 0.5 0.5 0.5" mass="0.0862" diaginertia="0.001 0.001 0.001"/>
          <joint name="patellofemoral_r_translation1" pos="0 0 0" axis="1 0 0" type="slide" range="-0.0227 0.0524" user="0.0524185"/>
          <joint name="patellofemoral_r_translation2" pos="0 0 0" axis="0 1 0" type="slide" range="-0.0408 -0.0108" user="-0.0108305"/>
          <joint name="patellofemoral_r_translation3" pos="0 0 0" axis="0 0 1" limited="false" type="slide"/>
          <joint name="patellofemoral_r_rotation1" pos="0 0 0" axis="0 0 1" range="-1.786 0.001137" user="0.0105072"/>
          <geom name="patella_r_geom_1" type="mesh" rgba="1 1 1 1" mesh="patella_r_geom_1_r_patella"/>
          <site name="recfem_r_recfem_r-P2" pos="0.01 0.049 0.0007"/>
          <site name="recfem_r_recfem_r-P3" pos="0.0121 0.0437 -0.001"/>
          <site name="recfem_r_recfem_r-P4" pos="0.005 0.00247 3e-05"/>
          <site name="vasint_r_vasint_r-P3" pos="0.0058 0.048 -0.0006"/>
          <site name="vasint_r_vasint_r-P4" pos="0.005 0.00247 -0.00039"/>
          <site name="vaslat140_r_vaslat140_r-P3" pos="0.0103 0.0423 0.0141"/>
          <site name="vaslat140_r_vaslat140_r-P4" pos="0.005 0.00247 0.00733"/>
          <site name="vasmed_r_vasmed_r-P3" pos="0.0063 0.0445 -0.017"/>
          <site name="vasmed_r_vasmed_r-P4" pos="0.005 0.00247 -0.0085"/>
        </body>
      </body>
      <!-- 左侧大腿肱骨-->
      <body name="femur_l" pos="-0.05628 -0.07849 -0.07726">
      <!--   动捕记录点     -->
        <body name="SMPL_2" pos="0 0 0">
          <site name="SMPL_2" pos="0 0 0" rgba="1 0 0 1" type="sphere" size="0.01"/>
        </body>
        <inertial pos="0 -0.17 0" quat="0.5 0.5 -0.5 0.5" mass="9.3014" diaginertia="0.1412 0.1339 0.0351"/>
        <joint name="hip_flexion_l" pos="0 0 0" axis="0 0 1" range="-0.5236 2.094" user="2.33205e-09"/>
        <joint name="hip_adduction_l" pos="0 0 0" axis="-1 0 0" range="-0.8727 0.5236" user="1.19929e-09"/>
        <joint name="hip_rotation_l" pos="0 0 0" axis="0 -1 0" range="-0.6981 0.6981"/>
        <geom name="femur_l_geom_1" type="mesh" rgba="1 1 1 1" mesh="femur_l_geom_1_l_femur"/>
        <geom name="GasLat_at_condyles_l_cylinder" size="0.026 0.05" pos="0.005 -0.41 0" type="cylinder" group="4" rgba="0.19 0.83 0.78 0.2"/>
        <geom name="GasMed_at_condyles_l_cylinder" size="0.025 0.05" pos="0.005 -0.41 0" type="cylinder" group="4" rgba="0.19 0.83 0.78 0.2"/>
        <geom name="KnExt_at_fem_l_cylinder" size="0.025 0.05" pos="0.003588 -0.4027 -0.002091" quat="0.999192 0.0311549 -0.0253649 -0.000790882" type="cylinder" group="4" rgba="0.19 0.83 0.78 0.2"/>
        <geom name="KnExtVL_at_fem_l_cylinder" size="0.025 0.05" pos="0.001888 -0.4027 -0.002091" quat="0.999192 0.0311549 -0.0253649 -0.000790882" type="cylinder" group="4" rgba="0.19 0.83 0.78 0.2"/>
        <geom name="AB_at_femshaft_l_cylinder" size="0.0165 0.035" pos="0.01464 -0.1126 -0.02337" quat="0.671205 -0.735393 -0.0628058 0.068812" type="cylinder" group="4" rgba="0.19 0.83 0.78 0.2"/>
        <geom name="AL_at_femshaft_l_cylinder" size="0.0201 0.05" pos="0.03073 -0.2319 -0.01511" quat="0.629109 -0.77432 -0.0430035 0.0529295" type="cylinder" group="4" rgba="0.19 0.83 0.78 0.2"/>
        <geom name="AMprox_at_femshaft_l_cylinder" size="0.0211 0.035" pos="0.005183 -0.07289 -0.0254" quat="0.689738 -0.718041 -0.0645399 0.0671882" type="cylinder" group="4" rgba="0.19 0.83 0.78 0.2"/>
        <geom name="AMmid_at_femshaft_l_cylinder" size="0.0214 0.06" pos="0.02301 -0.1607 -0.02058" quat="0.691136 -0.719496 -0.0472781 0.0492181" type="cylinder" group="4" rgba="0.19 0.83 0.78 0.2"/>
        <geom name="AMdist_at_femshaft_l_cylinder" size="0.0218 0.1" pos="0.03161 -0.2607 -0.009365" quat="0.652613 -0.751942 -0.0610661 0.0703605" type="cylinder" group="4" rgba="0.19 0.83 0.78 0.2"/>
        <geom name="AMisch_at_condyles_l_cylinder" size="0.04 0.12" pos="-0.02265 -0.3768 0.003154" quat="0.638315 -0.734726 0.150602 -0.173349" type="cylinder" group="4" rgba="0.19 0.83 0.78 0.2"/>
        <geom name="PECT_at_femshaft_l_cylinder" size="0.015 0.025" pos="0.006086 -0.0845 -0.03044" quat="0.610631 -0.779849 -0.0848995 0.108427" type="cylinder" group="4" rgba="0.19 0.83 0.78 0.2"/>
        <geom name="OBTEXT_at_femneck_l_cylinder" size="0.0136 0.024" pos="-0.005764 -0.01725 -0.02336" quat="0.939344 -0.325795 0.101275 -0.0351255" type="cylinder" group="4" rgba="0.19 0.83 0.78 0.2"/>
        <site name="addbrev_l_addbrev_l-P2" pos="-0.002 -0.118 -0.0249"/>
        <site name="AB_at_femshaft_l_cylinder_addbrev_l_1_sidesite" pos="0.00870947 -0.144296 -0.0046558" size="0.0005"/>
        <site name="addlong_l_addlong_l-P2" pos="0.01126 -0.23937 -0.01583"/>
        <site name="AL_at_femshaft_l_cylinder_addlong_l_1_sidesite" pos="0.01126 -0.2394 -0.01583" size="0.0005"/>
        <site name="addmagDist_l_addmagDist_l-P2" pos="0.01125 -0.2625 -0.0193"/>
        <site name="AMdist_at_femshaft_l_cylinder_addmagDist_l_1_sidesite" pos="0.00712899 -0.267636 -0.0155885" size="0.0005"/>
        <site name="addmagIsch_l_addmagIsch_l-P2" pos="0.00481 -0.38797 0.03273"/>
        <site name="AMisch_at_condyles_l_cylinder_addmagIsch_l_1_sidesite" pos="0.00481 -0.388 0.03273" size="0.0005"/>
        <site name="addmagMid_l_addmagMid_l-P2" pos="0.00242 -0.1624 -0.02922"/>
        <site name="AMmid_at_femshaft_l_cylinder_addmagMid_l_1_sidesite" pos="0.00242 -0.1624 -0.02922" size="0.0005"/>
        <site name="addmagProx_l_addmagProx_l-P2" pos="-0.01527 -0.07886 -0.03202"/>
        <site name="AMprox_at_femshaft_l_cylinder_addmagProx_l_1_sidesite" pos="-0.0144488 -0.097041 -0.0158885" size="0.0005"/>
        <site name="bfsh140_l_bfsh140_l-P1" pos="0.005 -0.2111 -0.0234"/>
        <site name="gaslat140_l_gaslat140_l-P1" pos="0.002 -0.381 -0.02059"/>
        <site name="GasLat_at_condyles_l_cylinder_gaslat140_l_1_sidesite" pos="-0.0250263 -0.401523 -0.0339369" size="0.0005"/>
        <site name="gasmed_l_gasmed_l-P1" pos="0.006 -0.384 0.022"/>
        <site name="GasMed_at_condyles_l_cylinder_gasmed_l_1_sidesite" pos="-0.00277448 -0.381025 0.0166003" size="0.0005"/>
        <site name="gem_l_gem_l-P2" pos="-0.0142 -0.0033 -0.0443"/>
        <site name="glmax1_l_glmax1_l-P3" pos="-0.0444 -0.0326 -0.0302"/>
        <site name="glmax1_l_glmax1_l-P4" pos="-0.0277 -0.0566 -0.047"/>
        <site name="glmax2_l_glmax2_l-P3" pos="-0.045 -0.0584 -0.0252"/>
        <site name="glmax2_l_glmax2_l-P4" pos="-0.0156 -0.1016 -0.0419"/>
        <site name="glmax3_l_glmax3_l-P3" pos="-0.0281 -0.1125 -0.0094"/>
        <site name="glmax3_l_glmax3_l-P4" pos="-0.006 -0.1419 -0.0411"/>
        <site name="glmed1_l_glmed1_l-P2" pos="-0.0218 -0.0117 -0.0555"/>
        <site name="glmed2_l_glmed2_l-P2" pos="-0.0258 -0.0058 -0.0527"/>
        <site name="glmed3_l_glmed3_l-P2" pos="-0.0309 -0.0047 -0.0518"/>
        <site name="glmin1_l_glmin1_l-P2" pos="-0.0072 -0.0104 -0.056"/>
        <site name="glmin2_l_glmin2_l-P2" pos="-0.0096 -0.0104 -0.056"/>
        <site name="glmin3_l_glmin3_l-P2" pos="-0.0135 -0.0083 -0.055"/>
        <site name="iliacus_l_iliacus_l-P3" pos="-0.0023 -0.0565 -0.0139"/>
        <site name="iliacus_l_iliacus_l-P4" pos="-0.0122 -0.0637 -0.0196"/>
        <site name="obtext_l_obtext_l-P2" pos="-0.025 -0.011 -0.039"/>
        <site name="OBTEXT_at_femneck_l_cylinder_obtext_l_1_sidesite" pos="-0.0206099 -0.014876 -0.0373357" size="0.0005"/>
        <site name="obtint_l_obtint_l-P3" pos="-0.0162 -0.0013 -0.0443"/>
        <site name="pect_l_pect_l-P2" pos="-0.00797 -0.08518 -0.02403"/>
        <site name="PECT_at_femshaft_l_cylinder_pect_l_1_sidesite" pos="-0.00797 -0.08518 -0.02403" size="0.0005"/>
        <site name="piri_l_piri_l-P3" pos="-0.0148 -0.0036 -0.0437"/>
        <site name="psoas_l_psoas_l-P3" pos="-0.0132 -0.0467 -0.0046"/>
        <site name="psoas_l_psoas_l-P4" pos="-0.0235 -0.0524 -0.0088"/>
        <site name="quadfem_l_quadfem_l-P2" pos="-0.03575 -0.03552 -0.03612"/>
        <site name="KnExt_at_fem_l_cylinder_recfem_l_3_sidesite" pos="0.253588 -0.1527 0.247909" size="0.0005"/>
        <site name="sart_l_sart_l-P2" pos="-0.003 -0.3568 0.0421"/>
        <site name="tfl_l_tfl_l-P2" pos="0.0294 -0.0995 -0.0597"/>
        <site name="tfl_l_tfl_l-P3" pos="0.0107 -0.405 -0.0324"/>
        <site name="vasint_l_vasint_l-P1" pos="0.029 -0.1924 -0.031"/>
        <site name="vasint_l_vasint_l-P2" pos="0.0335 -0.2084 -0.0285"/>
        <site name="KnExt_at_fem_l_cylinder_vasint_l_3_sidesite" pos="0.253588 -0.1527 0.247909" size="0.0005"/>
        <site name="vaslat140_l_vaslat140_l-P1" pos="0.0048 -0.1854 -0.0349"/>
        <site name="vaslat140_l_vaslat140_l-P2" pos="0.0269 -0.2591 -0.0409"/>
        <site name="KnExtVL_at_fem_l_cylinder_vaslat140_l_3_sidesite" pos="0.251888 -0.1527 0.247909" size="0.0005"/>
        <site name="vasmed_l_vasmed_l-P1" pos="0.014 -0.2099 -0.0188"/>
        <site name="vasmed_l_vasmed_l-P2" pos="0.0356 -0.2769 -0.0009"/>
        <site name="KnExt_at_fem_l_cylinder_vasmed_l_4_sidesite" pos="-0.007846 -0.4075 0.02075" size="0.0005"/>
        <site name="KnExt_at_fem_l_cylinder_vasmed_l_3_sidesite" pos="-0.007846 -0.4075 0.02075" size="0.0005"/>
        <!-- 左侧小腿-->
        <body name="tibia_l" pos="0.00359 -0.4061 0.0002653">
          <body name="SMPL_5" pos="0 0 0">
            <site name="SMPL_5" pos="0 0 0" rgba="1 0 0 1" type="sphere" size="0.01"/>
          </body>
          <inertial pos="0 -0.1867 0" quat="0.5 0.5 -0.5 0.5" mass="3.7075" diaginertia="0.0511 0.0504 0.0051"/>
          <joint name="walker_knee_l_translation1" pos="0 0 0" axis="-4.56599e-07 -0.0707098 0.997497" type="slide" range="0 0.00176" user="-7.73364e-07"/>
          <joint name="walker_knee_l_translation2" pos="0 0 0" axis="-0.124295 0.989762 0.0701573" type="slide" range="-0.006539 0.000301" user="-2.49715e-05"/>
          <joint name="walker_knee_l_translation3" pos="0 0 0" axis="-0.992243 -0.124005 -0.00878938" type="slide" range="-0.003676 0.001898" user="1.43135e-05"/>
          <joint name="knee_angle_l" pos="0 0 0" axis="4.56599e-07 0.0707098 -0.997497" range="-0.1745 2.443" user="4.87799e-05"/>
          <joint name="walker_knee_l_rotation2" pos="0 0 0" axis="-0.992243 -0.124005 -0.00878938" range="-0.001678 0.03354" user="3.84368e-06"/>
          <joint name="walker_knee_l_rotation3" pos="0 0 0" axis="-0.124295 0.989762 0.0701573" range="-0.2628 0" user="-1.80346e-05"/>
          <geom name="tibia_l_geom_1" type="mesh" rgba="1 1 1 1" mesh="tibia_l_geom_1_l_tibia"/>
          <geom name="tibia_l_geom_2" type="mesh" rgba="1 1 1 1" mesh="tibia_l_geom_2_l_fibula"/>
          <geom name="GasLat_at_shank_l_cylinder" size="0.055 0.05" pos="-0.0074 -0.074 0.0033" quat="-0.0297182 -0.737325 -0.65545 -0.160791" type="cylinder" group="4" rgba="0.19 0.83 0.78 0.2"/>
          <geom name="GasMed_at_shank_l_cylinder" size="0.059 0.05" pos="-0.0074 -0.074 0.0033" quat="0.0738196 -0.735435 -0.67182 -0.0484208" type="cylinder" group="4" rgba="0.19 0.83 0.78 0.2"/>
          <geom name="GR_at_condyles_l_cylinder" size="0.036 0.05" pos="-0.003 -0.02 0" quat="0.980067 0 0.198669 0" type="cylinder" group="4" rgba="0.19 0.83 0.78 0.2"/>
          <geom name="SM_at_condyles_l_cylinder" size="0.0345 0.05" pos="-0.001 -0.02 0" quat="0.99875 0 0.0499792 0" type="cylinder" group="4" rgba="0.19 0.83 0.78 0.2"/>
          <geom name="ST_at_condyles_l_cylinder" size="0.0425 0.05" pos="-0.002 -0.0205 0" quat="0.995004 0 0.0998334 0" type="cylinder" group="4" rgba="0.19 0.83 0.78 0.2"/>
          <geom name="BF140_at_gastroc_l_cylinder" size="0.029 0.075" pos="-0.039 -0.06 0" type="cylinder" group="4" rgba="0.19 0.83 0.78 0.2"/>
          <site name="GasLat_at_shank_l_sidesite" pos="-0.06099 -0.06623 -0.01096" size="0.0005"/>
          <site name="GasMed_at_shank_l_sidesite" pos="-0.06712 -0.06882 0.005909" size="0.0005"/>
          <site name="bflh140_l_bflh140_l-P2" pos="-0.03436 -0.03648 -0.03618"/>
          <site name="bflh140_l_bflh140_l-P3" pos="-0.02704 -0.05008 -0.03476"/>
          <site name="bfsh140_l_bfsh140_l-P2" pos="-0.02866 -0.03284 -0.03204"/>
          <site name="BF140_at_gastroc_l_cylinder_bfsh140_l_1_sidesite" pos="-0.0330663 -0.0257096 -0.0572595" size="0.0005"/>
          <site name="edl_l_edl_l-P1" pos="-0.016 -0.1157 -0.0205"/>
          <site name="edl_l_edl_l-P2" pos="0.0164 -0.376 -0.0112"/>
          <site name="ehl_l_ehl_l-P1" pos="-0.014 -0.155 -0.0189"/>
          <site name="ehl_l_ehl_l-P2" pos="0.0071 -0.2909 -0.0164"/>
          <site name="ehl_l_ehl_l-P3" pos="0.02 -0.3693 0.0028"/>
          <site name="fdl_l_fdl_l-P1" pos="-0.0023 -0.1832 0.0018"/>
          <site name="fdl_l_fdl_l-P2" pos="-0.0176 -0.3645 0.0124"/>
          <site name="fhl_l_fhl_l-P1" pos="-0.031 -0.2163 -0.02"/>
          <site name="fhl_l_fhl_l-P2" pos="-0.0242 -0.3671 0.0076"/>
          <site name="grac_l_grac_l-P2" pos="-0.01842 -0.04755 0.02961"/>
          <site name="grac_l_grac_l-P3" pos="0.00178 -0.06962 0.01573"/>
          <site name="GR_at_condyles_l_cylinder_grac_l_1_sidesite" pos="-0.01161 -0.0531856 0.050659" size="0.0005"/>
          <site name="perbrev_l_perbrev_l-P1" pos="-0.0243 -0.2532 -0.0251"/>
          <site name="perbrev_l_perbrev_l-P2" pos="-0.0339 -0.3893 -0.0249"/>
          <site name="perbrev_l_perbrev_l-P3" pos="-0.0285 -0.4004 -0.0255"/>
          <site name="perlong_l_perlong_l-P1" pos="-0.02 -0.1373 -0.0282"/>
          <site name="perlong_l_perlong_l-P2" pos="-0.0317 -0.39 -0.0237"/>
          <site name="perlong_l_perlong_l-P3" pos="-0.0272 -0.4014 -0.024"/>
          <site name="recfem_l_recfem_l-P5" pos="0.0326 -0.06312 0.00047"/>
          <site name="sart_l_sart_l-P3" pos="-0.0251 -0.0401 0.0365"/>
          <site name="sart_l_sart_l-P4" pos="-0.0159 -0.0599 0.0264"/>
          <site name="sart_l_sart_l-P5" pos="0.0136 -0.081 0.0026"/>
          <site name="semimem_l_semimem_l-P2" pos="-0.027 -0.041 0.0196"/>
          <site name="SM_at_condyles_l_cylinder_semimem_l_1_sidesite" pos="-0.0271739 0.00902271 0.0348628" size="0.0005"/>
          <site name="semiten_l_semiten_l-P2" pos="-0.0312 -0.0508 0.0229"/>
          <site name="semiten_l_semiten_l-P3" pos="0.0019 -0.0773 0.0117"/>
          <site name="ST_at_condyles_l_cylinder_semiten_l_1_sidesite" pos="-0.0355514 -0.0631554 -0.0247998" size="0.0005"/>
          <site name="soleus_l_soleus_l-P1" pos="-0.0076 -0.0916 -0.0098"/>
          <site name="tfl_l_tfl_l-P4" pos="0.0108 -0.041 -0.0346"/>
          <site name="tibant_l_tibant_l-P1" pos="0.0154 -0.1312 -0.0162"/>
          <site name="tibant_l_tibant_l-P2" pos="0.0251 -0.1906 -0.0128"/>
          <site name="tibant_l_tibant_l-P3" pos="0.0233 -0.3659 0.0132"/>
          <site name="tibpost_l_tibpost_l-P1" pos="-0.0041 -0.1304 -0.0103"/>
          <site name="tibpost_l_tibpost_l-P2" pos="-0.0164 -0.3655 0.0175"/>
          <site name="vasint_l_vasint_l-P5" pos="0.03257 -0.0632 -0.00043"/>
          <site name="vaslat140_l_vaslat140_l-P5" pos="0.03254 -0.06338 -0.00511"/>
          <site name="vasmed_l_vasmed_l-P5" pos="0.0319 -0.06357 0.00678"/>

          <body name="talus_l" pos="-0.01 -0.4 0">
          <!-- 动捕记录点-->
            <body name="SMPL_8" pos="0 0 0">
              <site name="SMPL_8" pos="0 0 0" rgba="1 0 0 1" type="sphere" size="0.01"/>
            </body>
            <inertial pos="0 0 0" mass="0.1" diaginertia="0.001 0.001 0.001"/>
            <joint name="ankle_angle_l" pos="0 0 0" axis="0.105003 0.174005 0.979131" range="-0.6981 0.5236" user="8.35266e-11"/>
            <geom name="talus_l_geom_1" type="mesh" rgba="1 1 1 1" mesh="talus_l_geom_1_l_talus"/>
            <body name="calcn_l" pos="-0.04877 -0.04195 -0.00792">
              <inertial pos="0.1 0.03 0" quat="0 0.707107 0 0.707107" mass="1.25" diaginertia="0.0041 0.0039 0.0014"/>
              <joint name="subtalar_angle_l" pos="0 0 0" axis="-0.787215 -0.604711 -0.120902" range="-0.6109 0.6109"/>
              <geom name="calcn_l_geom_1" type="mesh" rgba="1 1 1 1" mesh="calcn_l_geom_1_l_foot"/>
              <site name="edl_l_edl_l-P3" pos="0.0919 0.036 -0.0008"/>
              <site name="edl_l_edl_l-P4" pos="0.1616 0.0055 -0.013"/>
              <site name="ehl_l_ehl_l-P4" pos="0.097 0.0389 0.0211"/>
              <site name="ehl_l_ehl_l-P5" pos="0.1293 0.0309 0.0257"/>
              <site name="ehl_l_ehl_l-P6" pos="0.1734 0.0139 0.028"/>
              <site name="fdl_l_fdl_l-P3" pos="0.0436 0.0315 0.028"/>
              <site name="fdl_l_fdl_l-P4" pos="0.0708 0.0176 0.0263"/>
              <site name="fdl_l_fdl_l-P5" pos="0.1658 -0.0081 -0.0116"/>
              <site name="fhl_l_fhl_l-P3" pos="0.0374 0.0276 0.0241"/>
              <site name="fhl_l_fhl_l-P4" pos="0.1038 0.0068 0.0256"/>
              <site name="fhl_l_fhl_l-P5" pos="0.1726 -0.0053 0.0269"/>
              <site name="gaslat140_l_gaslat140_l-P2" pos="0.0044 0.031 0.0053"/>
              <site name="gasmed_l_gasmed_l-P2" pos="0.0044 0.031 0.0053"/>
              <site name="perbrev_l_perbrev_l-P4" pos="0.0471 0.027 -0.0233"/>
              <site name="perbrev_l_perbrev_l-P5" pos="0.0677 0.0219 -0.0343"/>
              <site name="perlong_l_perlong_l-P4" pos="0.0438 0.023 -0.0221"/>
              <site name="perlong_l_perlong_l-P5" pos="0.0681 0.0106 -0.0284"/>
              <site name="perlong_l_perlong_l-P6" pos="0.0852 0.0069 -0.0118"/>
              <site name="perlong_l_perlong_l-P7" pos="0.1203 0.0085 0.0184"/>
              <site name="soleus_l_soleus_l-P2" pos="0.0044 0.031 0.0053"/>
              <site name="tibant_l_tibant_l-P4" pos="0.1166 0.0178 0.0305"/>
              <site name="tibpost_l_tibpost_l-P3" pos="0.0417 0.0334 0.0286"/>
              <site name="tibpost_l_tibpost_l-P4" pos="0.0772 0.0159 0.0281"/>
              <body name="toes_l" pos="0.1788 -0.002 -0.00108">

                <body name="SMPL_11" pos="0 0 0">
                  <site name="SMPL_11" pos="0 0 0" rgba="1 0 0 1" type="sphere" size="0.01"/>
                </body>
                <inertial pos="0.0346 0.006 0.0175" quat="0 0.707107 0 0.707107" mass="0.2166" diaginertia="0.001 0.001 0.001"/>
                <joint name="mtp_angle_l" pos="0 0 0" axis="-0.581002 2.16001e-06 -0.813902" range="-0.5236 0.5236"/>
                <geom name="toes_l_geom_1" type="mesh" rgba="1 1 1 1" mesh="toes_l_geom_1_l_bofoot"/>
                <site name="edl_l_edl_l-P5" pos="0.0003 0.0047 -0.0153"/>
                <site name="edl_l_edl_l-P6" pos="0.0443 -0.0004 -0.025"/>
                <site name="ehl_l_ehl_l-P7" pos="0.0298 0.0041 0.0245"/>
                <site name="ehl_l_ehl_l-P8" pos="0.0563 0.0034 0.0186"/>
                <site name="fdl_l_fdl_l-P6" pos="-0.0019 -0.0078 -0.0147"/>
                <site name="fdl_l_fdl_l-P7" pos="0.0285 -0.0071 -0.0215"/>
                <site name="fdl_l_fdl_l-P8" pos="0.0441 -0.006 -0.0242"/>
                <site name="fhl_l_fhl_l-P6" pos="0.0155 -0.0064 0.0265"/>
                <site name="fhl_l_fhl_l-P7" pos="0.0562 -0.0102 0.0181"/>
              </body>
            </body>
          </body>
        </body>
        <body name="patella_l" pos="-0.00809 -0.408 0.00275">
          <inertial pos="0.0018 0.0264 0" quat="0.5 0.5 0.5 0.5" mass="0.0862" diaginertia="0.001 0.001 0.001"/>
          <joint name="patellofemoral_l_translation1" pos="0 0 0" axis="1 0 0" type="slide" range="-0.0227 0.0524" user="0.0524185"/>
          <joint name="patellofemoral_l_translation2" pos="0 0 0" axis="0 1 0" type="slide" range="-0.0408 -0.0108" user="-0.0108305"/>
          <joint name="patellofemoral_l_translation3" pos="0 0 0" axis="0 0 1" limited="false" type="slide"/>
          <joint name="patellofemoral_l_rotation1" pos="0 0 0" axis="0 0 1" range="-1.786 0.001137" user="0.0105072"/>
          <geom name="patella_l_geom_1" type="mesh" rgba="1 1 1 1" mesh="patella_l_geom_1_l_patella"/>
          <site name="recfem_l_recfem_l-P2" pos="0.01 0.049 -0.0007"/>
          <site name="recfem_l_recfem_l-P3" pos="0.0121 0.0437 0.001"/>
          <site name="recfem_l_recfem_l-P4" pos="0.005 0.00247 -3e-05"/>
          <site name="vasint_l_vasint_l-P3" pos="0.0058 0.048 0.0006"/>
          <site name="vasint_l_vasint_l-P4" pos="0.005 0.00247 0.00039"/>
          <site name="vaslat140_l_vaslat140_l-P3" pos="0.0103 0.0423 -0.0141"/>
          <site name="vaslat140_l_vaslat140_l-P4" pos="0.005 0.00247 -0.00733"/>
          <site name="vasmed_l_vasmed_l-P3" pos="0.0063 0.0445 0.017"/>
          <site name="vasmed_l_vasmed_l-P4" pos="0.005 0.00247 0.0085"/>
        </body>
      </body>
      <!-- 躯干 , 在此处拼接两个模型 -->
      <body name="torso" pos="-0.1007 0.0815 0">
        <!-- 动捕点记录     -->
        <body name="SMPL_0" pos="0 0 0">
          <site name="SMPL_0" pos="0 0 0" rgba="1 0 0 1" type="sphere" size="0.01"/>
        </body>
        <!--  拼接胸廓  -->
        <geom name="body" type="mesh" mesh="human_body" euler="0 0 0" contype="0" conaffinity="0" pos="0 0.38 0"/>
        <body name="full_body" euler="-1.57 0 1.57" pos="0 0.38 0">
          <include file="./1017/assets/bi_myoarm_body.xml"/>
          <body name="SMPL_12" pos="0 0.01 0.02">
            <site name="SMPL_12" pos="0 0.01 0.02" rgba="0 0 1 1" type="sphere" size="0.01"/>
          </body>
        </body>

        <inertial pos="-0.03 0.32 0" quat="0.707107 0.707107 0 0" mass="33.8996" diaginertia="1.4745 1.4314 0.7555"/>
        <joint name="lumbar_extension" pos="0 0 0" axis="0 0 1" range="-1.222 0.3491"/>
        <joint name="lumbar_bending" pos="0 0 0" axis="1 0 0" range="-0.5236 0.5236"/>
        <joint name="lumbar_rotation" pos="0 0 0" axis="0 1 0" range="-0.6981 0.6981"/>
        <geom name="torso_geom_1" type="mesh" rgba="1 1 1 1" mesh="torso_geom_1_hat_spine"/>
        <geom name="torso_geom_2" type="mesh" rgba="1 1 1 1" mesh="torso_geom_2_hat_jaw"/>
        <geom name="torso_geom_3" type="mesh" rgba="1 1 1 1" mesh="torso_geom_3_hat_skull"/>

<!--        原来的胸廓,通过对齐两个模型的胸廓将两个模型拼接-->
<!--        <geom name="torso_geom_4" type="mesh" rgba="1 1 1 1" mesh="torso_geom_4_hat_ribs_scap"/>-->
        <site name="ercspn_r_ercspn_r-P2" pos="-0.065 0.11 0.0241"/>
        <site name="extobl_r_extobl_r-P2" pos="0.045 0.11 0.12"/>
        <site name="intobl_r_intobl_r-P2" pos="0.06 0.16 0.045"/>
        <site name="rectab_r_rectab_r-P2" pos="0.09 0.19 0.05"/>
        <site name="ercspn_l_ercspn_l-P2" pos="-0.065 0.11 -0.0241"/>
        <site name="extobl_l_extobl_l-P2" pos="0.045 0.11 -0.12"/>
        <site name="intobl_l_intobl_l-P2" pos="0.06 0.16 -0.045"/>
        <site name="rectab_l_rectab_l-P2" pos="0.09 0.19 -0.05"/>
      </body>
    </body>
  </body>
</mujocoinclude>