<mujoco model="template">
  <!-- This model has been converted from an OpenSim model. Model conversion by MyoConverter https://github.com/MyoHub/myoconverter. This model is licensed under Apache 2.0. -->
  <compiler angle="radian" autolimits="true"/>

  <option timestep="0.005" />
  <size njmax="1000" nconmax="400" nkey="1" nuser_jnt="1"/>
  <visual>
<!--    <global rgba="0 0 0 1"/>-->
    <scale framelength="0.5" framewidth="0.01"/>
  </visual>
  <statistic meansize="0.167309" extent="2.0279" center="0 0 -0.0139475"/>

  <!-- 胳膊-->
  <include file="./1017/assets/bi_myoarm_assets.xml"/>

  <default class="main">
    <joint limited="true" armature="1e-05" damping="0.05"/>
    <geom margin="0.001" rgba="0.8 0.6 0.4 1" contype="0" conaffinity="0"/>
    <site size="0.001 0.005 0.005"/>
    <tendon limited="false" width="0.005" rgba="0.95 0.3 0.3 1"/>
    <default class="muscle">
      <general ctrllimited="true" ctrlrange="0 1" dyntype="muscle" gaintype="muscle" biastype="muscle" dynprm="0.01 0.04 0 0 0 0 0 0 0 0" gainprm="0.75 1.05 -1 200 0.5 1.6 1.5 1.3 1.2 0" biasprm="0.75 1.05 -1 200 0.5 1.6 1.5 1.3 1.2 0"/>
    </default>
    <default class="motor">
      <general gainprm="5 0 0 0 0 0 0 0 0 0"/>
    </default>
    <!--上肢参数 -->
    <default class="arm">
      <joint limited="true" damping="1.05" armature="1e-4" stiffness="0"/>
      <geom margin="0.001" rgba="0.8 0.8 0.8 1" contype="1" conaffinity="0"/>
      <site size="0.0025" group="4"/>
      <tendon rgba="0.95 0.3 0.3 41" width="0.003"/>
      <default class="myohand_coll">
        <geom type="capsule" group="4" contype="0" conaffinity="0" condim="3" rgba="0.8 0.7 .5 1" margin="0.001" material="MatSkin"/>
      </default>
      <default class="myoarm_coll">
        <geom type="capsule" group="4" contype="0" conaffinity="0" condim="3" rgba="0.8 0.7 .5 1" margin="0.001" material="MatSkin"/>
      </default>
      <default class="wrap">
        <geom group="3" rgba="0.19 0.83 0.78 0.2"/>
      </default>
      <default class="marker">
        <site rgba="1 0.1 0.5 0.5" size="0.001" group="4"/>
      </default>
    </default>
    <default class="upperarm_muscle">
      <general biasprm="0.75 1.05 -1 200 0.5 1.6 1.5 1.3 1.2 0" biastype="muscle" ctrllimited="true" ctrlrange="0 1" dynprm="0.01 0.04 0 0 0 0 0 0 0 0" dyntype="muscle" gainprm="0.75 1.05 -1 200 0.5 1.6 1.5 1.3 1.2 0" gaintype="muscle"/>
      <tendon rgba="0.95 0.3 0.3 41" width="0.007"/>
    </default>
    <default class="forearm_muscle">
      <muscle ctrllimited="true" ctrlrange="0 1" />
      <tendon rgba="0.95 0.3 0.3 41" width="0.002"/>
    </default>
    <default class="elbow">
      <joint limited="true" damping="0.75" armature="1e-4" stiffness="0"/>
      <geom margin="0.001" rgba="0.8 0.8 0.8 1" contype="1" conaffinity="0"/>
      <site size="0.0025" group="4"/>
      <tendon rgba="0.95 0.3 0.3 41" width="0.002"/>
    </default>
    <default class="wrist">
      <joint limited="true" damping=".05" armature="1e-4" stiffness="0"/>
      <geom margin="0.001" rgba="0.8 0.8 0.8 1" contype="1" conaffinity="0"/>
      <site size="0.0025" group="4"/>
      <tendon rgba="0.95 0.3 0.3 41" width="0.002"/>
    </default>
    <default class="fingers">
      <joint limited="true" damping=".05" armature="1e-4" stiffness="0"/>
      <geom margin="0.001" rgba="0.8 0.8 0.8 1" contype="1" conaffinity="0"/>
      <site size="0.0025" group="4"/>
    </default>
  </default>


  <asset>
    <!--  胸廓  -->
    <mesh name="human_body" file="./1017/meshes/thorax_our.stl"/>

<!--    <texture type="skybox" builtin="gradient" rgb1="1 1 1" rgb2="0.6 0.8 1" width="256" height="1536"/>-->
    <texture type="skybox" builtin="gradient" rgb1="0 0 0" rgb2="0 0 0" width="256" height="1536"/>
    <mesh name="pelvis_geom_1_r_pelvis" file="Geometry/r_pelvis.stl"/>
    <mesh name="pelvis_geom_2_l_pelvis" file="Geometry/l_pelvis.stl"/>
    <mesh name="pelvis_geom_3_sacrum" file="Geometry/sacrum.stl"/>
    <mesh name="femur_r_geom_1_r_femur" file="Geometry/r_femur.stl"/>
    <mesh name="tibia_r_geom_1_r_tibia" file="Geometry/r_tibia.stl"/>
    <mesh name="tibia_r_geom_2_r_fibula" file="Geometry/r_fibula.stl"/>
    <mesh name="talus_r_geom_1_r_talus" file="Geometry/r_talus.stl"/>
    <mesh name="calcn_r_geom_1_r_foot" file="Geometry/r_foot.stl"/>
    <mesh name="toes_r_geom_1_r_bofoot" file="Geometry/r_bofoot.stl"/>
    <mesh name="patella_r_geom_1_r_patella" file="Geometry/r_patella.stl"/>
    <mesh name="femur_l_geom_1_l_femur" file="Geometry/l_femur.stl"/>
    <mesh name="tibia_l_geom_1_l_tibia" file="Geometry/l_tibia.stl"/>
    <mesh name="tibia_l_geom_2_l_fibula" file="Geometry/l_fibula.stl"/>
    <mesh name="talus_l_geom_1_l_talus" file="Geometry/l_talus.stl"/>
    <mesh name="calcn_l_geom_1_l_foot" file="Geometry/l_foot.stl"/>
    <mesh name="toes_l_geom_1_l_bofoot" file="Geometry/l_bofoot.stl"/>
    <mesh name="patella_l_geom_1_l_patella" file="Geometry/l_patella.stl"/>
    <mesh name="torso_geom_1_hat_spine" file="Geometry/hat_spine.stl"/>
    <mesh name="torso_geom_2_hat_jaw" file="Geometry/hat_jaw.stl"/>
    <mesh name="torso_geom_3_hat_skull" file="Geometry/hat_skull.stl"/>
    <mesh name="torso_geom_4_hat_ribs_scap" file="Geometry/hat_ribs_scap.stl"/>
  </asset>




  <worldbody>

    <camera name="third_person" mode="trackcom" pos="1.5 0 0" target="SMPL_0" quat="0.5 0.5 0.5 0.5" fovy="90"/>
    
    <body mocap="true" name="mocap_0_body_ani" pos="-0.101 0 0.0815" quat="1 0 0 0">
      <site pos="0 0 0.200" size="0.003 0.003 0.200" type="box" name="body_0" rgba="0 0 1 0.5"/>
    </body>
    <body mocap="true" name="mocap_12_body_ani" pos="-0.1107 -0.0001 0.4815" quat="1 0 0 0">
      <site pos="0 0 0" rgba="1 0 1 0.5" type="sphere" size="0.01"/>
    </body>
    
    <!--    左腿的5个chain，从上往下123分别为髋关节/膝关节/踝关节-->
    <body mocap="true" name="mocap_0_ani" pos="-0.101 0 0.0815" quat="1 0 0 0">
      <site pos="0 0 -0.091" size="0.003 0.003 0.091" type="box" name="left_0" rgba="0 0 1 0.5"/>
    </body>
    <body mocap="true" name="mocap_1_ani" pos="-0.05628 -0.07724 -0.07851" quat="1 0 0 0">
      <site pos="0 0 -0.203" size="0.003 0.003 0.203" type="box" rgba="0 0 1 0.5"/>
      <site pos="0 0 0" rgba="0 1 0 0.5" type="sphere" size="0.01"/>
    </body>
    <body mocap="true" name="mocap_4_ani" pos="-0.05269 -0.0769 -0.4846" quat="1 0 0 0">
      <site pos="0 0 -0.200" size="0.003 0.003 0.200" type="box" rgba="0 0 1 0.5"/>
      <site pos="0 0 0" rgba="0 1 0 0.5" type="sphere" size="0.01"/>
    </body>
    <body mocap="true" name="mocap_7_ani" pos="-0.06269 -0.0768 -0.8846" quat="1 0 0 0">
      <site pos="0.069 0 0" size="0.069 0.003 0.003" type="box" rgba="0 0 1 0.5"/>
      <site pos="0 0 0" rgba="0 1 0 0.5" type="sphere" size="0.01"/>
    </body>
    <body mocap="true" name="mocap_10_ani" pos="0.0673 -0.0858 -0.9286" quat="1 0 0 0">
      <site pos="0 0 0" rgba="0 1 0 0.5" type="sphere" size="0.01"/>
    </body>
<!--右腿的5个动捕点-->
    <body mocap="true" name="mocap_0_right_ani" pos="-0.101 0 0.0815" quat="1 0 0 0">
      <site pos="0 0 -0.091" size="0.003 0.003 0.091" type="box" name="right_0" rgba="0 0 1 0.5"/>
    </body>
    <body mocap="true" name="mocap_2_ani" pos="-0.05628 0.07728 -0.07709" quat="1 0 0 0">
      <site pos="0 0 -0.203" size="0.003 0.003 0.203" type="box" rgba="0 0 1 0.5"/>
      <site pos="0 0 0" rgba="1 0 1 0.5" type="sphere" size="0.01"/>
    </body>
    <body mocap="true" name="mocap_5_ani" pos="-0.05269 0.0771 -0.4846" quat="1 0 0 0">
      <site pos="0 0 -0.200" size="0.003 0.003 0.200" type="box" rgba="0 0 1 0.5"/>
      <site pos="0 0 0" rgba="1 0 1 0.5" type="sphere" size="0.01"/>
    </body>
    <body mocap="true" name="mocap_8_ani" pos="-0.06227 0.07717 -0.8846" quat="1 0 0 0">
      <site pos="0.069 0 0" size="0.069 0.003 0.003" type="box" rgba="0 0 1 0.5"/>
      <site pos="0 0 0" rgba="1 0 1 1" type="sphere" size="0.01"/>
    </body>      
    <body mocap="true" name="mocap_11_ani" pos="0.0673 0.0862 -0.9285" quat="1 0 0 0">
      <site pos="0 0 0" rgba="1 0 1 0.5" type="sphere" size="0.01"/>
    </body>

    <!--    右手的5个chain，从上往下123分别为髋关节/膝关节/踝关节-->
    <body mocap="true" name="mocap_12_ani" pos="-0.1107 -0.0001 0.4815" quat="1 0 0 0">
      <site pos="0 0.0829 0" size="0.003 0.0829 0.003" type="box" name="right_12" rgba="0 0 1 0.5"/>
    </body>
    <body mocap="true" name="mocap_17_ani" pos="-0.09898 0.1631 0.4547" quat="1 0 0 0">
      <site pos="0 0 -0.1455" size="0.003 0.003 0.1455" type="box" rgba="0 0 1 0.5"/>
      <site pos="0 0 0" rgba="1 0 1 0.5" type="sphere" size="0.01"/>
    </body>
    <body mocap="true" name="mocap_19_ani" pos="-0.09289 0.1511 0.1643" quat="1 0 0 0">
      <site pos="0 0 -0.129" size="0.003 0.003 0.129" type="box" rgba="0 0 1 0.5"/>
      <site pos="0 0 0" rgba="1 0 1 0.5" type="sphere" size="0.01"/>
    </body>
    <body mocap="true" name="mocap_21_ani" pos="-0.07445 0.1963 -0.0892" quat="1 0 0 0">
      <site pos="0 0 -0.063" size="0.003 0.003 0.063" type="box" rgba="0 0 1 0.5"/>
      <site pos="0 0 0" rgba="1 0 1 0.5" type="sphere" size="0.01"/>
    </body>
    <body mocap="true" name="mocap_41_ani" pos="-0.0681 0.2141 -0.2140" quat="1 0 0 0">
      <site pos="0 0 0" rgba="1 0 1 0.5" type="sphere" size="0.01"/>
    </body>
<!--左手的5个动捕点-->
    <body mocap="true" name="mocap_12_left_ani" pos="-0.1107 -0.0001 0.4815" quat="1 0 0 0">
      <site pos="0 -0.0829 0" size="0.003 0.0829 0.003" type="box" name="left_12" rgba="0 0 1 0.5"/>
    </body>
    <body mocap="true" name="mocap_16_ani" pos="-0.09924 -0.1633 0.4543" quat="1 0 0 0">
      <site pos="0 0 -0.1455" size="0.003 0.003 0.1455" type="box" rgba="0 0 1 0.5"/>
      <site pos="0 0 0" rgba="0 1 0 0.5" type="sphere" size="0.01"/>
    </body>
    <body mocap="true" name="mocap_18_ani" pos="-0.09313 -0.1507 0.1639" quat="1 0 0 0">
      <site pos="0 0 -0.129" size="0.003 0.003 0.129" type="box" rgba="0 0 1 0.5"/>
      <site pos="0 0 0" rgba="0 1 0 0.5" type="sphere" size="0.01"/>
    </body>
    <body mocap="true" name="mocap_20_ani" pos="-0.07476 -0.1954 -0.0896" quat="1 0 0 0">
      <site pos="0 0 -0.063" size="0.003 0.003 0.063" type="box" rgba="0 0 1 0.5"/>
      <site pos="0 0 0" rgba="0 1 0 0.5" type="sphere" size="0.01"/>
    </body>
    <body mocap="true" name="mocap_26_ani" pos="-0.0684 -0.2130 -0.2144" quat="1 0 0 0">
      <site pos="0 0 0" rgba="0 1 0 0.5" type="sphere" size="0.01"/>
    </body>
    <!-- 跟踪 -->
    <body mocap="true" name="mocap_0" pos="-0.101 0 0.0815" quat="1 0 0 0"></body>
    <body mocap="true" name="mocap_12" pos="-0.1107 -0.0001 0.4815" quat="1 0 0 0"></body>
    
    <!--    左腿的5个chain，从上往下123分别为髋关节/膝关节/踝关节-->
   
    <body mocap="true" name="mocap_1" pos="-0.05628 -0.07724 -0.07851" quat="1 0 0 0"></body>
    <body mocap="true" name="mocap_4" pos="-0.05269 -0.0769 -0.4846" quat="1 0 0 0"></body>
    <body mocap="true" name="mocap_7" pos="-0.06269 -0.0768 -0.8846" quat="1 0 0 0"></body>
    <body mocap="true" name="mocap_10" pos="0.0673 -0.0858 -0.9286" quat="1 0 0 0"></body>
<!--右腿的5个动捕点-->

    <body mocap="true" name="mocap_2" pos="-0.05628 0.07728 -0.07709" quat="1 0 0 0"></body>
    <body mocap="true" name="mocap_5" pos="-0.05269 0.0771 -0.4846" quat="1 0 0 0"></body>
    <body mocap="true" name="mocap_8" pos="-0.06227 0.07717 -0.8846" quat="1 0 0 0"></body>      
    <body mocap="true" name="mocap_11" pos="0.0673 0.0862 -0.9285" quat="1 0 0 0"></body>

    <!--    右手的5个chain，从上往下123分别为髋关节/膝关节/踝关节-->
  
    <body mocap="true" name="mocap_17" pos="-0.09898 0.1631 0.4547" quat="1 0 0 0"></body>
    <body mocap="true" name="mocap_19" pos="-0.09289 0.1511 0.1643" quat="1 0 0 0"></body>
    <body mocap="true" name="mocap_21" pos="-0.07445 0.1963 -0.0892" quat="1 0 0 0"></body>
    <!-- <body mocap="true" name="mocap_41_ani" pos="-0.0681 0.2141 -0.2140" quat="1 0 0 0"></body> -->
<!--左手的5个动捕点-->
  
    <body mocap="true" name="mocap_16" pos="-0.09924 -0.1633 0.4543" quat="1 0 0 0"></body>
    <body mocap="true" name="mocap_18" pos="-0.09313 -0.1507 0.1639" quat="1 0 0 0"></body>
    <body mocap="true" name="mocap_20" pos="-0.07476 -0.1954 -0.0896" quat="1 0 0 0"></body>
    <!-- <body mocap="true" name="mocap_26_ani" pos="-0.0684 -0.2130 -0.2144" quat="1 0 0 0"></body> -->


<!--    <light pos="0 0 0" dir="0 0 -1" directional="true"/>-->
    <!-- <body name="ground" pos="0 0 -0.79449517" quat="0.707035 0.707179 0 0">
      <geom name="ground-plane" size="10 10 0.125" quat="0.707035 -0.707179 0 0" type="plane" rgba="1 0.7 0.4 1" contype="1" conaffinity="1"/>
    </body> -->
    <!--  盆骨  -->
    <body name="pelvis"  quat="0.707035 0.707179 0 0">
      <inertial pos="-0.0707 0 0" mass="11.777" diaginertia="0.1028 0.0871 0.0579"/>
      <joint name="pelvis_tx" pos="0 0 0" axis="1 0 0" type="slide" range="-5 5" damping="0"/>
      <joint name="pelvis_ty" pos="0 0 0" axis="0 1 0" type="slide" range="-1 2" damping="0" user="0.93"/>
      <joint name="pelvis_tz" pos="0 0 0" axis="0 0 1" type="slide" range="-3 3" damping="0"/>
      <joint name="pelvis_tilt" pos="0 0 0" axis="0 0 1" range="-1.571 1.571" damping="0"/>
      <joint name="pelvis_list" pos="0 0 0" axis="1 0 0" range="-1.571 1.571" damping="0"/>
      <joint name="pelvis_rotation" pos="0 0 0" axis="0 1 0" range="-1.571 1.571" damping="0"/>
      <geom name="pelvis_geom_1" type="mesh" rgba="1 1 1 1" mesh="pelvis_geom_1_r_pelvis"/>
      <geom name="pelvis_geom_2" type="mesh" rgba="1 1 1 1" mesh="pelvis_geom_2_l_pelvis"/>
      <geom name="pelvis_geom_3" type="mesh" rgba="1 1 1 1" mesh="pelvis_geom_3_sacrum"/>
      <geom name="Gmax1_at_pelvis_r_cylinder" size="0.04 0.075" pos="-0.077 -0.099 0.061" quat="0.931256 -0.288071 0.213142 -0.0659324" type="cylinder" group="4" rgba="0.19 0.83 0.78 0.2"/>
      <geom name="Gmax2_at_pelvis_r_cylinder" size="0.04 0.05" pos="-0.08 -0.083 0.068" quat="0.912872 -0.359331 0.180301 -0.0709714" type="cylinder" group="4" rgba="0.19 0.83 0.78 0.2"/>
      <geom name="Gmax3_at_pelvis_r_cylinder" size="0.04 0.05" pos="-0.083 -0.088 0.068" quat="0.99875 -0.0499792 0 0" type="cylinder" group="4" rgba="0.19 0.83 0.78 0.2"/>
      <geom name="Gmax1_at_pelvis_l_cylinder" size="0.04 0.075" pos="-0.077 -0.099 -0.061" quat="0.931256 0.288071 -0.213142 -0.0659324" type="cylinder" group="4" rgba="0.19 0.83 0.78 0.2"/>
      <geom name="Gmax2_at_pelvis_l_cylinder" size="0.04 0.05" pos="-0.08 -0.083 -0.068" quat="0.912872 0.359331 -0.180301 -0.0709714" type="cylinder" group="4" rgba="0.19 0.83 0.78 0.2"/>
      <geom name="Gmax3_at_pelvis_l_cylinder" size="0.04 0.05" pos="-0.083 -0.088 -0.068" quat="0.99875 0.0499792 0 0" type="cylinder" group="4" rgba="0.19 0.83 0.78 0.2"/>
      <geom name="PS_at_brim_r_cylinder" size="0.05 0.05" pos="-0.074 -0.06 0.0656" quat="0.981103 -0.13006 -0.127199 0.0658971" type="cylinder" group="4" rgba="0.19 0.83 0.78 0.2"/>
      <geom name="PS_at_brim_l_cylinder" size="0.05 0.05" pos="-0.074 -0.06 -0.0656" quat="0.981103 0.13006 0.127199 0.0658971" type="cylinder" group="4" rgba="0.19 0.83 0.78 0.2"/>
      <geom name="IL_at_brim_r_cylinder" size="0.0549 0.05" pos="-0.071 -0.065 0.0756" quat="0.874257 -0.193832 -0.0376181 0.443495" type="cylinder" group="4" rgba="0.19 0.83 0.78 0.2"/>
      <geom name="IL_at_brim_l_cylinder" size="0.0549 0.05" pos="-0.071 -0.065 -0.0756" quat="0.874257 0.193832 0.0376181 0.443495" type="cylinder" group="4" rgba="0.19 0.83 0.78 0.2"/>
      <site name="Gmax1_at_pelvis_r_sidesite" pos="-0.1139 -0.08893 0.07572" size="0.0005"/>
      <site name="Gmax1_at_pelvis_l_sidesite" pos="-0.1139 -0.08893 -0.07572" size="0.0005"/>
      <site name="PS_at_brim_r_sidesite" pos="-0.06909 -0.1088 0.07947" size="0.0005"/>
      <site name="PS_at_brim_l_sidesite" pos="-0.06909 -0.1088 -0.07947" size="0.0005"/>
      <site name="IL_at_brim_r_sidesite" pos="-0.02847 -0.09471 0.09641" size="0.0005"/>
      <site name="IL_at_brim_l_sidesite" pos="-0.02847 -0.09471 -0.09641" size="0.0005"/>
      <site name="addbrev_r_addbrev_r-P1" pos="-0.0191 -0.094 0.0154"/>
      <site name="addlong_r_addlong_r-P1" pos="-0.00758 -0.0889 0.01888"/>
      <site name="addmagDist_r_addmagDist_r-P1" pos="-0.07404 -0.12767 0.03982"/>
      <site name="addmagIsch_r_addmagIsch_r-P1" pos="-0.08962 -0.12976 0.04171"/>
      <site name="addmagMid_r_addmagMid_r-P1" pos="-0.05266 -0.12075 0.02854"/>
      <site name="addmagProx_r_addmagProx_r-P1" pos="-0.03098 -0.10755 0.01365"/>
      <site name="bflh140_r_bflh140_r-P1" pos="-0.104 -0.1191 0.0586"/>
      <site name="ercspn_r_ercspn_r-P1" pos="-0.15 0.0439 0.0436"/>
      <site name="extobl_r_extobl_r-P1" pos="-0.04 -0.055 0.05"/>
      <site name="gem_r_gem_r-P1" pos="-0.10357 -0.0764 0.06707"/>
      <site name="glmax1_r_glmax1_r-P1" pos="-0.1231 0.0345 0.0563"/>
      <site name="glmax1_r_glmax1_r-P2" pos="-0.1257 -0.0242 0.0779"/>
      <site name="Gmax1_at_pelvis_r_cylinder_glmax1_r_2_sidesite" pos="-0.102812 -0.084971 0.111667" size="0.0005"/>
      <site name="glmax2_r_glmax2_r-P1" pos="-0.1317 0.0087 0.0462"/>
      <site name="glmax2_r_glmax2_r-P2" pos="-0.1344 -0.0609 0.0813"/>
      <site name="Gmax2_at_pelvis_r_cylinder_glmax2_r_2_sidesite" pos="-0.115443 -0.07535 0.102803" size="0.0005"/>
      <site name="glmax3_r_glmax3_r-P1" pos="-0.13 -0.0525 0.009"/>
      <site name="glmax3_r_glmax3_r-P2" pos="-0.1273 -0.1263 0.0435"/>
      <site name="Gmax3_at_pelvis_r_cylinder_glmax3_r_1_sidesite" pos="0.317 0.312 0.468" size="0.0005"/>
      <site name="glmed1_r_glmed1_r-P1" pos="-0.0445 0.0245 0.1172"/>
      <site name="glmed2_r_glmed2_r-P1" pos="-0.085 0.0316 0.0675"/>
      <site name="glmed3_r_glmed3_r-P1" pos="-0.1152 -0.0073 0.0526"/>
      <site name="glmin1_r_glmin1_r-P1" pos="-0.0464 -0.0149 0.1042"/>
      <site name="glmin2_r_glmin2_r-P1" pos="-0.0616 -0.0142 0.0971"/>
      <site name="glmin3_r_glmin3_r-P1" pos="-0.0789 -0.0155 0.0798"/>
      <site name="grac_r_grac_r-P1" pos="-0.04736 -0.12932 0.02456"/>
      <site name="iliacus_r_iliacus_r-P1" pos="-0.0605 0.0309 0.0843"/>
      <site name="iliacus_r_iliacus_r-P2" pos="-0.0135 -0.0557 0.0756"/>
      <site name="IL_at_brim_r_cylinder_iliacus_r_2_sidesite" pos="0.00262162 -0.0899044 0.050451" size="0.0005"/>
      <site name="intobl_r_intobl_r-P1" pos="-0.05 0.07 0.1157"/>
      <site name="obtext_r_obtext_r-P1" pos="-0.054 -0.111 0.026"/>
      <site name="obtint_r_obtint_r-P1" pos="-0.062 -0.114 0.029"/>
      <site name="obtint_r_obtint_r-P2" pos="-0.111 -0.083 0.047"/>
      <site name="pect_r_pect_r-P1" pos="-0.0232 -0.08325 0.04529"/>
      <site name="piri_r_piri_r-P1" pos="-0.10181 -0.00653 0.01351"/>
      <site name="piri_r_piri_r-P2" pos="-0.10202 -0.03066 0.06092"/>
      <site name="psoas_r_psoas_r-P1" pos="-0.0606 0.062 0.039"/>
      <site name="psoas_r_psoas_r-P2" pos="-0.0205 -0.0654 0.0656"/>
      <site name="PS_at_brim_r_cylinder_psoas_r_2_sidesite" pos="-0.0240219 -0.0528315 0.109085" size="0.0005"/>
      <site name="quadfem_r_quadfem_r-P1" pos="-0.11192 -0.11473 0.05166"/>
      <site name="recfem_r_recfem_r-P1" pos="-0.024 -0.0388 0.0933"/>
      <site name="rectab_r_rectab_r-P1" pos="-0.025 -0.07 0.03"/>
      <site name="sart_r_sart_r-P1" pos="-0.0195 -0.0156 0.1056"/>
      <site name="semimem_r_semimem_r-P1" pos="-0.0987 -0.114 0.0614"/>
      <site name="semiten_r_semiten_r-P1" pos="-0.1038 -0.1253 0.0515"/>
      <site name="tfl_r_tfl_r-P1" pos="-0.0311 0.0214 0.1241"/>
      <site name="addbrev_l_addbrev_l-P1" pos="-0.0191 -0.094 -0.0154"/>
      <site name="addlong_l_addlong_l-P1" pos="-0.00758 -0.0889 -0.01888"/>
      <site name="addmagDist_l_addmagDist_l-P1" pos="-0.07404 -0.12767 -0.03982"/>
      <site name="addmagIsch_l_addmagIsch_l-P1" pos="-0.08962 -0.12976 -0.04171"/>
      <site name="addmagMid_l_addmagMid_l-P1" pos="-0.05266 -0.12075 -0.02854"/>
      <site name="addmagProx_l_addmagProx_l-P1" pos="-0.03098 -0.10755 -0.01365"/>
      <site name="bflh140_l_bflh140_l-P1" pos="-0.104 -0.1191 -0.0586"/>
      <site name="ercspn_l_ercspn_l-P1" pos="-0.15 0.0439 -0.0436"/>
      <site name="extobl_l_extobl_l-P1" pos="-0.04 -0.055 -0.05"/>
      <site name="gem_l_gem_l-P1" pos="-0.10357 -0.0764 -0.06707"/>
      <site name="glmax1_l_glmax1_l-P1" pos="-0.1231 0.0345 -0.0563"/>
      <site name="glmax1_l_glmax1_l-P2" pos="-0.1257 -0.0242 -0.0779"/>
      <site name="Gmax1_at_pelvis_l_cylinder_glmax1_l_2_sidesite" pos="-0.0886985 -0.0609517 -0.135862" size="0.0005"/>
      <site name="glmax2_l_glmax2_l-P1" pos="-0.1317 0.0087 -0.0462"/>
      <site name="glmax2_l_glmax2_l-P2" pos="-0.1344 -0.0609 -0.0813"/>
      <site name="Gmax2_at_pelvis_l_cylinder_glmax2_l_2_sidesite" pos="-0.11412 -0.0478044 -0.0898373" size="0.0005"/>
      <site name="glmax3_l_glmax3_l-P1" pos="-0.13 -0.0525 -0.009"/>
      <site name="glmax3_l_glmax3_l-P2" pos="-0.1273 -0.1263 -0.0435"/>
      <site name="Gmax3_at_pelvis_l_cylinder_glmax3_l_1_sidesite" pos="0.317 0.312 0.332" size="0.0005"/>
      <site name="glmed1_l_glmed1_l-P1" pos="-0.0445 0.0245 -0.1172"/>
      <site name="glmed2_l_glmed2_l-P1" pos="-0.085 0.0316 -0.0675"/>
      <site name="glmed3_l_glmed3_l-P1" pos="-0.1152 -0.0073 -0.0526"/>
      <site name="glmin1_l_glmin1_l-P1" pos="-0.0464 -0.0149 -0.1042"/>
      <site name="glmin2_l_glmin2_l-P1" pos="-0.0616 -0.0142 -0.0971"/>
      <site name="glmin3_l_glmin3_l-P1" pos="-0.0789 -0.0155 -0.0798"/>
      <site name="grac_l_grac_l-P1" pos="-0.04736 -0.12932 -0.02456"/>
      <site name="iliacus_l_iliacus_l-P1" pos="-0.0605 0.0309 -0.0843"/>
      <site name="iliacus_l_iliacus_l-P2" pos="-0.0135 -0.0557 -0.0756"/>
      <site name="IL_at_brim_l_cylinder_iliacus_l_2_sidesite" pos="-0.0524543 -0.00513011 -0.0545739" size="0.0005"/>
      <site name="intobl_l_intobl_l-P1" pos="-0.05 0.07 -0.1157"/>
      <site name="obtext_l_obtext_l-P1" pos="-0.054 -0.111 -0.026"/>
      <site name="obtint_l_obtint_l-P1" pos="-0.062 -0.114 -0.029"/>
      <site name="obtint_l_obtint_l-P2" pos="-0.111 -0.083 -0.047"/>
      <site name="pect_l_pect_l-P1" pos="-0.0232 -0.08325 -0.04529"/>
      <site name="piri_l_piri_l-P1" pos="-0.10181 -0.00653 -0.01351"/>
      <site name="piri_l_piri_l-P2" pos="-0.10202 -0.03066 -0.06092"/>
      <site name="psoas_l_psoas_l-P1" pos="-0.0606 0.062 -0.039"/>
      <site name="psoas_l_psoas_l-P2" pos="-0.0205 -0.0654 -0.0656"/>
      <site name="PS_at_brim_l_cylinder_psoas_l_2_sidesite" pos="-0.0227972 -0.0409222 -0.0984629" size="0.0005"/>
      <site name="quadfem_l_quadfem_l-P1" pos="-0.11192 -0.11473 -0.05166"/>
      <site name="recfem_l_recfem_l-P1" pos="-0.024 -0.0388 -0.0933"/>
      <site name="rectab_l_rectab_l-P1" pos="-0.025 -0.07 -0.03"/>
      <site name="sart_l_sart_l-P1" pos="-0.0195 -0.0156 -0.1056"/>
      <site name="semimem_l_semimem_l-P1" pos="-0.0987 -0.114 -0.0614"/>
      <site name="semiten_l_semiten_l-P1" pos="-0.1038 -0.1253 -0.0515"/>
      <site name="tfl_l_tfl_l-P1" pos="-0.0311 0.0214 -0.1241"/>
      <!--  右侧大腿股骨    -->
      <body name="femur_r" pos="-0.05628 -0.07849 0.07726">
        <!-- 髋关节动捕记录点    -->
        <body name="SMPL_1" pos="0 0 0">
          <site name="SMPL_1" pos="0 0 0" rgba="0 1 0 1" type="sphere" size="0.01"/>
        </body>

        <inertial pos="0 -0.17 0" quat="0.5 0.5 -0.5 0.5" mass="9.3014" diaginertia="0.1412 0.1339 0.0351"/>
        <joint name="hip_flexion_r" pos="0 0 0" axis="0 0 1" range="-0.5236 2.094" user="2.33205e-09"/>
        <joint name="hip_adduction_r" pos="0 0 0" axis="1 0 0" range="-0.8727 0.5236" user="-1.19929e-09"/>
        <joint name="hip_rotation_r" pos="0 0 0" axis="0 1 0" range="-0.6981 0.6981"/>
        <geom name="femur_r_geom_1" type="mesh" rgba="1 1 1 1" mesh="femur_r_geom_1_r_femur"/>
        <geom name="GasLat_at_condyles_r_cylinder" size="0.026 0.05" pos="0.005 -0.41 0" type="cylinder" group="4" rgba="0.19 0.83 0.78 0.2"/>
        <geom name="GasMed_at_condyles_r_cylinder" size="0.025 0.05" pos="0.005 -0.41 0" type="cylinder" group="4" rgba="0.19 0.83 0.78 0.2"/>
        <geom name="KnExt_at_fem_r_cylinder" size="0.025 0.05" pos="0.003588 -0.4027 0.002091" quat="0.999192 -0.0311549 0.0253649 -0.000790882" type="cylinder" group="4" rgba="0.19 0.83 0.78 0.2"/>
        <geom name="KnExtVL_at_fem_r_cylinder" size="0.025 0.05" pos="0.001888 -0.4027 0.002091" quat="0.999192 -0.0311549 0.0253649 -0.000790882" type="cylinder" group="4" rgba="0.19 0.83 0.78 0.2"/>
        <geom name="AB_at_femshaft_r_cylinder" size="0.0165 0.035" pos="0.01464 -0.1126 0.02337" quat="0.671205 0.735393 0.0628058 0.068812" type="cylinder" group="4" rgba="0.19 0.83 0.78 0.2"/>
        <geom name="AL_at_femshaft_r_cylinder" size="0.0201 0.05" pos="0.03073 -0.2319 0.01511" quat="0.629109 0.77432 0.0430035 0.0529295" type="cylinder" group="4" rgba="0.19 0.83 0.78 0.2"/>
        <geom name="AMprox_at_femshaft_r_cylinder" size="0.0211 0.035" pos="0.005183 -0.07289 0.0254" quat="0.689738 0.718041 0.0645399 0.0671882" type="cylinder" group="4" rgba="0.19 0.83 0.78 0.2"/>
        <geom name="AMmid_at_femshaft_r_cylinder" size="0.0214 0.06" pos="0.02301 -0.1607 0.02058" quat="0.691136 0.719496 0.0472781 0.0492181" type="cylinder" group="4" rgba="0.19 0.83 0.78 0.2"/>
        <geom name="AMdist_at_femshaft_r_cylinder" size="0.0218 0.1" pos="0.03161 -0.2607 0.009365" quat="0.652613 0.751942 0.0610661 0.0703605" type="cylinder" group="4" rgba="0.19 0.83 0.78 0.2"/>
        <geom name="AMisch_at_condyles_r_cylinder" size="0.04 0.12" pos="-0.02265 -0.3768 -0.003154" quat="0.638315 0.734726 -0.150602 -0.173349" type="cylinder" group="4" rgba="0.19 0.83 0.78 0.2"/>
        <geom name="PECT_at_femshaft_r_cylinder" size="0.015 0.025" pos="0.006086 -0.0845 0.03044" quat="0.610631 0.779849 0.0848995 0.108427" type="cylinder" group="4" rgba="0.19 0.83 0.78 0.2"/>
        <geom name="OBTEXT_at_femneck_r_cylinder" size="0.0136 0.024" pos="-0.005764 -0.01725 0.02336" quat="0.939344 0.325795 -0.101275 -0.0351255" type="cylinder" group="4" rgba="0.19 0.83 0.78 0.2"/>
        <site name="addbrev_r_addbrev_r-P2" pos="-0.002 -0.118 0.0249"/>
        <site name="AB_at_femshaft_r_cylinder_addbrev_r_1_sidesite" pos="0.0167109 -0.144235 0.00104369" size="0.0005"/>
        <site name="addlong_r_addlong_r-P2" pos="0.01126 -0.23937 0.01583"/>
        <site name="AL_at_femshaft_r_cylinder_addlong_r_1_sidesite" pos="0.01126 -0.2394 0.01583" size="0.0005"/>
        <site name="addmagDist_r_addmagDist_r-P2" pos="0.01125 -0.2625 0.0193"/>
        <site name="AMdist_at_femshaft_r_cylinder_addmagDist_r_1_sidesite" pos="0.00968235 -0.285318 0.00586558" size="0.0005"/>
        <site name="addmagIsch_r_addmagIsch_r-P2" pos="0.00481 -0.38797 -0.03273"/>
        <site name="AMisch_at_condyles_r_cylinder_addmagIsch_r_1_sidesite" pos="0.00481 -0.388 -0.03273" size="0.0005"/>
        <site name="addmagMid_r_addmagMid_r-P2" pos="0.00242 -0.1624 0.02922"/>
        <site name="AMmid_at_femshaft_r_cylinder_addmagMid_r_1_sidesite" pos="0.00242 -0.1624 0.02922" size="0.0005"/>
        <site name="addmagProx_r_addmagProx_r-P2" pos="-0.01527 -0.07886 0.03202"/>
        <site name="AMprox_at_femshaft_r_cylinder_addmagProx_r_1_sidesite" pos="-0.00447309 -0.0718189 0.00193965" size="0.0005"/>
        <site name="bfsh140_r_bfsh140_r-P1" pos="0.005 -0.2111 0.0234"/>
        <site name="gaslat140_r_gaslat140_r-P1" pos="0.002 -0.381 0.02059"/>
        <site name="GasLat_at_condyles_r_cylinder_gaslat140_r_1_sidesite" pos="-0.0185499 -0.389534 0.0360656" size="0.0005"/>
        <site name="gasmed_r_gasmed_r-P1" pos="0.006 -0.384 -0.022"/>
        <site name="GasMed_at_condyles_r_cylinder_gasmed_r_1_sidesite" pos="-0.0108691 -0.384541 -0.00961897" size="0.0005"/>
        <site name="gem_r_gem_r-P2" pos="-0.0142 -0.0033 0.0443"/>
        <site name="glmax1_r_glmax1_r-P3" pos="-0.0444 -0.0326 0.0302"/>
        <site name="glmax1_r_glmax1_r-P4" pos="-0.0277 -0.0566 0.047"/>
        <site name="glmax2_r_glmax2_r-P3" pos="-0.045 -0.0584 0.0252"/>
        <site name="glmax2_r_glmax2_r-P4" pos="-0.0156 -0.1016 0.0419"/>
        <site name="glmax3_r_glmax3_r-P3" pos="-0.0281 -0.1125 0.0094"/>
        <site name="glmax3_r_glmax3_r-P4" pos="-0.006 -0.1419 0.0411"/>
        <site name="glmed1_r_glmed1_r-P2" pos="-0.0218 -0.0117 0.0555"/>
        <site name="glmed2_r_glmed2_r-P2" pos="-0.0258 -0.0058 0.0527"/>
        <site name="glmed3_r_glmed3_r-P2" pos="-0.0309 -0.0047 0.0518"/>
        <site name="glmin1_r_glmin1_r-P2" pos="-0.0072 -0.0104 0.056"/>
        <site name="glmin2_r_glmin2_r-P2" pos="-0.0096 -0.0104 0.056"/>
        <site name="glmin3_r_glmin3_r-P2" pos="-0.0135 -0.0083 0.055"/>
        <site name="iliacus_r_iliacus_r-P3" pos="-0.0023 -0.0565 0.0139"/>
        <site name="iliacus_r_iliacus_r-P4" pos="-0.0122 -0.0637 0.0196"/>
        <site name="obtext_r_obtext_r-P2" pos="-0.025 -0.011 0.039"/>
        <site name="OBTEXT_at_femneck_r_cylinder_obtext_r_1_sidesite" pos="-0.0210016 -0.0162408 0.039308" size="0.0005"/>
        <site name="obtint_r_obtint_r-P3" pos="-0.0162 -0.0013 0.0443"/>
        <site name="pect_r_pect_r-P2" pos="-0.00797 -0.08518 0.02403"/>
        <site name="PECT_at_femshaft_r_cylinder_pect_r_1_sidesite" pos="-0.00797 -0.08518 0.02403" size="0.0005"/>
        <site name="piri_r_piri_r-P3" pos="-0.0148 -0.0036 0.0437"/>
        <site name="psoas_r_psoas_r-P3" pos="-0.0132 -0.0467 0.0046"/>
        <site name="psoas_r_psoas_r-P4" pos="-0.0235 -0.0524 0.0088"/>
        <site name="quadfem_r_quadfem_r-P2" pos="-0.03575 -0.03552 0.03612"/>
        <site name="KnExt_at_fem_r_cylinder_recfem_r_3_sidesite" pos="0.253588 -0.1527 0.252091" size="0.0005"/>
        <site name="sart_r_sart_r-P2" pos="-0.003 -0.3568 -0.0421"/>
        <site name="tfl_r_tfl_r-P2" pos="0.0294 -0.0995 0.0597"/>
        <site name="tfl_r_tfl_r-P3" pos="0.0107 -0.405 0.0324"/>
        <site name="vasint_r_vasint_r-P1" pos="0.029 -0.1924 0.031"/>
        <site name="vasint_r_vasint_r-P2" pos="0.0335 -0.2084 0.0285"/>
        <site name="KnExt_at_fem_r_cylinder_vasint_r_3_sidesite" pos="0.253588 -0.1527 0.252091" size="0.0005"/>
        <site name="vaslat140_r_vaslat140_r-P1" pos="0.0048 -0.1854 0.0349"/>
        <site name="vaslat140_r_vaslat140_r-P2" pos="0.0269 -0.2591 0.0409"/>
        <site name="KnExtVL_at_fem_r_cylinder_vaslat140_r_3_sidesite" pos="0.251888 -0.1527 0.252091" size="0.0005"/>
        <site name="vasmed_r_vasmed_r-P1" pos="0.014 -0.2099 0.0188"/>
        <site name="vasmed_r_vasmed_r-P2" pos="0.0356 -0.2769 0.0009"/>
        <site name="KnExt_at_fem_r_cylinder_vasmed_r_4_sidesite" pos="-0.007846 -0.4075 -0.02075" size="0.0005"/>
        <site name="KnExt_at_fem_r_cylinder_vasmed_r_3_sidesite" pos="-0.007846 -0.4075 -0.02075" size="0.0005"/>

        <!--   （胫骨）人体小腿内侧的长骨     -->
        <body name="tibia_r" pos="0.00359 -0.4061 -0.0002653">
          <!-- 髋关节动捕记录点    -->
          <body name="SMPL_4" pos="0 0 0">
            <site name="SMPL_4" pos="0 0 0" rgba="0 1 0 1" type="sphere" size="0.01"/>
          </body>
          <inertial pos="0 -0.1867 0" quat="0.5 0.5 -0.5 0.5" mass="3.7075" diaginertia="0.0511 0.0504 0.0051"/>
          <joint name="walker_knee_r_translation1" pos="0 0 0" axis="-4.56599e-07 -0.0707098 -0.997497" type="slide" range="0 0.00176" user="-7.73364e-07"/>
          <joint name="walker_knee_r_translation2" pos="0 0 0" axis="-0.124295 0.989762 -0.0701573" type="slide" range="-0.006539 0.000301" user="-2.49715e-05"/>
          <joint name="walker_knee_r_translation3" pos="0 0 0" axis="0.992243 0.124005 -0.00878938" type="slide" range="-0.001898 0.003676" user="-1.43135e-05"/>
          <joint name="knee_angle_r" pos="0 0 0" axis="-4.56599e-07 -0.0707098 -0.997497" range="-0.1745 2.443" user="4.87767e-05"/>
          <joint name="walker_knee_r_rotation2" pos="0 0 0" axis="0.992243 0.124005 -0.00878938" range="-0.001678 0.03354" user="3.84342e-06"/>
          <joint name="walker_knee_r_rotation3" pos="0 0 0" axis="-0.124295 0.989762 -0.0701573" range="0 0.2628" user="1.80334e-05"/>
          <geom name="tibia_r_geom_1" type="mesh" rgba="1 1 1 1" mesh="tibia_r_geom_1_r_tibia"/>
          <geom name="tibia_r_geom_2" type="mesh" rgba="1 1 1 1" mesh="tibia_r_geom_2_r_fibula"/>
          <geom name="GasLat_at_shank_r_cylinder" size="0.055 0.05" pos="-0.0074 -0.074 -0.0033" quat="-0.0297182 0.737325 0.65545 -0.160791" type="cylinder" group="4" rgba="0.19 0.83 0.78 0.2"/>
          <geom name="GasMed_at_shank_r_cylinder" size="0.059 0.05" pos="-0.0074 -0.074 -0.0033" quat="0.0738196 0.735435 0.67182 -0.0484208" type="cylinder" group="4" rgba="0.19 0.83 0.78 0.2"/>
          <geom name="GR_at_condyles_r_cylinder" size="0.036 0.05" pos="-0.003 -0.02 0" quat="0.980067 0 -0.198669 0" type="cylinder" group="4" rgba="0.19 0.83 0.78 0.2"/>
          <geom name="SM_at_condyles_r_cylinder" size="0.0345 0.05" pos="-0.001 -0.02 0" quat="0.99875 0 -0.0499792 0" type="cylinder" group="4" rgba="0.19 0.83 0.78 0.2"/>
          <geom name="ST_at_condyles_r_cylinder" size="0.0425 0.05" pos="-0.002 -0.0205 0" quat="0.995004 0 -0.0998334 0" type="cylinder" group="4" rgba="0.19 0.83 0.78 0.2"/>
          <geom name="BF140_at_gastroc_r_cylinder" size="0.029 0.075" pos="-0.039 -0.06 0" type="cylinder" group="4" rgba="0.19 0.83 0.78 0.2"/>
          <site name="GasLat_at_shank_r_sidesite" pos="-0.06099 -0.06623 0.01096" size="0.0005"/>
          <site name="GasMed_at_shank_r_sidesite" pos="-0.06712 -0.06882 -0.005909" size="0.0005"/>
          <site name="BF140_at_gastroc_r_sidesite" pos="-0.039 -0.03 0" size="0.0005"/>
          <site name="bflh140_r_bflh140_r-P2" pos="-0.03436 -0.03648 0.03618"/>
          <site name="bflh140_r_bflh140_r-P3" pos="-0.02704 -0.05008 0.03476"/>
          <site name="bfsh140_r_bfsh140_r-P2" pos="-0.02866 -0.03284 0.03204"/>
          <site name="BF140_at_gastroc_r_cylinder_bfsh140_r_1_sidesite" pos="-0.0458494 -0.0258807 -0.0218782" size="0.0005"/>
          <site name="edl_r_edl_r-P1" pos="-0.016 -0.1157 0.0205"/>
          <site name="edl_r_edl_r-P2" pos="0.0164 -0.376 0.0112"/>
          <site name="ehl_r_ehl_r-P1" pos="-0.014 -0.155 0.0189"/>
          <site name="ehl_r_ehl_r-P2" pos="0.0071 -0.2909 0.0164"/>
          <site name="ehl_r_ehl_r-P3" pos="0.02 -0.3693 -0.0028"/>
          <site name="fdl_r_fdl_r-P1" pos="-0.0023 -0.1832 -0.0018"/>
          <site name="fdl_r_fdl_r-P2" pos="-0.0176 -0.3645 -0.0124"/>
          <site name="fhl_r_fhl_r-P1" pos="-0.031 -0.2163 0.02"/>
          <site name="fhl_r_fhl_r-P2" pos="-0.0242 -0.3671 -0.0076"/>
          <site name="grac_r_grac_r-P2" pos="-0.01842 -0.04755 -0.02961"/>
          <site name="grac_r_grac_r-P3" pos="0.00178 -0.06962 -0.01573"/>
          <site name="GR_at_condyles_r_cylinder_grac_r_1_sidesite" pos="-0.0294079 -0.0412182 -0.0341712" size="0.0005"/>
          <site name="perbrev_r_perbrev_r-P1" pos="-0.0243 -0.2532 0.0251"/>
          <site name="perbrev_r_perbrev_r-P2" pos="-0.0339 -0.3893 0.0249"/>
          <site name="perbrev_r_perbrev_r-P3" pos="-0.0285 -0.4004 0.0255"/>
          <site name="perlong_r_perlong_r-P1" pos="-0.02 -0.1373 0.0282"/>
          <site name="perlong_r_perlong_r-P2" pos="-0.0317 -0.39 0.0237"/>
          <site name="perlong_r_perlong_r-P3" pos="-0.0272 -0.4014 0.024"/>
          <site name="recfem_r_recfem_r-P5" pos="0.0326 -0.06312 -0.00047"/>
          <site name="sart_r_sart_r-P3" pos="-0.0251 -0.0401 -0.0365"/>
          <site name="sart_r_sart_r-P4" pos="-0.0159 -0.0599 -0.0264"/>
          <site name="sart_r_sart_r-P5" pos="0.0136 -0.081 -0.0026"/>
          <site name="semimem_r_semimem_r-P2" pos="-0.027 -0.041 -0.0196"/>
          <site name="SM_at_condyles_r_cylinder_semimem_r_1_sidesite" pos="-0.0408605 -0.0256896 -0.0134805" size="0.0005"/>
          <site name="semiten_r_semiten_r-P2" pos="-0.0312 -0.0508 -0.0229"/>
          <site name="semiten_r_semiten_r-P3" pos="0.0019 -0.0773 -0.0117"/>
          <site name="ST_at_condyles_r_cylinder_semiten_r_1_sidesite" pos="-0.0387975 -0.0558564 -0.00347776" size="0.0005"/>
          <site name="soleus_r_soleus_r-P1" pos="-0.0076 -0.0916 0.0098"/>
          <site name="tfl_r_tfl_r-P4" pos="0.0108 -0.041 0.0346"/>
          <site name="tibant_r_tibant_r-P1" pos="0.0154 -0.1312 0.0162"/>
          <site name="tibant_r_tibant_r-P2" pos="0.0251 -0.1906 0.0128"/>
          <site name="tibant_r_tibant_r-P3" pos="0.0233 -0.3659 -0.0132"/>
          <site name="tibpost_r_tibpost_r-P1" pos="-0.0041 -0.1304 0.0103"/>
          <site name="tibpost_r_tibpost_r-P2" pos="-0.0164 -0.3655 -0.0175"/>
          <site name="vasint_r_vasint_r-P5" pos="0.03257 -0.0632 0.00043"/>
          <site name="vaslat140_r_vaslat140_r-P5" pos="0.03254 -0.06338 0.00511"/>
          <site name="vasmed_r_vasmed_r-P5" pos="0.0319 -0.06357 -0.00678"/>
          <!-- 距骨 是位于胫骨、腓骨与跟骨之间的短骨，属于足部最高位的骨骼 -->
          <body name="talus_r" pos="-0.01 -0.4 0">
            <!-- 踝关节动捕记录点    -->
            <body name="SMPL_7" pos="0 0 0">
              <site name="SMPL_7" pos="0 0 0" rgba="0 1 0 1" type="sphere" size="0.01"/>
            </body>
            <inertial pos="0 0 0" mass="0.1" diaginertia="0.001 0.001 0.001"/>
            <joint name="ankle_angle_r" pos="0 0 0" axis="-0.105003 -0.174005 0.979131" range="-0.6981 0.5236" user="-1.18287e-09"/>
            <geom name="talus_r_geom_1" type="mesh" rgba="1 1 1 1" mesh="talus_r_geom_1_r_talus"/>
            <!--跟骨Calcaneus -->
            <body name="calcn_r" pos="-0.04877 -0.04195 0.00792">
              <inertial pos="0.1 0.03 0" quat="0 0.707107 0 0.707107" mass="1.25" diaginertia="0.0041 0.0039 0.0014"/>
              <joint name="subtalar_angle_r" pos="0 0 0" axis="0.787215 0.604711 -0.120902" range="-0.6109 0.6109"/>
              <geom name="calcn_r_geom_1" type="mesh" rgba="1 1 1 1" mesh="calcn_r_geom_1_r_foot"/>
              <site name="edl_r_edl_r-P3" pos="0.0919 0.036 0.0008"/>
              <site name="edl_r_edl_r-P4" pos="0.1616 0.0055 0.013"/>
              <site name="ehl_r_ehl_r-P4" pos="0.097 0.0389 -0.0211"/>
              <site name="ehl_r_ehl_r-P5" pos="0.1293 0.0309 -0.0257"/>
              <site name="ehl_r_ehl_r-P6" pos="0.1734 0.0139 -0.028"/>
              <site name="fdl_r_fdl_r-P3" pos="0.0436 0.0315 -0.028"/>
              <site name="fdl_r_fdl_r-P4" pos="0.0708 0.0176 -0.0263"/>
              <site name="fdl_r_fdl_r-P5" pos="0.1658 -0.0081 0.0116"/>
              <site name="fhl_r_fhl_r-P3" pos="0.0374 0.0276 -0.0241"/>
              <site name="fhl_r_fhl_r-P4" pos="0.1038 0.0068 -0.0256"/>
              <site name="fhl_r_fhl_r-P5" pos="0.1726 -0.0053 -0.0269"/>
              <site name="gaslat140_r_gaslat140_r-P2" pos="0.0044 0.031 -0.0053"/>
              <site name="gasmed_r_gasmed_r-P2" pos="0.0044 0.031 -0.0053"/>
              <site name="perbrev_r_perbrev_r-P4" pos="0.0471 0.027 0.0233"/>
              <site name="perbrev_r_perbrev_r-P5" pos="0.0677 0.0219 0.0343"/>
              <site name="perlong_r_perlong_r-P4" pos="0.0438 0.023 0.0221"/>
              <site name="perlong_r_perlong_r-P5" pos="0.0681 0.0106 0.0284"/>
              <site name="perlong_r_perlong_r-P6" pos="0.0852 0.0069 0.0118"/>
              <site name="perlong_r_perlong_r-P7" pos="0.1203 0.0085 -0.0184"/>
              <site name="soleus_r_soleus_r-P2" pos="0.0044 0.031 -0.0053"/>
              <site name="tibant_r_tibant_r-P4" pos="0.1166 0.0178 -0.0305"/>
              <site name="tibpost_r_tibpost_r-P3" pos="0.0417 0.0334 -0.0286"/>
              <site name="tibpost_r_tibpost_r-P4" pos="0.0772 0.0159 -0.0281"/>
              <body name="toes_r" pos="0.1788 -0.002 0.00108">

                <body name="SMPL_10" pos="0 0 0">
                  <site name="SMPL_10" pos="0 0 0" rgba="0 1 0 1" type="sphere" size="0.01"/>
                </body>
                <inertial pos="0.0346 0.006 -0.0175" quat="0 0.707107 0 0.707107" mass="0.2166" diaginertia="0.001 0.001 0.001"/>
                <joint name="mtp_angle_r" pos="0 0 0" axis="0.581002 2.16001e-06 -0.813902" range="-0.5236 0.5236"/>
                <geom name="toes_r_geom_1" type="mesh" rgba="1 1 1 1" mesh="toes_r_geom_1_r_bofoot"/>
                <site name="edl_r_edl_r-P5" pos="0.0003 0.0047 0.0153"/>
                <site name="edl_r_edl_r-P6" pos="0.0443 -0.0004 0.025"/>
                <site name="ehl_r_ehl_r-P7" pos="0.0298 0.0041 -0.0245"/>
                <site name="ehl_r_ehl_r-P8" pos="0.0563 0.0034 -0.0186"/>
                <site name="fdl_r_fdl_r-P6" pos="-0.0019 -0.0078 0.0147"/>
                <site name="fdl_r_fdl_r-P7" pos="0.0285 -0.0071 0.0215"/>
                <site name="fdl_r_fdl_r-P8" pos="0.0441 -0.006 0.0242"/>
                <site name="fhl_r_fhl_r-P6" pos="0.0155 -0.0064 -0.0265"/>
                <site name="fhl_r_fhl_r-P7" pos="0.0562 -0.0102 -0.0181"/>
              </body>
            </body>
          </body>
        </body>
        <!-- 髌骨（即膝盖骨）       -->
        <body name="patella_r" pos="-0.00809 -0.408 -0.00275">
          <inertial pos="0.0018 0.0264 0" quat="0.5 0.5 0.5 0.5" mass="0.0862" diaginertia="0.001 0.001 0.001"/>
          <joint name="patellofemoral_r_translation1" pos="0 0 0" axis="1 0 0" type="slide" range="-0.0227 0.0524" user="0.0524185"/>
          <joint name="patellofemoral_r_translation2" pos="0 0 0" axis="0 1 0" type="slide" range="-0.0408 -0.0108" user="-0.0108305"/>
          <joint name="patellofemoral_r_translation3" pos="0 0 0" axis="0 0 1" limited="false" type="slide"/>
          <joint name="patellofemoral_r_rotation1" pos="0 0 0" axis="0 0 1" range="-1.786 0.001137" user="0.0105072"/>
          <geom name="patella_r_geom_1" type="mesh" rgba="1 1 1 1" mesh="patella_r_geom_1_r_patella"/>
          <site name="recfem_r_recfem_r-P2" pos="0.01 0.049 0.0007"/>
          <site name="recfem_r_recfem_r-P3" pos="0.0121 0.0437 -0.001"/>
          <site name="recfem_r_recfem_r-P4" pos="0.005 0.00247 3e-05"/>
          <site name="vasint_r_vasint_r-P3" pos="0.0058 0.048 -0.0006"/>
          <site name="vasint_r_vasint_r-P4" pos="0.005 0.00247 -0.00039"/>
          <site name="vaslat140_r_vaslat140_r-P3" pos="0.0103 0.0423 0.0141"/>
          <site name="vaslat140_r_vaslat140_r-P4" pos="0.005 0.00247 0.00733"/>
          <site name="vasmed_r_vasmed_r-P3" pos="0.0063 0.0445 -0.017"/>
          <site name="vasmed_r_vasmed_r-P4" pos="0.005 0.00247 -0.0085"/>
        </body>
      </body>
      <!-- 左侧大腿肱骨-->
      <body name="femur_l" pos="-0.05628 -0.07849 -0.07726">
      <!--   动捕记录点     -->
        <body name="SMPL_2" pos="0 0 0">
          <site name="SMPL_2" pos="0 0 0" rgba="1 0 0 1" type="sphere" size="0.01"/>
        </body>
        <inertial pos="0 -0.17 0" quat="0.5 0.5 -0.5 0.5" mass="9.3014" diaginertia="0.1412 0.1339 0.0351"/>
        <joint name="hip_flexion_l" pos="0 0 0" axis="0 0 1" range="-0.5236 2.094" user="2.33205e-09"/>
        <joint name="hip_adduction_l" pos="0 0 0" axis="-1 0 0" range="-0.8727 0.5236" user="1.19929e-09"/>
        <joint name="hip_rotation_l" pos="0 0 0" axis="0 -1 0" range="-0.6981 0.6981"/>
        <geom name="femur_l_geom_1" type="mesh" rgba="1 1 1 1" mesh="femur_l_geom_1_l_femur"/>
        <geom name="GasLat_at_condyles_l_cylinder" size="0.026 0.05" pos="0.005 -0.41 0" type="cylinder" group="4" rgba="0.19 0.83 0.78 0.2"/>
        <geom name="GasMed_at_condyles_l_cylinder" size="0.025 0.05" pos="0.005 -0.41 0" type="cylinder" group="4" rgba="0.19 0.83 0.78 0.2"/>
        <geom name="KnExt_at_fem_l_cylinder" size="0.025 0.05" pos="0.003588 -0.4027 -0.002091" quat="0.999192 0.0311549 -0.0253649 -0.000790882" type="cylinder" group="4" rgba="0.19 0.83 0.78 0.2"/>
        <geom name="KnExtVL_at_fem_l_cylinder" size="0.025 0.05" pos="0.001888 -0.4027 -0.002091" quat="0.999192 0.0311549 -0.0253649 -0.000790882" type="cylinder" group="4" rgba="0.19 0.83 0.78 0.2"/>
        <geom name="AB_at_femshaft_l_cylinder" size="0.0165 0.035" pos="0.01464 -0.1126 -0.02337" quat="0.671205 -0.735393 -0.0628058 0.068812" type="cylinder" group="4" rgba="0.19 0.83 0.78 0.2"/>
        <geom name="AL_at_femshaft_l_cylinder" size="0.0201 0.05" pos="0.03073 -0.2319 -0.01511" quat="0.629109 -0.77432 -0.0430035 0.0529295" type="cylinder" group="4" rgba="0.19 0.83 0.78 0.2"/>
        <geom name="AMprox_at_femshaft_l_cylinder" size="0.0211 0.035" pos="0.005183 -0.07289 -0.0254" quat="0.689738 -0.718041 -0.0645399 0.0671882" type="cylinder" group="4" rgba="0.19 0.83 0.78 0.2"/>
        <geom name="AMmid_at_femshaft_l_cylinder" size="0.0214 0.06" pos="0.02301 -0.1607 -0.02058" quat="0.691136 -0.719496 -0.0472781 0.0492181" type="cylinder" group="4" rgba="0.19 0.83 0.78 0.2"/>
        <geom name="AMdist_at_femshaft_l_cylinder" size="0.0218 0.1" pos="0.03161 -0.2607 -0.009365" quat="0.652613 -0.751942 -0.0610661 0.0703605" type="cylinder" group="4" rgba="0.19 0.83 0.78 0.2"/>
        <geom name="AMisch_at_condyles_l_cylinder" size="0.04 0.12" pos="-0.02265 -0.3768 0.003154" quat="0.638315 -0.734726 0.150602 -0.173349" type="cylinder" group="4" rgba="0.19 0.83 0.78 0.2"/>
        <geom name="PECT_at_femshaft_l_cylinder" size="0.015 0.025" pos="0.006086 -0.0845 -0.03044" quat="0.610631 -0.779849 -0.0848995 0.108427" type="cylinder" group="4" rgba="0.19 0.83 0.78 0.2"/>
        <geom name="OBTEXT_at_femneck_l_cylinder" size="0.0136 0.024" pos="-0.005764 -0.01725 -0.02336" quat="0.939344 -0.325795 0.101275 -0.0351255" type="cylinder" group="4" rgba="0.19 0.83 0.78 0.2"/>
        <site name="addbrev_l_addbrev_l-P2" pos="-0.002 -0.118 -0.0249"/>
        <site name="AB_at_femshaft_l_cylinder_addbrev_l_1_sidesite" pos="0.00870947 -0.144296 -0.0046558" size="0.0005"/>
        <site name="addlong_l_addlong_l-P2" pos="0.01126 -0.23937 -0.01583"/>
        <site name="AL_at_femshaft_l_cylinder_addlong_l_1_sidesite" pos="0.01126 -0.2394 -0.01583" size="0.0005"/>
        <site name="addmagDist_l_addmagDist_l-P2" pos="0.01125 -0.2625 -0.0193"/>
        <site name="AMdist_at_femshaft_l_cylinder_addmagDist_l_1_sidesite" pos="0.00712899 -0.267636 -0.0155885" size="0.0005"/>
        <site name="addmagIsch_l_addmagIsch_l-P2" pos="0.00481 -0.38797 0.03273"/>
        <site name="AMisch_at_condyles_l_cylinder_addmagIsch_l_1_sidesite" pos="0.00481 -0.388 0.03273" size="0.0005"/>
        <site name="addmagMid_l_addmagMid_l-P2" pos="0.00242 -0.1624 -0.02922"/>
        <site name="AMmid_at_femshaft_l_cylinder_addmagMid_l_1_sidesite" pos="0.00242 -0.1624 -0.02922" size="0.0005"/>
        <site name="addmagProx_l_addmagProx_l-P2" pos="-0.01527 -0.07886 -0.03202"/>
        <site name="AMprox_at_femshaft_l_cylinder_addmagProx_l_1_sidesite" pos="-0.0144488 -0.097041 -0.0158885" size="0.0005"/>
        <site name="bfsh140_l_bfsh140_l-P1" pos="0.005 -0.2111 -0.0234"/>
        <site name="gaslat140_l_gaslat140_l-P1" pos="0.002 -0.381 -0.02059"/>
        <site name="GasLat_at_condyles_l_cylinder_gaslat140_l_1_sidesite" pos="-0.0250263 -0.401523 -0.0339369" size="0.0005"/>
        <site name="gasmed_l_gasmed_l-P1" pos="0.006 -0.384 0.022"/>
        <site name="GasMed_at_condyles_l_cylinder_gasmed_l_1_sidesite" pos="-0.00277448 -0.381025 0.0166003" size="0.0005"/>
        <site name="gem_l_gem_l-P2" pos="-0.0142 -0.0033 -0.0443"/>
        <site name="glmax1_l_glmax1_l-P3" pos="-0.0444 -0.0326 -0.0302"/>
        <site name="glmax1_l_glmax1_l-P4" pos="-0.0277 -0.0566 -0.047"/>
        <site name="glmax2_l_glmax2_l-P3" pos="-0.045 -0.0584 -0.0252"/>
        <site name="glmax2_l_glmax2_l-P4" pos="-0.0156 -0.1016 -0.0419"/>
        <site name="glmax3_l_glmax3_l-P3" pos="-0.0281 -0.1125 -0.0094"/>
        <site name="glmax3_l_glmax3_l-P4" pos="-0.006 -0.1419 -0.0411"/>
        <site name="glmed1_l_glmed1_l-P2" pos="-0.0218 -0.0117 -0.0555"/>
        <site name="glmed2_l_glmed2_l-P2" pos="-0.0258 -0.0058 -0.0527"/>
        <site name="glmed3_l_glmed3_l-P2" pos="-0.0309 -0.0047 -0.0518"/>
        <site name="glmin1_l_glmin1_l-P2" pos="-0.0072 -0.0104 -0.056"/>
        <site name="glmin2_l_glmin2_l-P2" pos="-0.0096 -0.0104 -0.056"/>
        <site name="glmin3_l_glmin3_l-P2" pos="-0.0135 -0.0083 -0.055"/>
        <site name="iliacus_l_iliacus_l-P3" pos="-0.0023 -0.0565 -0.0139"/>
        <site name="iliacus_l_iliacus_l-P4" pos="-0.0122 -0.0637 -0.0196"/>
        <site name="obtext_l_obtext_l-P2" pos="-0.025 -0.011 -0.039"/>
        <site name="OBTEXT_at_femneck_l_cylinder_obtext_l_1_sidesite" pos="-0.0206099 -0.014876 -0.0373357" size="0.0005"/>
        <site name="obtint_l_obtint_l-P3" pos="-0.0162 -0.0013 -0.0443"/>
        <site name="pect_l_pect_l-P2" pos="-0.00797 -0.08518 -0.02403"/>
        <site name="PECT_at_femshaft_l_cylinder_pect_l_1_sidesite" pos="-0.00797 -0.08518 -0.02403" size="0.0005"/>
        <site name="piri_l_piri_l-P3" pos="-0.0148 -0.0036 -0.0437"/>
        <site name="psoas_l_psoas_l-P3" pos="-0.0132 -0.0467 -0.0046"/>
        <site name="psoas_l_psoas_l-P4" pos="-0.0235 -0.0524 -0.0088"/>
        <site name="quadfem_l_quadfem_l-P2" pos="-0.03575 -0.03552 -0.03612"/>
        <site name="KnExt_at_fem_l_cylinder_recfem_l_3_sidesite" pos="0.253588 -0.1527 0.247909" size="0.0005"/>
        <site name="sart_l_sart_l-P2" pos="-0.003 -0.3568 0.0421"/>
        <site name="tfl_l_tfl_l-P2" pos="0.0294 -0.0995 -0.0597"/>
        <site name="tfl_l_tfl_l-P3" pos="0.0107 -0.405 -0.0324"/>
        <site name="vasint_l_vasint_l-P1" pos="0.029 -0.1924 -0.031"/>
        <site name="vasint_l_vasint_l-P2" pos="0.0335 -0.2084 -0.0285"/>
        <site name="KnExt_at_fem_l_cylinder_vasint_l_3_sidesite" pos="0.253588 -0.1527 0.247909" size="0.0005"/>
        <site name="vaslat140_l_vaslat140_l-P1" pos="0.0048 -0.1854 -0.0349"/>
        <site name="vaslat140_l_vaslat140_l-P2" pos="0.0269 -0.2591 -0.0409"/>
        <site name="KnExtVL_at_fem_l_cylinder_vaslat140_l_3_sidesite" pos="0.251888 -0.1527 0.247909" size="0.0005"/>
        <site name="vasmed_l_vasmed_l-P1" pos="0.014 -0.2099 -0.0188"/>
        <site name="vasmed_l_vasmed_l-P2" pos="0.0356 -0.2769 -0.0009"/>
        <site name="KnExt_at_fem_l_cylinder_vasmed_l_4_sidesite" pos="-0.007846 -0.4075 0.02075" size="0.0005"/>
        <site name="KnExt_at_fem_l_cylinder_vasmed_l_3_sidesite" pos="-0.007846 -0.4075 0.02075" size="0.0005"/>
        <!-- 左侧小腿-->
        <body name="tibia_l" pos="0.00359 -0.4061 0.0002653">
          <body name="SMPL_5" pos="0 0 0">
            <site name="SMPL_5" pos="0 0 0" rgba="1 0 0 1" type="sphere" size="0.01"/>
          </body>
          <inertial pos="0 -0.1867 0" quat="0.5 0.5 -0.5 0.5" mass="3.7075" diaginertia="0.0511 0.0504 0.0051"/>
          <joint name="walker_knee_l_translation1" pos="0 0 0" axis="-4.56599e-07 -0.0707098 0.997497" type="slide" range="0 0.00176" user="-7.73364e-07"/>
          <joint name="walker_knee_l_translation2" pos="0 0 0" axis="-0.124295 0.989762 0.0701573" type="slide" range="-0.006539 0.000301" user="-2.49715e-05"/>
          <joint name="walker_knee_l_translation3" pos="0 0 0" axis="-0.992243 -0.124005 -0.00878938" type="slide" range="-0.003676 0.001898" user="1.43135e-05"/>
          <joint name="knee_angle_l" pos="0 0 0" axis="4.56599e-07 0.0707098 -0.997497" range="-0.1745 2.443" user="4.87799e-05"/>
          <joint name="walker_knee_l_rotation2" pos="0 0 0" axis="-0.992243 -0.124005 -0.00878938" range="-0.001678 0.03354" user="3.84368e-06"/>
          <joint name="walker_knee_l_rotation3" pos="0 0 0" axis="-0.124295 0.989762 0.0701573" range="-0.2628 0" user="-1.80346e-05"/>
          <geom name="tibia_l_geom_1" type="mesh" rgba="1 1 1 1" mesh="tibia_l_geom_1_l_tibia"/>
          <geom name="tibia_l_geom_2" type="mesh" rgba="1 1 1 1" mesh="tibia_l_geom_2_l_fibula"/>
          <geom name="GasLat_at_shank_l_cylinder" size="0.055 0.05" pos="-0.0074 -0.074 0.0033" quat="-0.0297182 -0.737325 -0.65545 -0.160791" type="cylinder" group="4" rgba="0.19 0.83 0.78 0.2"/>
          <geom name="GasMed_at_shank_l_cylinder" size="0.059 0.05" pos="-0.0074 -0.074 0.0033" quat="0.0738196 -0.735435 -0.67182 -0.0484208" type="cylinder" group="4" rgba="0.19 0.83 0.78 0.2"/>
          <geom name="GR_at_condyles_l_cylinder" size="0.036 0.05" pos="-0.003 -0.02 0" quat="0.980067 0 0.198669 0" type="cylinder" group="4" rgba="0.19 0.83 0.78 0.2"/>
          <geom name="SM_at_condyles_l_cylinder" size="0.0345 0.05" pos="-0.001 -0.02 0" quat="0.99875 0 0.0499792 0" type="cylinder" group="4" rgba="0.19 0.83 0.78 0.2"/>
          <geom name="ST_at_condyles_l_cylinder" size="0.0425 0.05" pos="-0.002 -0.0205 0" quat="0.995004 0 0.0998334 0" type="cylinder" group="4" rgba="0.19 0.83 0.78 0.2"/>
          <geom name="BF140_at_gastroc_l_cylinder" size="0.029 0.075" pos="-0.039 -0.06 0" type="cylinder" group="4" rgba="0.19 0.83 0.78 0.2"/>
          <site name="GasLat_at_shank_l_sidesite" pos="-0.06099 -0.06623 -0.01096" size="0.0005"/>
          <site name="GasMed_at_shank_l_sidesite" pos="-0.06712 -0.06882 0.005909" size="0.0005"/>
          <site name="bflh140_l_bflh140_l-P2" pos="-0.03436 -0.03648 -0.03618"/>
          <site name="bflh140_l_bflh140_l-P3" pos="-0.02704 -0.05008 -0.03476"/>
          <site name="bfsh140_l_bfsh140_l-P2" pos="-0.02866 -0.03284 -0.03204"/>
          <site name="BF140_at_gastroc_l_cylinder_bfsh140_l_1_sidesite" pos="-0.0330663 -0.0257096 -0.0572595" size="0.0005"/>
          <site name="edl_l_edl_l-P1" pos="-0.016 -0.1157 -0.0205"/>
          <site name="edl_l_edl_l-P2" pos="0.0164 -0.376 -0.0112"/>
          <site name="ehl_l_ehl_l-P1" pos="-0.014 -0.155 -0.0189"/>
          <site name="ehl_l_ehl_l-P2" pos="0.0071 -0.2909 -0.0164"/>
          <site name="ehl_l_ehl_l-P3" pos="0.02 -0.3693 0.0028"/>
          <site name="fdl_l_fdl_l-P1" pos="-0.0023 -0.1832 0.0018"/>
          <site name="fdl_l_fdl_l-P2" pos="-0.0176 -0.3645 0.0124"/>
          <site name="fhl_l_fhl_l-P1" pos="-0.031 -0.2163 -0.02"/>
          <site name="fhl_l_fhl_l-P2" pos="-0.0242 -0.3671 0.0076"/>
          <site name="grac_l_grac_l-P2" pos="-0.01842 -0.04755 0.02961"/>
          <site name="grac_l_grac_l-P3" pos="0.00178 -0.06962 0.01573"/>
          <site name="GR_at_condyles_l_cylinder_grac_l_1_sidesite" pos="-0.01161 -0.0531856 0.050659" size="0.0005"/>
          <site name="perbrev_l_perbrev_l-P1" pos="-0.0243 -0.2532 -0.0251"/>
          <site name="perbrev_l_perbrev_l-P2" pos="-0.0339 -0.3893 -0.0249"/>
          <site name="perbrev_l_perbrev_l-P3" pos="-0.0285 -0.4004 -0.0255"/>
          <site name="perlong_l_perlong_l-P1" pos="-0.02 -0.1373 -0.0282"/>
          <site name="perlong_l_perlong_l-P2" pos="-0.0317 -0.39 -0.0237"/>
          <site name="perlong_l_perlong_l-P3" pos="-0.0272 -0.4014 -0.024"/>
          <site name="recfem_l_recfem_l-P5" pos="0.0326 -0.06312 0.00047"/>
          <site name="sart_l_sart_l-P3" pos="-0.0251 -0.0401 0.0365"/>
          <site name="sart_l_sart_l-P4" pos="-0.0159 -0.0599 0.0264"/>
          <site name="sart_l_sart_l-P5" pos="0.0136 -0.081 0.0026"/>
          <site name="semimem_l_semimem_l-P2" pos="-0.027 -0.041 0.0196"/>
          <site name="SM_at_condyles_l_cylinder_semimem_l_1_sidesite" pos="-0.0271739 0.00902271 0.0348628" size="0.0005"/>
          <site name="semiten_l_semiten_l-P2" pos="-0.0312 -0.0508 0.0229"/>
          <site name="semiten_l_semiten_l-P3" pos="0.0019 -0.0773 0.0117"/>
          <site name="ST_at_condyles_l_cylinder_semiten_l_1_sidesite" pos="-0.0355514 -0.0631554 -0.0247998" size="0.0005"/>
          <site name="soleus_l_soleus_l-P1" pos="-0.0076 -0.0916 -0.0098"/>
          <site name="tfl_l_tfl_l-P4" pos="0.0108 -0.041 -0.0346"/>
          <site name="tibant_l_tibant_l-P1" pos="0.0154 -0.1312 -0.0162"/>
          <site name="tibant_l_tibant_l-P2" pos="0.0251 -0.1906 -0.0128"/>
          <site name="tibant_l_tibant_l-P3" pos="0.0233 -0.3659 0.0132"/>
          <site name="tibpost_l_tibpost_l-P1" pos="-0.0041 -0.1304 -0.0103"/>
          <site name="tibpost_l_tibpost_l-P2" pos="-0.0164 -0.3655 0.0175"/>
          <site name="vasint_l_vasint_l-P5" pos="0.03257 -0.0632 -0.00043"/>
          <site name="vaslat140_l_vaslat140_l-P5" pos="0.03254 -0.06338 -0.00511"/>
          <site name="vasmed_l_vasmed_l-P5" pos="0.0319 -0.06357 0.00678"/>

          <body name="talus_l" pos="-0.01 -0.4 0">
          <!-- 动捕记录点-->
            <body name="SMPL_8" pos="0 0 0">
              <site name="SMPL_8" pos="0 0 0" rgba="1 0 0 1" type="sphere" size="0.01"/>
            </body>
            <inertial pos="0 0 0" mass="0.1" diaginertia="0.001 0.001 0.001"/>
            <joint name="ankle_angle_l" pos="0 0 0" axis="0.105003 0.174005 0.979131" range="-0.6981 0.5236" user="8.35266e-11"/>
            <geom name="talus_l_geom_1" type="mesh" rgba="1 1 1 1" mesh="talus_l_geom_1_l_talus"/>
            <body name="calcn_l" pos="-0.04877 -0.04195 -0.00792">
              <inertial pos="0.1 0.03 0" quat="0 0.707107 0 0.707107" mass="1.25" diaginertia="0.0041 0.0039 0.0014"/>
              <joint name="subtalar_angle_l" pos="0 0 0" axis="-0.787215 -0.604711 -0.120902" range="-0.6109 0.6109"/>
              <geom name="calcn_l_geom_1" type="mesh" rgba="1 1 1 1" mesh="calcn_l_geom_1_l_foot"/>
              <site name="edl_l_edl_l-P3" pos="0.0919 0.036 -0.0008"/>
              <site name="edl_l_edl_l-P4" pos="0.1616 0.0055 -0.013"/>
              <site name="ehl_l_ehl_l-P4" pos="0.097 0.0389 0.0211"/>
              <site name="ehl_l_ehl_l-P5" pos="0.1293 0.0309 0.0257"/>
              <site name="ehl_l_ehl_l-P6" pos="0.1734 0.0139 0.028"/>
              <site name="fdl_l_fdl_l-P3" pos="0.0436 0.0315 0.028"/>
              <site name="fdl_l_fdl_l-P4" pos="0.0708 0.0176 0.0263"/>
              <site name="fdl_l_fdl_l-P5" pos="0.1658 -0.0081 -0.0116"/>
              <site name="fhl_l_fhl_l-P3" pos="0.0374 0.0276 0.0241"/>
              <site name="fhl_l_fhl_l-P4" pos="0.1038 0.0068 0.0256"/>
              <site name="fhl_l_fhl_l-P5" pos="0.1726 -0.0053 0.0269"/>
              <site name="gaslat140_l_gaslat140_l-P2" pos="0.0044 0.031 0.0053"/>
              <site name="gasmed_l_gasmed_l-P2" pos="0.0044 0.031 0.0053"/>
              <site name="perbrev_l_perbrev_l-P4" pos="0.0471 0.027 -0.0233"/>
              <site name="perbrev_l_perbrev_l-P5" pos="0.0677 0.0219 -0.0343"/>
              <site name="perlong_l_perlong_l-P4" pos="0.0438 0.023 -0.0221"/>
              <site name="perlong_l_perlong_l-P5" pos="0.0681 0.0106 -0.0284"/>
              <site name="perlong_l_perlong_l-P6" pos="0.0852 0.0069 -0.0118"/>
              <site name="perlong_l_perlong_l-P7" pos="0.1203 0.0085 0.0184"/>
              <site name="soleus_l_soleus_l-P2" pos="0.0044 0.031 0.0053"/>
              <site name="tibant_l_tibant_l-P4" pos="0.1166 0.0178 0.0305"/>
              <site name="tibpost_l_tibpost_l-P3" pos="0.0417 0.0334 0.0286"/>
              <site name="tibpost_l_tibpost_l-P4" pos="0.0772 0.0159 0.0281"/>
              <body name="toes_l" pos="0.1788 -0.002 -0.00108">

                <body name="SMPL_11" pos="0 0 0">
                  <site name="SMPL_11" pos="0 0 0" rgba="1 0 0 1" type="sphere" size="0.01"/>
                </body>
                <inertial pos="0.0346 0.006 0.0175" quat="0 0.707107 0 0.707107" mass="0.2166" diaginertia="0.001 0.001 0.001"/>
                <joint name="mtp_angle_l" pos="0 0 0" axis="-0.581002 2.16001e-06 -0.813902" range="-0.5236 0.5236"/>
                <geom name="toes_l_geom_1" type="mesh" rgba="1 1 1 1" mesh="toes_l_geom_1_l_bofoot"/>
                <site name="edl_l_edl_l-P5" pos="0.0003 0.0047 -0.0153"/>
                <site name="edl_l_edl_l-P6" pos="0.0443 -0.0004 -0.025"/>
                <site name="ehl_l_ehl_l-P7" pos="0.0298 0.0041 0.0245"/>
                <site name="ehl_l_ehl_l-P8" pos="0.0563 0.0034 0.0186"/>
                <site name="fdl_l_fdl_l-P6" pos="-0.0019 -0.0078 -0.0147"/>
                <site name="fdl_l_fdl_l-P7" pos="0.0285 -0.0071 -0.0215"/>
                <site name="fdl_l_fdl_l-P8" pos="0.0441 -0.006 -0.0242"/>
                <site name="fhl_l_fhl_l-P6" pos="0.0155 -0.0064 0.0265"/>
                <site name="fhl_l_fhl_l-P7" pos="0.0562 -0.0102 0.0181"/>
              </body>
            </body>
          </body>
        </body>
        <body name="patella_l" pos="-0.00809 -0.408 0.00275">
          <inertial pos="0.0018 0.0264 0" quat="0.5 0.5 0.5 0.5" mass="0.0862" diaginertia="0.001 0.001 0.001"/>
          <joint name="patellofemoral_l_translation1" pos="0 0 0" axis="1 0 0" type="slide" range="-0.0227 0.0524" user="0.0524185"/>
          <joint name="patellofemoral_l_translation2" pos="0 0 0" axis="0 1 0" type="slide" range="-0.0408 -0.0108" user="-0.0108305"/>
          <joint name="patellofemoral_l_translation3" pos="0 0 0" axis="0 0 1" limited="false" type="slide"/>
          <joint name="patellofemoral_l_rotation1" pos="0 0 0" axis="0 0 1" range="-1.786 0.001137" user="0.0105072"/>
          <geom name="patella_l_geom_1" type="mesh" rgba="1 1 1 1" mesh="patella_l_geom_1_l_patella"/>
          <site name="recfem_l_recfem_l-P2" pos="0.01 0.049 -0.0007"/>
          <site name="recfem_l_recfem_l-P3" pos="0.0121 0.0437 0.001"/>
          <site name="recfem_l_recfem_l-P4" pos="0.005 0.00247 -3e-05"/>
          <site name="vasint_l_vasint_l-P3" pos="0.0058 0.048 0.0006"/>
          <site name="vasint_l_vasint_l-P4" pos="0.005 0.00247 0.00039"/>
          <site name="vaslat140_l_vaslat140_l-P3" pos="0.0103 0.0423 -0.0141"/>
          <site name="vaslat140_l_vaslat140_l-P4" pos="0.005 0.00247 -0.00733"/>
          <site name="vasmed_l_vasmed_l-P3" pos="0.0063 0.0445 0.017"/>
          <site name="vasmed_l_vasmed_l-P4" pos="0.005 0.00247 0.0085"/>
        </body>
      </body>
      <!-- 躯干 , 在此处拼接两个模型 -->
      <body name="torso" pos="-0.1007 0.0815 0">
        <!-- 动捕点记录     -->
        <body name="SMPL_0" pos="0 0 0">
          <site name="SMPL_0" pos="0 0 0" rgba="1 0 0 1" type="sphere" size="0.01"/>
        </body>
        <!--  拼接胸廓  -->
        <geom name="body" type="mesh" mesh="human_body" euler="0 0 0" contype="0" conaffinity="0" pos="0 0.38 0"/>
        <body name="full_body" euler="-1.57 0 1.57" pos="0 0.38 0">
          <include file="./1017/assets/bi_myoarm_body.xml"/>
          <body name="SMPL_12" pos="0 0.01 0.02">
            <site name="SMPL_12" pos="0 0.01 0.02" rgba="0 0 1 1" type="sphere" size="0.02"/>
          </body>
        </body>

        <inertial pos="-0.03 0.32 0" quat="0.707107 0.707107 0 0" mass="33.8996" diaginertia="1.4745 1.4314 0.7555"/>
        <joint name="lumbar_extension" pos="0 0 0" axis="0 0 1" range="-1.222 0.3491"/>
        <joint name="lumbar_bending" pos="0 0 0" axis="1 0 0" range="-0.5236 0.5236"/>
        <joint name="lumbar_rotation" pos="0 0 0" axis="0 1 0" range="-0.6981 0.6981"/>
        <geom name="torso_geom_1" type="mesh" rgba="1 1 1 1" mesh="torso_geom_1_hat_spine"/>
        <geom name="torso_geom_2" type="mesh" rgba="1 1 1 1" mesh="torso_geom_2_hat_jaw"/>
        <geom name="torso_geom_3" type="mesh" rgba="1 1 1 1" mesh="torso_geom_3_hat_skull"/>

<!--        原来的胸廓,通过对齐两个模型的胸廓将两个模型拼接-->
<!--        <geom name="torso_geom_4" type="mesh" rgba="1 1 1 1" mesh="torso_geom_4_hat_ribs_scap"/>-->
        <site name="ercspn_r_ercspn_r-P2" pos="-0.065 0.11 0.0241"/>
        <site name="extobl_r_extobl_r-P2" pos="0.045 0.11 0.12"/>
        <site name="intobl_r_intobl_r-P2" pos="0.06 0.16 0.045"/>
        <site name="rectab_r_rectab_r-P2" pos="0.09 0.19 0.05"/>
        <site name="ercspn_l_ercspn_l-P2" pos="-0.065 0.11 -0.0241"/>
        <site name="extobl_l_extobl_l-P2" pos="0.045 0.11 -0.12"/>
        <site name="intobl_l_intobl_l-P2" pos="0.06 0.16 -0.045"/>
        <site name="rectab_l_rectab_l-P2" pos="0.09 0.19 -0.05"/>
        <site name="head_max" pos="0 0.66 0" rgba="1 1 1 0" type="sphere" size="0.01"/>
      </body>
    </body>
  </worldbody>

  <!--定义模型中的碰撞检测与接触力学规则  -->
  <!-- <contact>
    <pair geom1="ground-plane" geom2="pelvis_geom_1"/>
    <pair geom1="ground-plane" geom2="pelvis_geom_2"/>
    <pair geom1="ground-plane" geom2="pelvis_geom_3"/>
    <pair geom1="ground-plane" geom2="femur_r_geom_1"/>
    <pair geom1="ground-plane" geom2="tibia_r_geom_1"/>
    <pair geom1="ground-plane" geom2="tibia_r_geom_2"/>
    <pair geom1="ground-plane" geom2="talus_r_geom_1"/>
    <pair geom1="ground-plane" geom2="calcn_r_geom_1"/>
    <pair geom1="ground-plane" geom2="toes_r_geom_1"/>
    <pair geom1="ground-plane" geom2="patella_r_geom_1"/>
    <pair geom1="ground-plane" geom2="femur_l_geom_1"/>
    <pair geom1="ground-plane" geom2="tibia_l_geom_1"/>
    <pair geom1="ground-plane" geom2="tibia_l_geom_2"/>
    <pair geom1="ground-plane" geom2="talus_l_geom_1"/>
    <pair geom1="ground-plane" geom2="calcn_l_geom_1"/>
    <pair geom1="ground-plane" geom2="toes_l_geom_1"/>
    <pair geom1="ground-plane" geom2="patella_l_geom_1"/>
    <pair geom1="ground-plane" geom2="torso_geom_1"/>
    <pair geom1="ground-plane" geom2="torso_geom_2"/>
    <pair geom1="ground-plane" geom2="torso_geom_3"/> -->
<!--    <pair geom1="ground-plane" geom2="torso_geom_4"/>-->

  <!-- </contact> -->

  <!--定义关节或骨骼之间的约束关系  -->
  <equality>
    <!-- 关联动捕点   -->
    <weld body1="mocap_0" body2="SMPL_0" />
    <weld body1="mocap_1" body2="SMPL_1" />
    <weld body1="mocap_4" body2="SMPL_4" />
    <weld body1="mocap_7" body2="SMPL_7" />
    <weld body1="mocap_10" body2="SMPL_10" />
    
    <weld body1="mocap_2" body2="SMPL_2" />
    <weld body1="mocap_5" body2="SMPL_5" />
    <weld body1="mocap_8" body2="SMPL_8" />
    <weld body1="mocap_11" body2="SMPL_11" /> 
    
    <weld body1="mocap_12" body2="SMPL_12" />
    <weld body1="mocap_16" body2="SMPL_16" />
    <weld body1="mocap_18" body2="SMPL_18" />
    <weld body1="mocap_20" body2="SMPL_20" />
    <!-- <weld body1="mocap_26" body2="SMPL_26" /> -->
  
    <weld body1="mocap_17" body2="SMPL_17" />
    <weld body1="mocap_19" body2="SMPL_19" />
    <weld body1="mocap_21" body2="SMPL_21" />
    <!-- <weld body1="mocap_41" body2="SMPL_41" /> -->


    <joint joint1="walker_knee_r_translation1" joint2="knee_angle_r" polycoef="-7.747e-07 2.641e-05 0.001818 -0.001015 0.000159" solimp="0.9999 0.9999 0.001 0.5 2"/>
    <joint joint1="walker_knee_r_translation2" joint2="knee_angle_r" polycoef="-2.516e-05 0.003937 -0.01144 0.00508 -0.0005797" solimp="0.9999 0.9999 0.001 0.5 2"/>
    <joint joint1="walker_knee_r_translation3" joint2="knee_angle_r" polycoef="-1.462e-05 0.006265 0.0006116 -0.004454 0.001208" solimp="0.9999 0.9999 0.001 0.5 2"/>
    <joint joint1="walker_knee_r_rotation2" joint2="knee_angle_r" polycoef="-1.473e-08 0.0791 -0.03285 -0.02522 0.01083" solimp="0.9999 0.9999 0.001 0.5 2"/>
    <joint joint1="walker_knee_r_rotation3" joint2="knee_angle_r" polycoef="1.089e-08 0.3695 -0.1695 0.02516 3.505e-07" solimp="0.9999 0.9999 0.001 0.5 2"/>
    <joint name="mtp_angle_r_locked" joint1="mtp_angle_r" polycoef="0 0 0 0 0" solimp="0.9999 0.9999 0.001 0.5 2"/>
    <joint joint1="patellofemoral_r_translation1" joint2="knee_angle_r" polycoef="0.05242 -0.01502 -0.03405 0.01334 -0.0008792" solimp="0.9999 0.9999 0.001 0.5 2"/>
    <joint joint1="patellofemoral_r_translation2" joint2="knee_angle_r" polycoef="-0.01083 -0.04878 0.009276 0.01317 -0.003497" solimp="0.9999 0.9999 0.001 0.5 2"/>
    <joint joint1="patellofemoral_r_rotation1" joint2="knee_angle_r" polycoef="0.01051 0.02476 -1.316 0.7163 -0.1383" solimp="0.9999 0.9999 0.001 0.5 2"/>
    <joint name="patellofemoral_r_translation3_locked" joint1="patellofemoral_r_translation3" polycoef="0.00275 0 0 0 0" solimp="0.9999 0.9999 0.001 0.5 2"/>
    <joint joint1="walker_knee_l_translation1" joint2="knee_angle_l" polycoef="-7.747e-07 2.641e-05 0.001818 -0.001015 0.000159" solimp="0.9999 0.9999 0.001 0.5 2"/>
    <joint joint1="walker_knee_l_translation2" joint2="knee_angle_l" polycoef="-2.516e-05 0.003937 -0.01144 0.00508 -0.0005797" solimp="0.9999 0.9999 0.001 0.5 2"/>
    <joint joint1="walker_knee_l_translation3" joint2="knee_angle_l" polycoef="1.462e-05 -0.006265 -0.0006116 0.004454 -0.001208" solimp="0.9999 0.9999 0.001 0.5 2"/>
    <joint joint1="walker_knee_l_rotation2" joint2="knee_angle_l" polycoef="-1.473e-08 0.0791 -0.03285 -0.02522 0.01083" solimp="0.9999 0.9999 0.001 0.5 2"/>
    <joint joint1="walker_knee_l_rotation3" joint2="knee_angle_l" polycoef="-1.089e-08 -0.3695 0.1695 -0.02516 -3.505e-07" solimp="0.9999 0.9999 0.001 0.5 2"/>
    <joint name="mtp_angle_l_locked" joint1="mtp_angle_l" polycoef="0 0 0 0 0" solimp="0.9999 0.9999 0.001 0.5 2"/>
    <joint joint1="patellofemoral_l_translation1" joint2="knee_angle_l" polycoef="0.05242 -0.01502 -0.03405 0.01334 -0.0008792" solimp="0.9999 0.9999 0.001 0.5 2"/>
    <joint joint1="patellofemoral_l_translation2" joint2="knee_angle_l" polycoef="-0.01083 -0.04878 0.009276 0.01317 -0.003497" solimp="0.9999 0.9999 0.001 0.5 2"/>
    <joint joint1="patellofemoral_l_rotation1" joint2="knee_angle_l" polycoef="0.01051 0.02476 -1.316 0.7163 -0.1383" solimp="0.9999 0.9999 0.001 0.5 2"/>
    <joint name="patellofemoral_l_translation3_locked" joint1="patellofemoral_l_translation3" polycoef="-0.00275 0 0 0 0" solimp="0.9999 0.9999 0.001 0.5 2"/>
  </equality>

  <!--定义肌腱或韧带的力学连接路径  -->
  <tendon>
    <spatial name="addbrev_r_tendon">
      <site site="addbrev_r_addbrev_r-P1"/>
      <geom geom="AB_at_femshaft_r_cylinder" sidesite="AB_at_femshaft_r_cylinder_addbrev_r_1_sidesite"/>
      <site site="addbrev_r_addbrev_r-P2"/>
    </spatial>
    <spatial name="addlong_r_tendon">
      <site site="addlong_r_addlong_r-P1"/>
      <geom geom="AL_at_femshaft_r_cylinder" sidesite="AL_at_femshaft_r_cylinder_addlong_r_1_sidesite"/>
      <site site="addlong_r_addlong_r-P2"/>
    </spatial>
    <spatial name="addmagDist_r_tendon">
      <site site="addmagDist_r_addmagDist_r-P1"/>
      <geom geom="AMdist_at_femshaft_r_cylinder" sidesite="AMdist_at_femshaft_r_cylinder_addmagDist_r_1_sidesite"/>
      <site site="addmagDist_r_addmagDist_r-P2"/>
    </spatial>
    <spatial name="addmagIsch_r_tendon">
      <site site="addmagIsch_r_addmagIsch_r-P1"/>
      <geom geom="AMisch_at_condyles_r_cylinder" sidesite="AMisch_at_condyles_r_cylinder_addmagIsch_r_1_sidesite"/>
      <site site="addmagIsch_r_addmagIsch_r-P2"/>
    </spatial>
    <spatial name="addmagMid_r_tendon">
      <site site="addmagMid_r_addmagMid_r-P1"/>
      <geom geom="AMmid_at_femshaft_r_cylinder" sidesite="AMmid_at_femshaft_r_cylinder_addmagMid_r_1_sidesite"/>
      <site site="addmagMid_r_addmagMid_r-P2"/>
    </spatial>
    <spatial name="addmagProx_r_tendon">
      <site site="addmagProx_r_addmagProx_r-P1"/>
      <geom geom="AMprox_at_femshaft_r_cylinder" sidesite="AMprox_at_femshaft_r_cylinder_addmagProx_r_1_sidesite"/>
      <site site="addmagProx_r_addmagProx_r-P2"/>
    </spatial>
    <spatial name="bflh140_r_tendon">
      <site site="bflh140_r_bflh140_r-P1"/>
      <site site="bflh140_r_bflh140_r-P2"/>
      <site site="bflh140_r_bflh140_r-P3"/>
    </spatial>
    <spatial name="bfsh140_r_tendon">
      <site site="bfsh140_r_bfsh140_r-P1"/>
      <geom geom="BF140_at_gastroc_r_cylinder" sidesite="BF140_at_gastroc_r_cylinder_bfsh140_r_1_sidesite"/>
      <site site="bfsh140_r_bfsh140_r-P2"/>
    </spatial>
    <spatial name="edl_r_tendon">
      <site site="edl_r_edl_r-P1"/>
      <site site="edl_r_edl_r-P2"/>
      <site site="edl_r_edl_r-P3"/>
      <site site="edl_r_edl_r-P4"/>
      <site site="edl_r_edl_r-P5"/>
      <site site="edl_r_edl_r-P6"/>
    </spatial>
    <spatial name="ehl_r_tendon">
      <site site="ehl_r_ehl_r-P1"/>
      <site site="ehl_r_ehl_r-P2"/>
      <site site="ehl_r_ehl_r-P3"/>
      <site site="ehl_r_ehl_r-P4"/>
      <site site="ehl_r_ehl_r-P5"/>
      <site site="ehl_r_ehl_r-P6"/>
      <site site="ehl_r_ehl_r-P7"/>
      <site site="ehl_r_ehl_r-P8"/>
    </spatial>
    <spatial name="ercspn_r_tendon">
      <site site="ercspn_r_ercspn_r-P1"/>
      <site site="ercspn_r_ercspn_r-P2"/>
    </spatial>
    <spatial name="extobl_r_tendon">
      <site site="extobl_r_extobl_r-P1"/>
      <site site="extobl_r_extobl_r-P2"/>
    </spatial>
    <spatial name="fdl_r_tendon">
      <site site="fdl_r_fdl_r-P1"/>
      <site site="fdl_r_fdl_r-P2"/>
      <site site="fdl_r_fdl_r-P3"/>
      <site site="fdl_r_fdl_r-P4"/>
      <site site="fdl_r_fdl_r-P5"/>
      <site site="fdl_r_fdl_r-P6"/>
      <site site="fdl_r_fdl_r-P7"/>
      <site site="fdl_r_fdl_r-P8"/>
    </spatial>
    <spatial name="fhl_r_tendon">
      <site site="fhl_r_fhl_r-P1"/>
      <site site="fhl_r_fhl_r-P2"/>
      <site site="fhl_r_fhl_r-P3"/>
      <site site="fhl_r_fhl_r-P4"/>
      <site site="fhl_r_fhl_r-P5"/>
      <site site="fhl_r_fhl_r-P6"/>
      <site site="fhl_r_fhl_r-P7"/>
    </spatial>
    <spatial name="gaslat140_r_tendon">
      <site site="gaslat140_r_gaslat140_r-P1"/>
      <geom geom="GasLat_at_condyles_r_cylinder" sidesite="GasLat_at_condyles_r_cylinder_gaslat140_r_1_sidesite"/>
      <site site="gaslat140_r_gaslat140_r-P2"/>
    </spatial>
    <spatial name="gasmed_r_tendon">
      <site site="gasmed_r_gasmed_r-P1"/>
      <geom geom="GasMed_at_condyles_r_cylinder" sidesite="GasMed_at_condyles_r_cylinder_gasmed_r_1_sidesite"/>
      <site site="gasmed_r_gasmed_r-P2"/>
    </spatial>
    <spatial name="gem_r_tendon">
      <site site="gem_r_gem_r-P1"/>
      <site site="gem_r_gem_r-P2"/>
    </spatial>
    <spatial name="glmax1_r_tendon">
      <site site="glmax1_r_glmax1_r-P1"/>
      <site site="glmax1_r_glmax1_r-P2"/>
      <geom geom="Gmax1_at_pelvis_r_cylinder" sidesite="Gmax1_at_pelvis_r_cylinder_glmax1_r_2_sidesite"/>
      <site site="glmax1_r_glmax1_r-P3"/>
      <site site="glmax1_r_glmax1_r-P4"/>
    </spatial>
    <spatial name="glmax2_r_tendon">
      <site site="glmax2_r_glmax2_r-P1"/>
      <site site="glmax2_r_glmax2_r-P2"/>
      <geom geom="Gmax2_at_pelvis_r_cylinder" sidesite="Gmax2_at_pelvis_r_cylinder_glmax2_r_2_sidesite"/>
      <site site="glmax2_r_glmax2_r-P3"/>
      <site site="glmax2_r_glmax2_r-P4"/>
    </spatial>
    <spatial name="glmax3_r_tendon">
      <site site="glmax3_r_glmax3_r-P1"/>
      <geom geom="Gmax3_at_pelvis_r_cylinder" sidesite="Gmax3_at_pelvis_r_cylinder_glmax3_r_1_sidesite"/>
      <site site="glmax3_r_glmax3_r-P2"/>
      <site site="glmax3_r_glmax3_r-P3"/>
      <site site="glmax3_r_glmax3_r-P4"/>
    </spatial>
    <spatial name="glmed1_r_tendon">
      <site site="glmed1_r_glmed1_r-P1"/>
      <site site="glmed1_r_glmed1_r-P2"/>
    </spatial>
    <spatial name="glmed2_r_tendon">
      <site site="glmed2_r_glmed2_r-P1"/>
      <site site="glmed2_r_glmed2_r-P2"/>
    </spatial>
    <spatial name="glmed3_r_tendon">
      <site site="glmed3_r_glmed3_r-P1"/>
      <site site="glmed3_r_glmed3_r-P2"/>
    </spatial>
    <spatial name="glmin1_r_tendon">
      <site site="glmin1_r_glmin1_r-P1"/>
      <site site="glmin1_r_glmin1_r-P2"/>
    </spatial>
    <spatial name="glmin2_r_tendon">
      <site site="glmin2_r_glmin2_r-P1"/>
      <site site="glmin2_r_glmin2_r-P2"/>
    </spatial>
    <spatial name="glmin3_r_tendon">
      <site site="glmin3_r_glmin3_r-P1"/>
      <site site="glmin3_r_glmin3_r-P2"/>
    </spatial>
    <spatial name="grac_r_tendon">
      <site site="grac_r_grac_r-P1"/>
      <geom geom="GR_at_condyles_r_cylinder" sidesite="GR_at_condyles_r_cylinder_grac_r_1_sidesite"/>
      <site site="grac_r_grac_r-P2"/>
      <site site="grac_r_grac_r-P3"/>
    </spatial>
    <spatial name="iliacus_r_tendon">
      <site site="iliacus_r_iliacus_r-P1"/>
      <site site="iliacus_r_iliacus_r-P2"/>
      <geom geom="IL_at_brim_r_cylinder" sidesite="IL_at_brim_r_cylinder_iliacus_r_2_sidesite"/>
      <site site="iliacus_r_iliacus_r-P3"/>
      <site site="iliacus_r_iliacus_r-P4"/>
    </spatial>
    <spatial name="intobl_r_tendon">
      <site site="intobl_r_intobl_r-P1"/>
      <site site="intobl_r_intobl_r-P2"/>
    </spatial>
    <spatial name="obtext_r_tendon">
      <site site="obtext_r_obtext_r-P1"/>
      <geom geom="OBTEXT_at_femneck_r_cylinder" sidesite="OBTEXT_at_femneck_r_cylinder_obtext_r_1_sidesite"/>
      <site site="obtext_r_obtext_r-P2"/>
    </spatial>
    <spatial name="obtint_r_tendon">
      <site site="obtint_r_obtint_r-P1"/>
      <site site="obtint_r_obtint_r-P2"/>
      <site site="obtint_r_obtint_r-P3"/>
    </spatial>
    <spatial name="pect_r_tendon">
      <site site="pect_r_pect_r-P1"/>
      <geom geom="PECT_at_femshaft_r_cylinder" sidesite="PECT_at_femshaft_r_cylinder_pect_r_1_sidesite"/>
      <site site="pect_r_pect_r-P2"/>
    </spatial>
    <spatial name="perbrev_r_tendon">
      <site site="perbrev_r_perbrev_r-P1"/>
      <site site="perbrev_r_perbrev_r-P2"/>
      <site site="perbrev_r_perbrev_r-P3"/>
      <site site="perbrev_r_perbrev_r-P4"/>
      <site site="perbrev_r_perbrev_r-P5"/>
    </spatial>
    <spatial name="perlong_r_tendon">
      <site site="perlong_r_perlong_r-P1"/>
      <site site="perlong_r_perlong_r-P2"/>
      <site site="perlong_r_perlong_r-P3"/>
      <site site="perlong_r_perlong_r-P4"/>
      <site site="perlong_r_perlong_r-P5"/>
      <site site="perlong_r_perlong_r-P6"/>
      <site site="perlong_r_perlong_r-P7"/>
    </spatial>
    <spatial name="piri_r_tendon">
      <site site="piri_r_piri_r-P1"/>
      <site site="piri_r_piri_r-P2"/>
      <site site="piri_r_piri_r-P3"/>
    </spatial>
    <spatial name="psoas_r_tendon">
      <site site="psoas_r_psoas_r-P1"/>
      <site site="psoas_r_psoas_r-P2"/>
      <geom geom="PS_at_brim_r_cylinder" sidesite="PS_at_brim_r_cylinder_psoas_r_2_sidesite"/>
      <site site="psoas_r_psoas_r-P3"/>
      <site site="psoas_r_psoas_r-P4"/>
    </spatial>
    <spatial name="quadfem_r_tendon">
      <site site="quadfem_r_quadfem_r-P1"/>
      <site site="quadfem_r_quadfem_r-P2"/>
    </spatial>
    <spatial name="recfem_r_tendon">
      <site site="recfem_r_recfem_r-P1"/>
      <site site="recfem_r_recfem_r-P2"/>
      <site site="recfem_r_recfem_r-P3"/>
      <geom geom="KnExt_at_fem_r_cylinder" sidesite="KnExt_at_fem_r_cylinder_recfem_r_3_sidesite"/>
      <site site="recfem_r_recfem_r-P4"/>
      <site site="recfem_r_recfem_r-P5"/>
    </spatial>
    <spatial name="rectab_r_tendon">
      <site site="rectab_r_rectab_r-P1"/>
      <site site="rectab_r_rectab_r-P2"/>
    </spatial>
    <spatial name="sart_r_tendon">
      <site site="sart_r_sart_r-P1"/>
      <site site="sart_r_sart_r-P2"/>
      <site site="sart_r_sart_r-P3"/>
      <site site="sart_r_sart_r-P4"/>
      <site site="sart_r_sart_r-P5"/>
    </spatial>
    <spatial name="semimem_r_tendon">
      <site site="semimem_r_semimem_r-P1"/>
      <geom geom="SM_at_condyles_r_cylinder" sidesite="SM_at_condyles_r_cylinder_semimem_r_1_sidesite"/>
      <site site="semimem_r_semimem_r-P2"/>
    </spatial>
    <spatial name="semiten_r_tendon">
      <site site="semiten_r_semiten_r-P1"/>
      <geom geom="ST_at_condyles_r_cylinder" sidesite="ST_at_condyles_r_cylinder_semiten_r_1_sidesite"/>
      <site site="semiten_r_semiten_r-P2"/>
      <site site="semiten_r_semiten_r-P3"/>
    </spatial>
    <spatial name="soleus_r_tendon">
      <site site="soleus_r_soleus_r-P1"/>
      <site site="soleus_r_soleus_r-P2"/>
    </spatial>
    <spatial name="tfl_r_tendon">
      <site site="tfl_r_tfl_r-P1"/>
      <site site="tfl_r_tfl_r-P2"/>
      <site site="tfl_r_tfl_r-P3"/>
      <site site="tfl_r_tfl_r-P4"/>
    </spatial>
    <spatial name="tibant_r_tendon">
      <site site="tibant_r_tibant_r-P1"/>
      <site site="tibant_r_tibant_r-P2"/>
      <site site="tibant_r_tibant_r-P3"/>
      <site site="tibant_r_tibant_r-P4"/>
    </spatial>
    <spatial name="tibpost_r_tendon">
      <site site="tibpost_r_tibpost_r-P1"/>
      <site site="tibpost_r_tibpost_r-P2"/>
      <site site="tibpost_r_tibpost_r-P3"/>
      <site site="tibpost_r_tibpost_r-P4"/>
    </spatial>
    <spatial name="vasint_r_tendon">
      <site site="vasint_r_vasint_r-P1"/>
      <site site="vasint_r_vasint_r-P2"/>
      <site site="vasint_r_vasint_r-P3"/>
      <geom geom="KnExt_at_fem_r_cylinder" sidesite="KnExt_at_fem_r_cylinder_vasint_r_3_sidesite"/>
      <site site="vasint_r_vasint_r-P4"/>
      <site site="vasint_r_vasint_r-P5"/>
    </spatial>
    <spatial name="vaslat140_r_tendon">
      <site site="vaslat140_r_vaslat140_r-P1"/>
      <site site="vaslat140_r_vaslat140_r-P2"/>
      <site site="vaslat140_r_vaslat140_r-P3"/>
      <geom geom="KnExtVL_at_fem_r_cylinder" sidesite="KnExtVL_at_fem_r_cylinder_vaslat140_r_3_sidesite"/>
      <site site="vaslat140_r_vaslat140_r-P4"/>
      <site site="vaslat140_r_vaslat140_r-P5"/>
    </spatial>
    <spatial name="vasmed_r_tendon">
      <site site="vasmed_r_vasmed_r-P1"/>
      <site site="vasmed_r_vasmed_r-P2"/>
      <site site="vasmed_r_vasmed_r-P3"/>
      <geom geom="KnExt_at_fem_r_cylinder" sidesite="KnExt_at_fem_r_cylinder_vasmed_r_3_sidesite"/>
      <site site="vasmed_r_vasmed_r-P4"/>
      <geom geom="KnExt_at_fem_r_cylinder" sidesite="KnExt_at_fem_r_cylinder_vasmed_r_4_sidesite"/>
      <site site="vasmed_r_vasmed_r-P5"/>
    </spatial>
    <spatial name="addbrev_l_tendon">
      <site site="addbrev_l_addbrev_l-P1"/>
      <geom geom="AB_at_femshaft_l_cylinder" sidesite="AB_at_femshaft_l_cylinder_addbrev_l_1_sidesite"/>
      <site site="addbrev_l_addbrev_l-P2"/>
    </spatial>
    <spatial name="addlong_l_tendon">
      <site site="addlong_l_addlong_l-P1"/>
      <geom geom="AL_at_femshaft_l_cylinder" sidesite="AL_at_femshaft_l_cylinder_addlong_l_1_sidesite"/>
      <site site="addlong_l_addlong_l-P2"/>
    </spatial>
    <spatial name="addmagDist_l_tendon">
      <site site="addmagDist_l_addmagDist_l-P1"/>
      <geom geom="AMdist_at_femshaft_l_cylinder" sidesite="AMdist_at_femshaft_l_cylinder_addmagDist_l_1_sidesite"/>
      <site site="addmagDist_l_addmagDist_l-P2"/>
    </spatial>
    <spatial name="addmagIsch_l_tendon">
      <site site="addmagIsch_l_addmagIsch_l-P1"/>
      <geom geom="AMisch_at_condyles_l_cylinder" sidesite="AMisch_at_condyles_l_cylinder_addmagIsch_l_1_sidesite"/>
      <site site="addmagIsch_l_addmagIsch_l-P2"/>
    </spatial>
    <spatial name="addmagMid_l_tendon">
      <site site="addmagMid_l_addmagMid_l-P1"/>
      <geom geom="AMmid_at_femshaft_l_cylinder" sidesite="AMmid_at_femshaft_l_cylinder_addmagMid_l_1_sidesite"/>
      <site site="addmagMid_l_addmagMid_l-P2"/>
    </spatial>
    <spatial name="addmagProx_l_tendon">
      <site site="addmagProx_l_addmagProx_l-P1"/>
      <geom geom="AMprox_at_femshaft_l_cylinder" sidesite="AMprox_at_femshaft_l_cylinder_addmagProx_l_1_sidesite"/>
      <site site="addmagProx_l_addmagProx_l-P2"/>
    </spatial>
    <spatial name="bflh140_l_tendon">
      <site site="bflh140_l_bflh140_l-P1"/>
      <site site="bflh140_l_bflh140_l-P2"/>
      <site site="bflh140_l_bflh140_l-P3"/>
    </spatial>
    <spatial name="bfsh140_l_tendon">
      <site site="bfsh140_l_bfsh140_l-P1"/>
      <geom geom="BF140_at_gastroc_l_cylinder" sidesite="BF140_at_gastroc_l_cylinder_bfsh140_l_1_sidesite"/>
      <site site="bfsh140_l_bfsh140_l-P2"/>
    </spatial>
    <spatial name="edl_l_tendon">
      <site site="edl_l_edl_l-P1"/>
      <site site="edl_l_edl_l-P2"/>
      <site site="edl_l_edl_l-P3"/>
      <site site="edl_l_edl_l-P4"/>
      <site site="edl_l_edl_l-P5"/>
      <site site="edl_l_edl_l-P6"/>
    </spatial>
    <spatial name="ehl_l_tendon">
      <site site="ehl_l_ehl_l-P1"/>
      <site site="ehl_l_ehl_l-P2"/>
      <site site="ehl_l_ehl_l-P3"/>
      <site site="ehl_l_ehl_l-P4"/>
      <site site="ehl_l_ehl_l-P5"/>
      <site site="ehl_l_ehl_l-P6"/>
      <site site="ehl_l_ehl_l-P7"/>
      <site site="ehl_l_ehl_l-P8"/>
    </spatial>
    <spatial name="ercspn_l_tendon">
      <site site="ercspn_l_ercspn_l-P1"/>
      <site site="ercspn_l_ercspn_l-P2"/>
    </spatial>
    <spatial name="extobl_l_tendon">
      <site site="extobl_l_extobl_l-P1"/>
      <site site="extobl_l_extobl_l-P2"/>
    </spatial>
    <spatial name="fdl_l_tendon">
      <site site="fdl_l_fdl_l-P1"/>
      <site site="fdl_l_fdl_l-P2"/>
      <site site="fdl_l_fdl_l-P3"/>
      <site site="fdl_l_fdl_l-P4"/>
      <site site="fdl_l_fdl_l-P5"/>
      <site site="fdl_l_fdl_l-P6"/>
      <site site="fdl_l_fdl_l-P7"/>
      <site site="fdl_l_fdl_l-P8"/>
    </spatial>
    <spatial name="fhl_l_tendon">
      <site site="fhl_l_fhl_l-P1"/>
      <site site="fhl_l_fhl_l-P2"/>
      <site site="fhl_l_fhl_l-P3"/>
      <site site="fhl_l_fhl_l-P4"/>
      <site site="fhl_l_fhl_l-P5"/>
      <site site="fhl_l_fhl_l-P6"/>
      <site site="fhl_l_fhl_l-P7"/>
    </spatial>
    <spatial name="gaslat140_l_tendon">
      <site site="gaslat140_l_gaslat140_l-P1"/>
      <geom geom="GasLat_at_condyles_l_cylinder" sidesite="GasLat_at_condyles_l_cylinder_gaslat140_l_1_sidesite"/>
      <site site="gaslat140_l_gaslat140_l-P2"/>
    </spatial>
    <spatial name="gasmed_l_tendon">
      <site site="gasmed_l_gasmed_l-P1"/>
      <geom geom="GasMed_at_condyles_l_cylinder" sidesite="GasMed_at_condyles_l_cylinder_gasmed_l_1_sidesite"/>
      <site site="gasmed_l_gasmed_l-P2"/>
    </spatial>
    <spatial name="gem_l_tendon">
      <site site="gem_l_gem_l-P1"/>
      <site site="gem_l_gem_l-P2"/>
    </spatial>
    <spatial name="glmax1_l_tendon">
      <site site="glmax1_l_glmax1_l-P1"/>
      <site site="glmax1_l_glmax1_l-P2"/>
      <geom geom="Gmax1_at_pelvis_l_cylinder" sidesite="Gmax1_at_pelvis_l_cylinder_glmax1_l_2_sidesite"/>
      <site site="glmax1_l_glmax1_l-P3"/>
      <site site="glmax1_l_glmax1_l-P4"/>
    </spatial>
    <spatial name="glmax2_l_tendon">
      <site site="glmax2_l_glmax2_l-P1"/>
      <site site="glmax2_l_glmax2_l-P2"/>
      <geom geom="Gmax2_at_pelvis_l_cylinder" sidesite="Gmax2_at_pelvis_l_cylinder_glmax2_l_2_sidesite"/>
      <site site="glmax2_l_glmax2_l-P3"/>
      <site site="glmax2_l_glmax2_l-P4"/>
    </spatial>
    <spatial name="glmax3_l_tendon">
      <site site="glmax3_l_glmax3_l-P1"/>
      <geom geom="Gmax3_at_pelvis_l_cylinder" sidesite="Gmax3_at_pelvis_l_cylinder_glmax3_l_1_sidesite"/>
      <site site="glmax3_l_glmax3_l-P2"/>
      <site site="glmax3_l_glmax3_l-P3"/>
      <site site="glmax3_l_glmax3_l-P4"/>
    </spatial>
    <spatial name="glmed1_l_tendon">
      <site site="glmed1_l_glmed1_l-P1"/>
      <site site="glmed1_l_glmed1_l-P2"/>
    </spatial>
    <spatial name="glmed2_l_tendon">
      <site site="glmed2_l_glmed2_l-P1"/>
      <site site="glmed2_l_glmed2_l-P2"/>
    </spatial>
    <spatial name="glmed3_l_tendon">
      <site site="glmed3_l_glmed3_l-P1"/>
      <site site="glmed3_l_glmed3_l-P2"/>
    </spatial>
    <spatial name="glmin1_l_tendon">
      <site site="glmin1_l_glmin1_l-P1"/>
      <site site="glmin1_l_glmin1_l-P2"/>
    </spatial>
    <spatial name="glmin2_l_tendon">
      <site site="glmin2_l_glmin2_l-P1"/>
      <site site="glmin2_l_glmin2_l-P2"/>
    </spatial>
    <spatial name="glmin3_l_tendon">
      <site site="glmin3_l_glmin3_l-P1"/>
      <site site="glmin3_l_glmin3_l-P2"/>
    </spatial>
    <spatial name="grac_l_tendon">
      <site site="grac_l_grac_l-P1"/>
      <geom geom="GR_at_condyles_l_cylinder" sidesite="GR_at_condyles_l_cylinder_grac_l_1_sidesite"/>
      <site site="grac_l_grac_l-P2"/>
      <site site="grac_l_grac_l-P3"/>
    </spatial>
    <spatial name="iliacus_l_tendon">
      <site site="iliacus_l_iliacus_l-P1"/>
      <site site="iliacus_l_iliacus_l-P2"/>
      <geom geom="IL_at_brim_l_cylinder" sidesite="IL_at_brim_l_cylinder_iliacus_l_2_sidesite"/>
      <site site="iliacus_l_iliacus_l-P3"/>
      <site site="iliacus_l_iliacus_l-P4"/>
    </spatial>
    <spatial name="intobl_l_tendon">
      <site site="intobl_l_intobl_l-P1"/>
      <site site="intobl_l_intobl_l-P2"/>
    </spatial>
    <spatial name="obtext_l_tendon">
      <site site="obtext_l_obtext_l-P1"/>
      <geom geom="OBTEXT_at_femneck_l_cylinder" sidesite="OBTEXT_at_femneck_l_cylinder_obtext_l_1_sidesite"/>
      <site site="obtext_l_obtext_l-P2"/>
    </spatial>
    <spatial name="obtint_l_tendon">
      <site site="obtint_l_obtint_l-P1"/>
      <site site="obtint_l_obtint_l-P2"/>
      <site site="obtint_l_obtint_l-P3"/>
    </spatial>
    <spatial name="pect_l_tendon">
      <site site="pect_l_pect_l-P1"/>
      <geom geom="PECT_at_femshaft_l_cylinder" sidesite="PECT_at_femshaft_l_cylinder_pect_l_1_sidesite"/>
      <site site="pect_l_pect_l-P2"/>
    </spatial>
    <spatial name="perbrev_l_tendon">
      <site site="perbrev_l_perbrev_l-P1"/>
      <site site="perbrev_l_perbrev_l-P2"/>
      <site site="perbrev_l_perbrev_l-P3"/>
      <site site="perbrev_l_perbrev_l-P4"/>
      <site site="perbrev_l_perbrev_l-P5"/>
    </spatial>
    <spatial name="perlong_l_tendon">
      <site site="perlong_l_perlong_l-P1"/>
      <site site="perlong_l_perlong_l-P2"/>
      <site site="perlong_l_perlong_l-P3"/>
      <site site="perlong_l_perlong_l-P4"/>
      <site site="perlong_l_perlong_l-P5"/>
      <site site="perlong_l_perlong_l-P6"/>
      <site site="perlong_l_perlong_l-P7"/>
    </spatial>
    <spatial name="piri_l_tendon">
      <site site="piri_l_piri_l-P1"/>
      <site site="piri_l_piri_l-P2"/>
      <site site="piri_l_piri_l-P3"/>
    </spatial>
    <spatial name="psoas_l_tendon">
      <site site="psoas_l_psoas_l-P1"/>
      <site site="psoas_l_psoas_l-P2"/>
      <geom geom="PS_at_brim_l_cylinder" sidesite="PS_at_brim_l_cylinder_psoas_l_2_sidesite"/>
      <site site="psoas_l_psoas_l-P3"/>
      <site site="psoas_l_psoas_l-P4"/>
    </spatial>
    <spatial name="quadfem_l_tendon">
      <site site="quadfem_l_quadfem_l-P1"/>
      <site site="quadfem_l_quadfem_l-P2"/>
    </spatial>
    <spatial name="recfem_l_tendon">
      <site site="recfem_l_recfem_l-P1"/>
      <site site="recfem_l_recfem_l-P2"/>
      <site site="recfem_l_recfem_l-P3"/>
      <geom geom="KnExt_at_fem_l_cylinder" sidesite="KnExt_at_fem_l_cylinder_recfem_l_3_sidesite"/>
      <site site="recfem_l_recfem_l-P4"/>
      <site site="recfem_l_recfem_l-P5"/>
    </spatial>
    <spatial name="rectab_l_tendon">
      <site site="rectab_l_rectab_l-P1"/>
      <site site="rectab_l_rectab_l-P2"/>
    </spatial>
    <spatial name="sart_l_tendon">
      <site site="sart_l_sart_l-P1"/>
      <site site="sart_l_sart_l-P2"/>
      <site site="sart_l_sart_l-P3"/>
      <site site="sart_l_sart_l-P4"/>
      <site site="sart_l_sart_l-P5"/>
    </spatial>
    <spatial name="semimem_l_tendon">
      <site site="semimem_l_semimem_l-P1"/>
      <geom geom="SM_at_condyles_l_cylinder" sidesite="SM_at_condyles_l_cylinder_semimem_l_1_sidesite"/>
      <site site="semimem_l_semimem_l-P2"/>
    </spatial>
    <spatial name="semiten_l_tendon">
      <site site="semiten_l_semiten_l-P1"/>
      <geom geom="ST_at_condyles_l_cylinder" sidesite="ST_at_condyles_l_cylinder_semiten_l_1_sidesite"/>
      <site site="semiten_l_semiten_l-P2"/>
      <site site="semiten_l_semiten_l-P3"/>
    </spatial>
    <spatial name="soleus_l_tendon">
      <site site="soleus_l_soleus_l-P1"/>
      <site site="soleus_l_soleus_l-P2"/>
    </spatial>
    <spatial name="tfl_l_tendon">
      <site site="tfl_l_tfl_l-P1"/>
      <site site="tfl_l_tfl_l-P2"/>
      <site site="tfl_l_tfl_l-P3"/>
      <site site="tfl_l_tfl_l-P4"/>
    </spatial>
    <spatial name="tibant_l_tendon">
      <site site="tibant_l_tibant_l-P1"/>
      <site site="tibant_l_tibant_l-P2"/>
      <site site="tibant_l_tibant_l-P3"/>
      <site site="tibant_l_tibant_l-P4"/>
    </spatial>
    <spatial name="tibpost_l_tendon">
      <site site="tibpost_l_tibpost_l-P1"/>
      <site site="tibpost_l_tibpost_l-P2"/>
      <site site="tibpost_l_tibpost_l-P3"/>
      <site site="tibpost_l_tibpost_l-P4"/>
    </spatial>
    <spatial name="vasint_l_tendon">
      <site site="vasint_l_vasint_l-P1"/>
      <site site="vasint_l_vasint_l-P2"/>
      <site site="vasint_l_vasint_l-P3"/>
      <geom geom="KnExt_at_fem_l_cylinder" sidesite="KnExt_at_fem_l_cylinder_vasint_l_3_sidesite"/>
      <site site="vasint_l_vasint_l-P4"/>
      <site site="vasint_l_vasint_l-P5"/>
    </spatial>
    <spatial name="vaslat140_l_tendon">
      <site site="vaslat140_l_vaslat140_l-P1"/>
      <site site="vaslat140_l_vaslat140_l-P2"/>
      <site site="vaslat140_l_vaslat140_l-P3"/>
      <geom geom="KnExtVL_at_fem_l_cylinder" sidesite="KnExtVL_at_fem_l_cylinder_vaslat140_l_3_sidesite"/>
      <site site="vaslat140_l_vaslat140_l-P4"/>
      <site site="vaslat140_l_vaslat140_l-P5"/>
    </spatial>
    <spatial name="vasmed_l_tendon">
      <site site="vasmed_l_vasmed_l-P1"/>
      <site site="vasmed_l_vasmed_l-P2"/>
      <site site="vasmed_l_vasmed_l-P3"/>
      <geom geom="KnExt_at_fem_l_cylinder" sidesite="KnExt_at_fem_l_cylinder_vasmed_l_3_sidesite"/>
      <site site="vasmed_l_vasmed_l-P4"/>
      <geom geom="KnExt_at_fem_l_cylinder" sidesite="KnExt_at_fem_l_cylinder_vasmed_l_4_sidesite"/>
      <site site="vasmed_l_vasmed_l-P5"/>
    </spatial>
  </tendon>
  <actuator>
    <general name="addbrev_r" class="muscle" tendon="addbrev_r_tendon" lengthrange="0.0748213 0.186183" gainprm="0.392855 1.2679 589.927 1 0 2 10 1.11555 1.4 0" biasprm="0.392855 1.2679 589.927 1 0 2 10 1.11555 1.4 0"/>
    <general name="addlong_r" class="muscle" tendon="addlong_r_tendon" lengthrange="0.170922 0.301501" gainprm="0.323267 1.44047 863.381 1 0 2 10 1.04089 1.4 0" biasprm="0.323267 1.44047 863.381 1 0 2 10 1.04089 1.4 0"/>
    <general name="addmagDist_r" class="muscle" tendon="addmagDist_r_tendon" lengthrange="0.202039 0.321797" gainprm="0.644112 1.54402 575.1 1 0 2 10 0.750348 1.4 0" biasprm="0.644112 1.54402 575.1 1 0 2 10 0.750348 1.4 0"/>
    <general name="addmagIsch_r" class="muscle" tendon="addmagIsch_r_tendon" lengthrange="0.319892 0.456744" gainprm="0.634503 1.40643 559.25 1 0 2 10 0.843292 1.4 0" biasprm="0.634503 1.40643 559.25 1 0 2 10 0.843292 1.4 0"/>
    <general name="addmagMid_r" class="muscle" tendon="addmagMid_r_tendon" lengthrange="0.112433 0.222783" gainprm="0.482121 1.39185 540.142 1 0 2 10 1.23756 1.4 0" biasprm="0.482121 1.39185 540.142 1 0 2 10 1.23756 1.4 0"/>
    <general name="addmagProx_r" class="muscle" tendon="addmagProx_r_tendon" lengthrange="0.0575134 0.156741" gainprm="0.170071 1.19984 539.978 1 0 2 10 1.51129 1.4 0" biasprm="0.170071 1.19984 539.978 1 0 2 10 1.51129 1.4 0"/>
    <general name="bflh140_r" class="muscle" tendon="bflh140_r_tendon" lengthrange="0.319167 0.531663" gainprm="0.147625 1.34388 1231.51 1 0 2 10 3.09419 1.4 0" biasprm="0.147625 1.34388 1231.51 1 0 2 10 3.09419 1.4 0"/>
    <general name="bfsh140_r" class="muscle" tendon="bfsh140_r_tendon" lengthrange="0.167629 0.235415" gainprm="0.721496 1.05099 524.729 1 0 2 10 3.3738 1.4 0" biasprm="0.721496 1.05099 524.729 1 0 2 10 3.3738 1.4 0"/>
    <general name="edl_r" class="muscle" tendon="edl_r_tendon" lengthrange="0.415184 0.465294" gainprm="0.503847 1.29007 550.067 1 0 2 10 1.19917 1.4 0" biasprm="0.503847 1.29007 550.067 1 0 2 10 1.19917 1.4 0"/>
    <general name="ehl_r" class="muscle" tendon="ehl_r_tendon" lengthrange="0.38298 0.429589" gainprm="0.600128 1.13536 270.507 1 0 2 10 1.59748 1.4 0" biasprm="0.600128 1.13536 270.507 1 0 2 10 1.59748 1.4 0"/>
    <general name="ercspn_r" class="muscle" tendon="ercspn_r_tendon" lengthrange="0.104556 0.203755" gainprm="0.61076 1.47309 2896.61 1 0 2 10 0.730046 1.4 0" biasprm="0.61076 1.47309 2896.61 1 0 2 10 0.730046 1.4 0"/>
    <general name="extobl_r" class="muscle" tendon="extobl_r_tendon" lengthrange="0.088324 0.309294" gainprm="0.0114981 1.13233 900.233 1 0 2 10 3.37937 1.4 0" biasprm="0.0114981 1.13233 900.233 1 0 2 10 3.37937 1.4 0"/>
    <general name="fdl_r" class="muscle" tendon="fdl_r_tendon" lengthrange="0.403831 0.433648" gainprm="0.375877 1.48345 286.369 1 0 2 10 1.79285 1.4 0" biasprm="0.375877 1.48345 286.369 1 0 2 10 1.79285 1.4 0"/>
    <general name="fhl_r" class="muscle" tendon="fhl_r_tendon" lengthrange="0.382054 0.415995" gainprm="0.365086 1.5342 636.76 1 0 2 10 1.60997 1.4 0" biasprm="0.365086 1.5342 636.76 1 0 2 10 1.60997 1.4 0"/>
    <general name="gaslat140_r" class="muscle" tendon="gaslat140_r_tendon" lengthrange="0.361524 0.477186" gainprm="0.0792913 1.30602 1232.66 1 0 2 10 2.17554 1.4 0" biasprm="0.0792913 1.30602 1232.66 1 0 2 10 2.17554 1.4 0"/>
    <general name="gasmed_r" class="muscle" tendon="gasmed_r_tendon" lengthrange="0.363569 0.477349" gainprm="0.09751 1.08829 2558.65 1 0 2 10 1.55705 1.4 0" biasprm="0.09751 1.08829 2558.65 1 0 2 10 1.55705 1.4 0"/>
    <general name="gem_r" class="muscle" tendon="gem_r_tendon" lengthrange="0.0290229 0.0907207" gainprm="0.0997791 1.54393 347.97 1 0 2 10 3.17462 1.4 0" biasprm="0.0997791 1.54393 347.97 1 0 2 10 3.17462 1.4 0"/>
    <general name="glmax1_r" class="muscle" tendon="glmax1_r_tendon" lengthrange="0.150904 0.293464" gainprm="0.679936 1.47361 969.486 1 0 2 10 0.677682 1.4 0" biasprm="0.679936 1.47361 969.486 1 0 2 10 0.677682 1.4 0"/>
    <general name="glmax2_r" class="muscle" tendon="glmax2_r_tendon" lengthrange="0.176435 0.315396" gainprm="0.466726 1.44176 1283.45 1 0 2 10 0.707566 1.4 0" biasprm="0.466726 1.44176 1283.45 1 0 2 10 0.707566 1.4 0"/>
    <general name="glmax3_r" class="muscle" tendon="glmax3_r_tendon" lengthrange="0.298242 0.473619" gainprm="0.393593 1.62221 820.116 1 0 2 10 1.01395 1.4 0" biasprm="0.393593 1.62221 820.116 1 0 2 10 1.01395 1.4 0"/>
    <general name="glmed1_r" class="muscle" tendon="glmed1_r_tendon" lengthrange="0.063405 0.162068" gainprm="0.17641 1.38507 994.256 1 0 2 10 1.05416 1.4 0" biasprm="0.17641 1.38507 994.256 1 0 2 10 1.05416 1.4 0"/>
    <general name="glmed2_r" class="muscle" tendon="glmed2_r_tendon" lengthrange="0.0773352 0.171886" gainprm="0.207373 1.7352 654.984 1 0 2 10 0.96374 1.4 0" biasprm="0.207373 1.7352 654.984 1 0 2 10 0.96374 1.4 0"/>
    <general name="glmed3_r" class="muscle" tendon="glmed3_r_tendon" lengthrange="0.0544207 0.156047" gainprm="0.171903 1.5202 793.335 1 0 2 10 1.05273 1.4 0" biasprm="0.171903 1.5202 793.335 1 0 2 10 1.05273 1.4 0"/>
    <general name="glmin1_r" class="muscle" tendon="glmin1_r_tendon" lengthrange="0.022913 0.112252" gainprm="0.11867 1.40546 337.531 1 0 2 10 1.0816 1.4 0" biasprm="0.11867 1.40546 337.531 1 0 2 10 1.0816 1.4 0"/>
    <general name="glmin2_r" class="muscle" tendon="glmin2_r_tendon" lengthrange="0.032689 0.115728" gainprm="0.111382 1.73375 360.606 1 0 2 10 1.03103 1.4 0" biasprm="0.111382 1.73375 360.606 1 0 2 10 1.03103 1.4 0"/>
    <general name="glmin3_r" class="muscle" tendon="glmin3_r_tendon" lengthrange="0.0345951 0.119939" gainprm="0.0157931 1.26941 410.39 1 0 2 10 3.28378 1.4 0" biasprm="0.0157931 1.26941 410.39 1 0 2 10 3.28378 1.4 0"/>
    <general name="grac_r" class="muscle" tendon="grac_r_tendon" lengthrange="0.332812 0.549995" gainprm="0.815984 1.29423 257.423 1 0 2 10 2.06449 1.4 0" biasprm="0.815984 1.29423 257.423 1 0 2 10 2.06449 1.4 0"/>
    <general name="iliacus_r" class="muscle" tendon="iliacus_r_tendon" lengthrange="0.126931 0.338954" gainprm="0.3482 1.59478 1065.55 1 0 2 10 0.688834 1.4 0" biasprm="0.3482 1.59478 1065.55 1 0 2 10 0.688834 1.4 0"/>
    <general name="intobl_r" class="muscle" tendon="intobl_r_tendon" lengthrange="0.0654653 0.260356" gainprm="0.01 1.09439 1035.27 1 0 2 10 1.92922 1.4 0" biasprm="0.01 1.09439 1035.27 1 0 2 10 1.92922 1.4 0"/>
    <general name="obtext_r" class="muscle" tendon="obtext_r_tendon" lengthrange="0.0595832 0.111757" gainprm="0.0156931 1.08488 1037.57 1 0 2 10 2.81623 1.4 0" biasprm="0.0156931 1.08488 1037.57 1 0 2 10 2.81623 1.4 0"/>
    <general name="obtint_r" class="muscle" tendon="obtint_r_tendon" lengthrange="0.108712 0.167968" gainprm="0.231607 1.283 304.445 1 0 2 10 0.947442 1.4 0" biasprm="0.231607 1.283 304.445 1 0 2 10 0.947442 1.4 0"/>
    <general name="pect_r" class="muscle" tendon="pect_r_tendon" lengthrange="0.0537743 0.131142" gainprm="0.304731 1.36423 258.517 1 0 2 10 1.74496 1.4 0" biasprm="0.304731 1.36423 258.517 1 0 2 10 1.74496 1.4 0"/>
    <general name="perbrev_r" class="muscle" tendon="perbrev_r_tendon" lengthrange="0.179464 0.213915" gainprm="0.574471 1.6198 492.889 1 0 2 10 0.823054 1.4 0" biasprm="0.574471 1.6198 492.889 1 0 2 10 0.823054 1.4 0"/>
    <general name="perlong_r" class="muscle" tendon="perlong_r_tendon" lengthrange="0.370491 0.404205" gainprm="0.542048 1.13495 1032.29 1 0 2 10 3.54259 1.4 0" biasprm="0.542048 1.13495 1032.29 1 0 2 10 3.54259 1.4 0"/>
    <general name="piri_r" class="muscle" tendon="piri_r_tendon" lengthrange="0.0953576 0.167003" gainprm="0.0117465 1.02786 1100.93 1 0 2 10 2.31705 1.4 0" biasprm="0.0117465 1.02786 1100.93 1 0 2 10 2.31705 1.4 0"/>
    <general name="psoas_r" class="muscle" tendon="psoas_r_tendon" lengthrange="0.157713 0.242031" gainprm="0.526261 1.1954 1305.13 1 0 2 10 2.11215 1.4 0" biasprm="0.526261 1.1954 1305.13 1 0 2 10 2.11215 1.4 0"/>
    <general name="quadfem_r" class="muscle" tendon="quadfem_r_tendon" lengthrange="0.0258222 0.132866" gainprm="0.144129 1.47229 347.882 1 0 2 10 3.26616 1.4 0" biasprm="0.144129 1.47229 347.882 1 0 2 10 3.26616 1.4 0"/>
    <general name="recfem_r" class="muscle" tendon="recfem_r_tendon" lengthrange="0.417957 0.722399" gainprm="0.318952 1.47882 1291.7 1 0 2 10 3.26063 1.4 0" biasprm="0.318952 1.47882 1291.7 1 0 2 10 3.26063 1.4 0"/>
    <general name="rectab_r" class="muscle" tendon="rectab_r_tendon" lengthrange="0.173108 0.383554" gainprm="0.143552 1.16458 1010.52 1 0 2 10 2.37485 1.4 0" biasprm="0.143552 1.16458 1010.52 1 0 2 10 2.37485 1.4 0"/>
    <general name="sart_r" class="muscle" tendon="sart_r_tendon" lengthrange="0.372165 0.597742" gainprm="0.655815 1.5259 233.635 1 0 2 10 1.07033 1.4 0" biasprm="0.655815 1.5259 233.635 1 0 2 10 1.07033 1.4 0"/>
    <general name="semimem_r" class="muscle" tendon="semimem_r_tendon" lengthrange="0.310341 0.512477" gainprm="0.0202901 1.48962 1981.21 1 0 2 10 2.08604 1.4 0" biasprm="0.0202901 1.48962 1981.21 1 0 2 10 2.08604 1.4 0"/>
    <general name="semiten_r" class="muscle" tendon="semiten_r_tendon" lengthrange="0.328098 0.57932" gainprm="0.480526 1.57168 530.858 1 0 2 10 1.30475 1.4 0" biasprm="0.480526 1.57168 530.858 1 0 2 10 1.30475 1.4 0"/>
    <general name="soleus_r" class="muscle" tendon="soleus_r_tendon" lengthrange="0.292625 0.345468" gainprm="0.241091 1.1165 5448.72 1 0 2 10 1.58337 1.4 0" biasprm="0.241091 1.1165 5448.72 1 0 2 10 1.58337 1.4 0"/>
    <general name="tfl_r" class="muscle" tendon="tfl_r_tendon" lengthrange="0.374442 0.591145" gainprm="0.079937 1.11274 336.281 1 0 2 10 1.92353 1.4 0" biasprm="0.079937 1.11274 336.281 1 0 2 10 1.92353 1.4 0"/>
    <general name="tibant_r" class="muscle" tendon="tibant_r_tendon" lengthrange="0.281495 0.335794" gainprm="0.484965 1.34576 1137.19 1 0 2 10 0.9213 1.4 0" biasprm="0.484965 1.34576 1137.19 1 0 2 10 0.9213 1.4 0"/>
    <general name="tibpost_r" class="muscle" tendon="tibpost_r_tendon" lengthrange="0.300089 0.33065" gainprm="0.327142 1.07249 1564.49 1 0 2 10 3.34003 1.4 0" biasprm="0.327142 1.07249 1564.49 1 0 2 10 3.34003 1.4 0"/>
    <general name="vasint_r" class="muscle" tendon="vasint_r_tendon" lengthrange="0.276451 0.466544" gainprm="0.694882 1.31794 1459.81 1 0 2 10 1.81919 1.4 0" biasprm="0.694882 1.31794 1459.81 1 0 2 10 1.81919 1.4 0"/>
    <general name="vaslat140_r" class="muscle" tendon="vaslat140_r_tendon" lengthrange="0.290763 0.482911" gainprm="0.483593 1.55698 6015.2 1 0 2 10 0.571103 1.4 0" biasprm="0.483593 1.55698 6015.2 1 0 2 10 0.571103 1.4 0"/>
    <general name="vasmed_r" class="muscle" tendon="vasmed_r_tendon" lengthrange="0.312918 0.363521" gainprm="0.546757 1.2664 2450.22 1 0 2 10 0.998959 1.4 0" biasprm="0.546757 1.2664 2450.22 1 0 2 10 0.998959 1.4 0"/>
    <general name="addbrev_l" class="muscle" tendon="addbrev_l_tendon" lengthrange="0.0748213 0.186183" gainprm="0.36744 1.44083 582.991 1 0 2 10 0.973627 1.4 0" biasprm="0.36744 1.44083 582.991 1 0 2 10 0.973627 1.4 0"/>
    <general name="addlong_l" class="muscle" tendon="addlong_l_tendon" lengthrange="0.170922 0.301501" gainprm="0.296967 1.55734 869.084 1 0 2 10 0.931463 1.4 0" biasprm="0.296967 1.55734 869.084 1 0 2 10 0.931463 1.4 0"/>
    <general name="addmagDist_l" class="muscle" tendon="addmagDist_l_tendon" lengthrange="0.202039 0.321797" gainprm="0.724931 1.07053 549.042 1 0 2 10 2.38618 1.4 0" biasprm="0.724931 1.07053 549.042 1 0 2 10 2.38618 1.4 0"/>
    <general name="addmagIsch_l" class="muscle" tendon="addmagIsch_l_tendon" lengthrange="0.319892 0.456744" gainprm="0.614509 1.58721 565.439 1 0 2 10 0.851024 1.4 0" biasprm="0.614509 1.58721 565.439 1 0 2 10 0.851024 1.4 0"/>
    <general name="addmagMid_l" class="muscle" tendon="addmagMid_l_tendon" lengthrange="0.112433 0.222783" gainprm="0.453672 1.59578 561.982 1 0 2 10 0.856057 1.4 0" biasprm="0.453672 1.59578 561.982 1 0 2 10 0.856057 1.4 0"/>
    <general name="addmagProx_l" class="muscle" tendon="addmagProx_l_tendon" lengthrange="0.0575134 0.156741" gainprm="0.207599 1.05205 563.227 1 0 2 10 4.75283 1.4 0" biasprm="0.207599 1.05205 563.227 1 0 2 10 4.75283 1.4 0"/>
    <general name="bflh140_l" class="muscle" tendon="bflh140_l_tendon" lengthrange="0.319167 0.531663" gainprm="0.0529433 1.58954 1179.61 1 0 2 10 1.81867 1.4 0" biasprm="0.0529433 1.58954 1179.61 1 0 2 10 1.81867 1.4 0"/>
    <general name="bfsh140_l" class="muscle" tendon="bfsh140_l_tendon" lengthrange="0.167629 0.235415" gainprm="0.678386 1.33199 533.099 1 0 2 10 0.69671 1.4 0" biasprm="0.678386 1.33199 533.099 1 0 2 10 0.69671 1.4 0"/>
    <general name="edl_l" class="muscle" tendon="edl_l_tendon" lengthrange="0.415184 0.465294" gainprm="0.508595 1.04557 578.194 1 0 2 10 3.47143 1.4 0" biasprm="0.508595 1.04557 578.194 1 0 2 10 3.47143 1.4 0"/>
    <general name="ehl_l" class="muscle" tendon="ehl_l_tendon" lengthrange="0.38298 0.429589" gainprm="0.585935 1.27902 271.636 1 0 2 10 0.74111 1.4 0" biasprm="0.585935 1.27902 271.636 1 0 2 10 0.74111 1.4 0"/>
    <general name="ercspn_l" class="muscle" tendon="ercspn_l_tendon" lengthrange="0.104556 0.203755" gainprm="0.685626 1.15877 2728.48 1 0 2 10 2.69686 1.4 0" biasprm="0.685626 1.15877 2728.48 1 0 2 10 2.69686 1.4 0"/>
    <general name="extobl_l" class="muscle" tendon="extobl_l_tendon" lengthrange="0.088324 0.309294" gainprm="0.0549259 1.70919 556.65 1 0 2 10 1.98738 1.4 0" biasprm="0.0549259 1.70919 556.65 1 0 2 10 1.98738 1.4 0"/>
    <general name="fdl_l" class="muscle" tendon="fdl_l_tendon" lengthrange="0.403831 0.433648" gainprm="0.466853 1.45239 270.637 1 0 2 10 2.24943 1.4 0" biasprm="0.466853 1.45239 270.637 1 0 2 10 2.24943 1.4 0"/>
    <general name="fhl_l" class="muscle" tendon="fhl_l_tendon" lengthrange="0.382054 0.415995" gainprm="0.365026 1.16366 734.296 1 0 2 10 2.35291 1.4 0" biasprm="0.365026 1.16366 734.296 1 0 2 10 2.35291 1.4 0"/>
    <general name="gaslat140_l" class="muscle" tendon="gaslat140_l_tendon" lengthrange="0.361524 0.477186" gainprm="0.0177832 1.05246 1441.41 1 0 2 10 3.81335 1.4 0" biasprm="0.0177832 1.05246 1441.41 1 0 2 10 3.81335 1.4 0"/>
    <general name="gasmed_l" class="muscle" tendon="gasmed_l_tendon" lengthrange="0.363569 0.477349" gainprm="0.0162685 1 2838.3 1 0 2 10 4.56246 1.4 0" biasprm="0.0162685 1 2838.3 1 0 2 10 4.56246 1.4 0"/>
    <general name="gem_l" class="muscle" tendon="gem_l_tendon" lengthrange="0.0290229 0.0907207" gainprm="0.0385338 1.3951 387.939 1 0 2 10 4.42403 1.4 0" biasprm="0.0385338 1.3951 387.939 1 0 2 10 4.42403 1.4 0"/>
    <general name="glmax1_l" class="muscle" tendon="glmax1_l_tendon" lengthrange="0.150904 0.293464" gainprm="0.675237 1.59562 949.403 1 0 2 10 0.765473 1.4 0" biasprm="0.675237 1.59562 949.403 1 0 2 10 0.765473 1.4 0"/>
    <general name="glmax2_l" class="muscle" tendon="glmax2_l_tendon" lengthrange="0.176435 0.310285" gainprm="0.465947 1.51373 1263.26 1 0 2 10 0.841429 1.4 0" biasprm="0.465947 1.51373 1263.26 1 0 2 10 0.841429 1.4 0"/>
    <general name="glmax3_l" class="muscle" tendon="glmax3_l_tendon" lengthrange="0.298242 0.473619" gainprm="0.435248 1.27539 825.954 1 0 2 10 1.4742 1.4 0" biasprm="0.435248 1.27539 825.954 1 0 2 10 1.4742 1.4 0"/>
    <general name="glmed1_l" class="muscle" tendon="glmed1_l_tendon" lengthrange="0.063405 0.162068" gainprm="0.174686 1.37268 1001.01 1 0 2 10 0.878115 1.4 0" biasprm="0.174686 1.37268 1001.01 1 0 2 10 0.878115 1.4 0"/>
    <general name="glmed2_l" class="muscle" tendon="glmed2_l_tendon" lengthrange="0.0773352 0.171886" gainprm="0.210546 1.45747 699.196 1 0 2 10 0.908782 1.4 0" biasprm="0.210546 1.45747 699.196 1 0 2 10 0.908782 1.4 0"/>
    <general name="glmed3_l" class="muscle" tendon="glmed3_l_tendon" lengthrange="0.0544207 0.156047" gainprm="0.13486 1.64704 784.978 1 0 2 10 0.996668 1.4 0" biasprm="0.13486 1.64704 784.978 1 0 2 10 0.996668 1.4 0"/>
    <general name="glmin1_l" class="muscle" tendon="glmin1_l_tendon" lengthrange="0.022913 0.112252" gainprm="0.0750063 1.49969 349.945 1 0 2 10 0.88015 1.4 0" biasprm="0.0750063 1.49969 349.945 1 0 2 10 0.88015 1.4 0"/>
    <general name="glmin2_l" class="muscle" tendon="glmin2_l_tendon" lengthrange="0.032689 0.115728" gainprm="0.124642 1.45282 373.173 1 0 2 10 1.21426 1.4 0" biasprm="0.124642 1.45282 373.173 1 0 2 10 1.21426 1.4 0"/>
    <general name="glmin3_l" class="muscle" tendon="glmin3_l_tendon" lengthrange="0.0345951 0.119939" gainprm="0.0228229 1.26777 413.763 1 0 2 10 3.39519 1.4 0" biasprm="0.0228229 1.26777 413.763 1 0 2 10 3.39519 1.4 0"/>
    <general name="grac_l" class="muscle" tendon="grac_l_tendon" lengthrange="0.332812 0.549995" gainprm="0.813941 1.27819 256.87 1 0 2 10 2.20682 1.4 0" biasprm="0.813941 1.27819 256.87 1 0 2 10 2.20682 1.4 0"/>
    <general name="iliacus_l" class="muscle" tendon="iliacus_l_tendon" lengthrange="0.126931 0.338954" gainprm="0.346883 1.7041 1034.39 1 0 2 10 0.706799 1.4 0" biasprm="0.346883 1.7041 1034.39 1 0 2 10 0.706799 1.4 0"/>
    <general name="intobl_l" class="muscle" tendon="intobl_l_tendon" lengthrange="0.0654653 0.260356" gainprm="0.01 1.31556 1001.66 1 0 2 10 1.28808 1.4 0" biasprm="0.01 1.31556 1001.66 1 0 2 10 1.28808 1.4 0"/>
    <general name="obtext_l" class="muscle" tendon="obtext_l_tendon" lengthrange="0.0595832 0.111757" gainprm="0.01 1.09996 1005.62 1 0 2 10 1.84683 1.4 0" biasprm="0.01 1.09996 1005.62 1 0 2 10 1.84683 1.4 0"/>
    <general name="obtint_l" class="muscle" tendon="obtint_l_tendon" lengthrange="0.108712 0.167968" gainprm="0.227774 1.28955 303.07 1 0 2 10 1.06593 1.4 0" biasprm="0.227774 1.28955 303.07 1 0 2 10 1.06593 1.4 0"/>
    <general name="pect_l" class="muscle" tendon="pect_l_tendon" lengthrange="0.0537743 0.131142" gainprm="0.319985 1.09277 291.583 1 0 2 10 0.77741 1.4 0" biasprm="0.319985 1.09277 291.583 1 0 2 10 0.77741 1.4 0"/>
    <general name="perbrev_l" class="muscle" tendon="perbrev_l_tendon" lengthrange="0.179464 0.213915" gainprm="0.598391 1.37858 483.017 1 0 2 10 0.905725 1.4 0" biasprm="0.598391 1.37858 483.017 1 0 2 10 0.905725 1.4 0"/>
    <general name="perlong_l" class="muscle" tendon="perlong_l_tendon" lengthrange="0.370491 0.404205" gainprm="0.536542 1.25415 1026.91 1 0 2 10 1.20634 1.4 0" biasprm="0.536542 1.25415 1026.91 1 0 2 10 1.20634 1.4 0"/>
    <general name="piri_l" class="muscle" tendon="piri_l_tendon" lengthrange="0.0953576 0.167003" gainprm="0.0316248 1.00335 1089.82 1 0 2 10 2.87921 1.4 0" biasprm="0.0316248 1.00335 1089.82 1 0 2 10 2.87921 1.4 0"/>
    <general name="psoas_l" class="muscle" tendon="psoas_l_tendon" lengthrange="0.157713 0.242031" gainprm="0.487134 1.25223 1376.74 1 0 2 10 0.163408 1.4 0" biasprm="0.487134 1.25223 1376.74 1 0 2 10 0.163408 1.4 0"/>
    <general name="quadfem_l" class="muscle" tendon="quadfem_l_tendon" lengthrange="0.0258222 0.132866" gainprm="0.124593 1.49758 349.449 1 0 2 10 2.98275 1.4 0" biasprm="0.124593 1.49758 349.449 1 0 2 10 2.98275 1.4 0"/>
    <general name="recfem_l" class="muscle" tendon="recfem_l_tendon" lengthrange="0.417957 0.722399" gainprm="0.125274 1.80556 1192.4 1 0 2 10 1.94405 1.4 0" biasprm="0.125274 1.80556 1192.4 1 0 2 10 1.94405 1.4 0"/>
    <general name="rectab_l" class="muscle" tendon="rectab_l_tendon" lengthrange="0.173108 0.383554" gainprm="0.138951 1.18731 1022.35 1 0 2 10 2.09117 1.4 0" biasprm="0.138951 1.18731 1022.35 1 0 2 10 2.09117 1.4 0"/>
    <general name="sart_l" class="muscle" tendon="sart_l_tendon" lengthrange="0.372165 0.597742" gainprm="0.610943 1.36497 244.162 1 0 2 10 0.828286 1.4 0" biasprm="0.610943 1.36497 244.162 1 0 2 10 0.828286 1.4 0"/>
    <general name="semimem_l" class="muscle" tendon="semimem_l_tendon" lengthrange="0.310341 0.512477" gainprm="0.0611808 1.35588 2021.42 1 0 2 10 2.99204 1.4 0" biasprm="0.0611808 1.35588 2021.42 1 0 2 10 2.99204 1.4 0"/>
    <general name="semiten_l" class="muscle" tendon="semiten_l_tendon" lengthrange="0.328098 0.57932" gainprm="0.44014 1.86162 547.779 1 0 2 10 0.949036 1.4 0" biasprm="0.44014 1.86162 547.779 1 0 2 10 0.949036 1.4 0"/>
    <general name="soleus_l" class="muscle" tendon="soleus_l_tendon" lengthrange="0.292625 0.345468" gainprm="0.262793 1.09523 5411.23 1 0 2 10 3.68506 1.4 0" biasprm="0.262793 1.09523 5411.23 1 0 2 10 3.68506 1.4 0"/>
    <general name="tfl_l" class="muscle" tendon="tfl_l_tendon" lengthrange="0.374442 0.591145" gainprm="0.207377 1.09926 300.305 1 0 2 10 2.82599 1.4 0" biasprm="0.207377 1.09926 300.305 1 0 2 10 2.82599 1.4 0"/>
    <general name="tibant_l" class="muscle" tendon="tibant_l_tendon" lengthrange="0.281495 0.335794" gainprm="0.478684 1.36088 1151.14 1 0 2 10 0.772738 1.4 0" biasprm="0.478684 1.36088 1151.14 1 0 2 10 0.772738 1.4 0"/>
    <general name="tibpost_l" class="muscle" tendon="tibpost_l_tendon" lengthrange="0.300089 0.33065" gainprm="0.333041 1 1617.3 1 0 2 10 1.38751 1.4 0" biasprm="0.333041 1 1617.3 1 0 2 10 1.38751 1.4 0"/>
    <general name="vasint_l" class="muscle" tendon="vasint_l_tendon" lengthrange="0.276451 0.466544" gainprm="0.477687 1.59386 2008.19 1 0 2 10 0.580763 1.4 0" biasprm="0.477687 1.59386 2008.19 1 0 2 10 0.580763 1.4 0"/>
    <general name="vaslat140_l" class="muscle" tendon="vaslat140_l_tendon" lengthrange="0.290763 0.482911" gainprm="0.475532 1.54701 6154.68 1 0 2 10 0.518601 1.4 0" biasprm="0.475532 1.54701 6154.68 1 0 2 10 0.518601 1.4 0"/>
    <general name="vasmed_l" class="muscle" tendon="vasmed_l_tendon" lengthrange="0.312918 0.363521" gainprm="0.532878 1.43752 2469.59 1 0 2 10 0.847582 1.4 0" biasprm="0.532878 1.43752 2469.59 1 0 2 10 0.847582 1.4 0"/>
  </actuator>
  <!--定义模型的预设姿态或动作关键帧 -->
<!--  <keyframe>-->
<!--    <key name="default-pose" qpos="0 0.93 0 0 0 0 2.332e-09 -1.199e-09 0 -7.734e-07 -2.497e-05 -1.431e-05 4.878e-05 3.843e-06 1.803e-05 -1.183e-09 0 0 0.05242 -0.01083 0.00275 0.01051 2.332e-09 1.199e-09 0 -7.734e-07 -2.497e-05 1.431e-05 4.878e-05 3.844e-06 -1.803e-05 8.353e-11 0 0 0.05242 -0.01083 -0.00275 0.01051 0 0 0"/>-->
<!--  </keyframe>-->
</mujoco>
